Workbook

Sheet Consolidado
A1: Consolidado de calificaciones – Práctica 1: Sistema de Estacionamiento
A2: No. | B2: Carné | C2: Nombre del estudiante | D2: Habilidades (20) | E2: Conocimiento (55) | F2: Autoría (25) | G2: Subtotal | H2: Penalización | I2: Nota final | J2: Repositorio
A3: 1 | B3: 201024808 | C3: MARTA GABRIELA GÓMEZ DIMAYUGA | D3: =IFERROR(INDIRECT(B3 & "!D13"), "0") -> #REF! | E3: =IFERROR(INDIRECT(B3 & "!D27"), "0") -> #REF! | F3: =IFERROR(INDIRECT(B3 & "!D64"), "0") -> #REF! | G3: =IF(C3="","",SUM(D3:F3)) -> #REF! | H3: =IFERROR(__xludf.dummyfunction("IFERROR(MIN(FILTER(INDIRECT(B3 & ""!B101:B115""), LEFT(INDIRECT(B3 & ""!C101:C115""),1)=""S"")), ""0%"")"),"0%") -> 0% | I3: =IF(C3="","",MAX(0,ROUND(G3*(1+H3),2))) -> #REF!
A4: 2 | B4: 201503481 | C4: DIEGO ALFONSO CANEL FUENTES | D4: =IFERROR(INDIRECT(B4 & "!D13"), "0") -> #REF! | E4: =IFERROR(INDIRECT(B4 & "!D27"), "0") -> #REF! | F4: =IFERROR(INDIRECT(B4 & "!D64"), "0") -> #REF! | G4: =IF(C4="","",SUM(D4:F4)) -> #REF! | H4: =IFERROR(__xludf.dummyfunction("IFERROR(MIN(FILTER(INDIRECT(B4 & ""!B101:B115""), LEFT(INDIRECT(B4 & ""!C101:C115""),1)=""S"")), ""0%"")"),"0%") -> 0% | I4: =IF(C4="","",MAX(0,ROUND(G4*(1+H4),2))) -> #REF!
A5: 3 | B5: 202004723 | C5: ERMI RONALDO SOTO MEJÍA | D5: =IFERROR(INDIRECT(B5 & "!D13"), "0") -> #REF! | E5: =IFERROR(INDIRECT(B5 & "!D27"), "0") -> #REF! | F5: =IFERROR(INDIRECT(B5 & "!D64"), "0") -> #REF! | G5: =IF(C5="","",SUM(D5:F5)) -> #REF! | H5: =IFERROR(__xludf.dummyfunction("IFERROR(MIN(FILTER(INDIRECT(B5 & ""!B101:B115""), LEFT(INDIRECT(B5 & ""!C101:C115""),1)=""S"")), ""0%"")"),"0%") -> 0% | I5: =IF(C5="","",MAX(0,ROUND(G5*(1+H5),2))) -> #REF!
A6: 4 | B6: 202201204 | C6: BRYAN ALEXANDER MARTÍNEZ FLORES | D6: =IFERROR(INDIRECT(B6 & "!D13"), "0") -> 0 | E6: =IFERROR(INDIRECT(B6 & "!D27"), "0") -> 2 | F6: =IFERROR(INDIRECT(B6 & "!D64"), "0") -> 0 | G6: =IF(C6="","",SUM(D6:F6)) -> 2 | H6: =IFERROR(__xludf.dummyfunction("IFERROR(MIN(FILTER(INDIRECT(B6 & ""!B101:B115""), LEFT(INDIRECT(B6 & ""!C101:C115""),1)=""S"")), ""0%"")"),"0%") -> 0% | I6: =IF(C6="","",MAX(0,ROUND(G6*(1+H6),2))) -> 2
A7: 5 | B7: 202300365 | C7: BRAYAN HOMERO SOSA GONZALEZ | D7: =IFERROR(INDIRECT(B7 & "!D13"), "0") -> #REF! | E7: =IFERROR(INDIRECT(B7 & "!D27"), "0") -> #REF! | F7: =IFERROR(INDIRECT(B7 & "!D64"), "0") -> #REF! | G7: =IF(C7="","",SUM(D7:F7)) -> #REF! | H7: =IFERROR(__xludf.dummyfunction("IFERROR(MIN(FILTER(INDIRECT(B7 & ""!B101:B115""), LEFT(INDIRECT(B7 & ""!C101:C115""),1)=""S"")), ""0%"")"),"0%") -> 0% | I7: =IF(C7="","",MAX(0,ROUND(G7*(1+H7),2))) -> #REF!
A8: 6 | B8: 202303797 | C8: ROLANDO AARÓN BARRIOS BOROR | D8: =IFERROR(INDIRECT(B8 & "!D13"), "0") -> #REF! | E8: =IFERROR(INDIRECT(B8 & "!D27"), "0") -> #REF! | F8: =IFERROR(INDIRECT(B8 & "!D64"), "0") -> #REF! | G8: =IF(C8="","",SUM(D8:F8)) -> #REF! | H8: =IFERROR(__xludf.dummyfunction("IFERROR(MIN(FILTER(INDIRECT(B8 & ""!B101:B115""), LEFT(INDIRECT(B8 & ""!C101:C115""),1)=""S"")), ""0%"")"),"0%") -> 0% | I8: =IF(C8="","",MAX(0,ROUND(G8*(1+H8),2))) -> #REF!
A9: 7 | B9: 202306260 | C9: WILLIAM SAMUEL CABRERA GÓMEZ | D9: =IFERROR(INDIRECT(B9 & "!D13"), "0") -> #REF! | E9: =IFERROR(INDIRECT(B9 & "!D27"), "0") -> #REF! | F9: =IFERROR(INDIRECT(B9 & "!D64"), "0") -> #REF! | G9: =IF(C9="","",SUM(D9:F9)) -> #REF! | H9: =IFERROR(__xludf.dummyfunction("IFERROR(MIN(FILTER(INDIRECT(B9 & ""!B101:B115""), LEFT(INDIRECT(B9 & ""!C101:C115""),1)=""S"")), ""0%"")"),"0%") -> 0% | I9: =IF(C9="","",MAX(0,ROUND(G9*(1+H9),2))) -> #REF!
A10: 8 | B10: 202308203 | C10: HANS CRISTIAN MEYER DIAZ | D10: =IFERROR(INDIRECT(B10 & "!D13"), "0") -> 0 | E10: =IFERROR(INDIRECT(B10 & "!D27"), "0") -> 2 | F10: =IFERROR(INDIRECT(B10 & "!D64"), "0") -> 0 | G10: =IF(C10="","",SUM(D10:F10)) -> 2 | H10: =IFERROR(__xludf.dummyfunction("IFERROR(MIN(FILTER(INDIRECT(B10 & ""!B101:B115""), LEFT(INDIRECT(B10 & ""!C101:C115""),1)=""S"")), ""0%"")"),"0%") -> 0% | I10: =IF(C10="","",MAX(0,ROUND(G10*(1+H10),2))) -> 2
A11: 9 | B11: 202308528 | C11: ASTRID MARIA SUSETH MORALES RODAS | D11: =IFERROR(INDIRECT(B11 & "!D13"), "0") -> #REF! | E11: =IFERROR(INDIRECT(B11 & "!D27"), "0") -> #REF! | F11: =IFERROR(INDIRECT(B11 & "!D64"), "0") -> #REF! | G11: =IF(C11="","",SUM(D11:F11)) -> #REF! | H11: =IFERROR(__xludf.dummyfunction("IFERROR(MIN(FILTER(INDIRECT(B11 & ""!B101:B115""), LEFT(INDIRECT(B11 & ""!C101:C115""),1)=""S"")), ""0%"")"),"0%") -> 0% | I11: =IF(C11="","",MAX(0,ROUND(G11*(1+H11),2))) -> #REF!
A12: 10 | B12: 202400066 | C12: DIEGO SEBASTIAN ALVARADO MORATAYA | D12: =IFERROR(INDIRECT(B12 & "!D13"), "0") -> 0 | E12: =IFERROR(INDIRECT(B12 & "!D27"), "0") -> 2 | F12: =IFERROR(INDIRECT(B12 & "!D64"), "0") -> 3 | G12: =IF(C12="","",SUM(D12:F12)) -> 5 | H12: =IFERROR(__xludf.dummyfunction("IFERROR(MIN(FILTER(INDIRECT(B12 & ""!B101:B115""), LEFT(INDIRECT(B12 & ""!C101:C115""),1)=""S"")), ""0%"")"),"0%") -> 0% | I12: =IF(C12="","",MAX(0,ROUND(G12*(1+H12),2))) -> 5
A13: 11 | B13: 202400155 | C13: ESVIN FERNANDO ORTEGA GONZÁLEZ | D13: =IFERROR(INDIRECT(B13 & "!D13"), "0") -> 0 | E13: =IFERROR(INDIRECT(B13 & "!D27"), "0") -> 2 | F13: =IFERROR(INDIRECT(B13 & "!D64"), "0") -> 3 | G13: =IF(C13="","",SUM(D13:F13)) -> 5 | H13: =IFERROR(__xludf.dummyfunction("IFERROR(MIN(FILTER(INDIRECT(B13 & ""!B101:B115""), LEFT(INDIRECT(B13 & ""!C101:C115""),1)=""S"")), ""0%"")"),"0%") -> 0% | I13: =IF(C13="","",MAX(0,ROUND(G13*(1+H13),2))) -> 5
A14: 12 | B14: 202400482 | C14: ADRIAN EDUARDO ALVAREZ ZAMBRANO | D14: =IFERROR(INDIRECT(B14 & "!D13"), "0") -> 0 | E14: =IFERROR(INDIRECT(B14 & "!D27"), "0") -> 0 | F14: =IFERROR(INDIRECT(B14 & "!D64"), "0") -> 0 | G14: =IF(C14="","",SUM(D14:F14)) -> 0 | H14: =IFERROR(__xludf.dummyfunction("IFERROR(MIN(FILTER(INDIRECT(B14 & ""!B101:B115""), LEFT(INDIRECT(B14 & ""!C101:C115""),1)=""S"")), ""0%"")"),"0%") -> 0% | I14: =IF(C14="","",MAX(0,ROUND(G14*(1+H14),2))) -> 0
A15: 13 | B15: 202403338 | C15: ANDY RAÍ TELÓN GABRIEL | D15: =IFERROR(INDIRECT(B15 & "!D13"), "0") -> 0 | E15: =IFERROR(INDIRECT(B15 & "!D27"), "0") -> 2 | F15: =IFERROR(INDIRECT(B15 & "!D64"), "0") -> 3 | G15: =IF(C15="","",SUM(D15:F15)) -> 5 | H15: =IFERROR(__xludf.dummyfunction("IFERROR(MIN(FILTER(INDIRECT(B15 & ""!B101:B115""), LEFT(INDIRECT(B15 & ""!C101:C115""),1)=""S"")), ""0%"")"),"0%") -> 0% | I15: =IF(C15="","",MAX(0,ROUND(G15*(1+H15),2))) -> 5
A16: 14 | B16: 202404528 | C16: MELISSA GRISSEL PEREZ RIVAS | D16: =IFERROR(INDIRECT(B16 & "!D13"), "0") -> 0 | E16: =IFERROR(INDIRECT(B16 & "!D27"), "0") -> 0 | F16: =IFERROR(INDIRECT(B16 & "!D64"), "0") -> 3 | G16: =IF(C16="","",SUM(D16:F16)) -> 3 | H16: =IFERROR(__xludf.dummyfunction("IFERROR(MIN(FILTER(INDIRECT(B16 & ""!B101:B115""), LEFT(INDIRECT(B16 & ""!C101:C115""),1)=""S"")), ""0%"")"),"0%") -> 0% | I16: =IF(C16="","",MAX(0,ROUND(G16*(1+H16),2))) -> 3
A17: 15 | B17: 202405048 | C17: MONIKA ESTEFANIA CRUZ PALACIOS | D17: =IFERROR(INDIRECT(B17 & "!D13"), "0") -> 0 | E17: =IFERROR(INDIRECT(B17 & "!D27"), "0") -> 2 | F17: =IFERROR(INDIRECT(B17 & "!D64"), "0") -> 3 | G17: =IF(C17="","",SUM(D17:F17)) -> 5 | H17: =IFERROR(__xludf.dummyfunction("IFERROR(MIN(FILTER(INDIRECT(B17 & ""!B101:B115""), LEFT(INDIRECT(B17 & ""!C101:C115""),1)=""S"")), ""0%"")"),"0%") -> 0% | I17: =IF(C17="","",MAX(0,ROUND(G17*(1+H17),2))) -> 5
A18: 16 | B18: 202405842 | C18: GABRIEL LEVI ZAPETA MAZARIEGOS | D18: =IFERROR(INDIRECT(B18 & "!D13"), "0") -> #REF! | E18: =IFERROR(INDIRECT(B18 & "!D27"), "0") -> #REF! | F18: =IFERROR(INDIRECT(B18 & "!D64"), "0") -> #REF! | G18: =IF(C18="","",SUM(D18:F18)) -> #REF! | H18: =IFERROR(__xludf.dummyfunction("IFERROR(MIN(FILTER(INDIRECT(B18 & ""!B101:B115""), LEFT(INDIRECT(B18 & ""!C101:C115""),1)=""S"")), ""0%"")"),"0%") -> 0% | I18: =IF(C18="","",MAX(0,ROUND(G18*(1+H18),2))) -> #REF!
A19: 17 | B19: 202406816 | C19: EVELYN ARACELY CARDONA AGUILON | D19: =IFERROR(INDIRECT(B19 & "!D13"), "0") -> 0 | E19: =IFERROR(INDIRECT(B19 & "!D27"), "0") -> 1 | F19: =IFERROR(INDIRECT(B19 & "!D64"), "0") -> 3 | G19: =IF(C19="","",SUM(D19:F19)) -> 4 | H19: =IFERROR(__xludf.dummyfunction("IFERROR(MIN(FILTER(INDIRECT(B19 & ""!B101:B115""), LEFT(INDIRECT(B19 & ""!C101:C115""),1)=""S"")), ""0%"")"),"0%") -> 0% | I19: =IF(C19="","",MAX(0,ROUND(G19*(1+H19),2))) -> 4
A20: 18 | B20: 202407699 | C20: KEVIN ANDRE MENDOZA VILLEDA | D20: =IFERROR(INDIRECT(B20 & "!D13"), "0") -> 0 | E20: =IFERROR(INDIRECT(B20 & "!D27"), "0") -> 0 | F20: =IFERROR(INDIRECT(B20 & "!D64"), "0") -> 0 | G20: =IF(C20="","",SUM(D20:F20)) -> 0 | H20: =IFERROR(__xludf.dummyfunction("IFERROR(MIN(FILTER(INDIRECT(B20 & ""!B101:B115""), LEFT(INDIRECT(B20 & ""!C101:C115""),1)=""S"")), ""0%"")"),"0%") -> 0% | I20: =IF(C20="","",MAX(0,ROUND(G20*(1+H20),2))) -> 0
A21: 19 | B21: 202501349 | C21: DIEGO JOSÉ GÓMEZ LÓPEZ | D21: =IFERROR(INDIRECT(B21 & "!D13"), "0") -> 0 | E21: =IFERROR(INDIRECT(B21 & "!D27"), "0") -> 2 | F21: =IFERROR(INDIRECT(B21 & "!D64"), "0") -> 3 | G21: =IF(C21="","",SUM(D21:F21)) -> 5 | H21: =IFERROR(__xludf.dummyfunction("IFERROR(MIN(FILTER(INDIRECT(B21 & ""!B101:B115""), LEFT(INDIRECT(B21 & ""!C101:C115""),1)=""S"")), ""0%"")"),"0%") -> 0% | I21: =IF(C21="","",MAX(0,ROUND(G21*(1+H21),2))) -> 5
A22: 20 | B22: 202501470 | C22: CARLOS ANDRÉS HERNÁNDEZ VÁSQUEZ | D22: =IFERROR(INDIRECT(B22 & "!D13"), "0") -> 0 | E22: =IFERROR(INDIRECT(B22 & "!D27"), "0") -> 2 | F22: =IFERROR(INDIRECT(B22 & "!D64"), "0") -> 3 | G22: =IF(C22="","",SUM(D22:F22)) -> 5 | H22: =IFERROR(__xludf.dummyfunction("IFERROR(MIN(FILTER(INDIRECT(B22 & ""!B101:B115""), LEFT(INDIRECT(B22 & ""!C101:C115""),1)=""S"")), ""0%"")"),"0%") -> 0% | I22: =IF(C22="","",MAX(0,ROUND(G22*(1+H22),2))) -> 5
A23: 21 | B23: 202501625 | C23: CHUNG MIN KIM CHEN | D23: =IFERROR(INDIRECT(B23 & "!D13"), "0") -> 0 | E23: =IFERROR(INDIRECT(B23 & "!D27"), "0") -> 2 | F23: =IFERROR(INDIRECT(B23 & "!D64"), "0") -> 3 | G23: =IF(C23="","",SUM(D23:F23)) -> 5 | H23: =IFERROR(__xludf.dummyfunction("IFERROR(MIN(FILTER(INDIRECT(B23 & ""!B101:B115""), LEFT(INDIRECT(B23 & ""!C101:C115""),1)=""S"")), ""0%"")"),"0%") -> 0% | I23: =IF(C23="","",MAX(0,ROUND(G23*(1+H23),2))) -> 5
A24: 22 | B24: 202502481 | C24: FRANCISCO JAVIER CHIVICHÓN FERNÁNDEZ | D24: =IFERROR(INDIRECT(B24 & "!D13"), "0") -> 0 | E24: =IFERROR(INDIRECT(B24 & "!D27"), "0") -> 0 | F24: =IFERROR(INDIRECT(B24 & "!D64"), "0") -> 0 | G24: =IF(C24="","",SUM(D24:F24)) -> 0 | H24: =IFERROR(__xludf.dummyfunction("IFERROR(MIN(FILTER(INDIRECT(B24 & ""!B101:B115""), LEFT(INDIRECT(B24 & ""!C101:C115""),1)=""S"")), ""0%"")"),"0%") -> 0% | I24: =IF(C24="","",MAX(0,ROUND(G24*(1+H24),2))) -> 0
A25: 23 | B25: 202505830 | C25: NAOMI ROCIO AXPUAC VELASQUEZ | D25: =IFERROR(INDIRECT(B25 & "!D13"), "0") -> 0 | E25: =IFERROR(INDIRECT(B25 & "!D27"), "0") -> 2 | F25: =IFERROR(INDIRECT(B25 & "!D64"), "0") -> 3 | G25: =IF(C25="","",SUM(D25:F25)) -> 5 | H25: =IFERROR(__xludf.dummyfunction("IFERROR(MIN(FILTER(INDIRECT(B25 & ""!B101:B115""), LEFT(INDIRECT(B25 & ""!C101:C115""),1)=""S"")), ""0%"")"),"0%") -> 0% | I25: =IF(C25="","",MAX(0,ROUND(G25*(1+H25),2))) -> 5
A26: 24 | B26: 202507586 | C26: KEVYN JOSUÉ APÉN OTZOY | D26: =IFERROR(INDIRECT(B26 & "!D13"), "0") -> 0 | E26: =IFERROR(INDIRECT(B26 & "!D27"), "0") -> 2 | F26: =IFERROR(INDIRECT(B26 & "!D64"), "0") -> 3 | G26: =IF(C26="","",SUM(D26:F26)) -> 5 | H26: =IFERROR(__xludf.dummyfunction("IFERROR(MIN(FILTER(INDIRECT(B26 & ""!B101:B115""), LEFT(INDIRECT(B26 & ""!C101:C115""),1)=""S"")), ""0%"")"),"0%") -> 0% | I26: =IF(C26="","",MAX(0,ROUND(G26*(1+H26),2))) -> 5
C28: Estudiantes calificados | D28: =COUNT(I3:I26) -> 16
C29: Nota promedio | D29: =IFERROR(AVERAGE(I3:I26),0) -> 0
C30: Nota más alta | D30: =IFERROR(MAX(I3:I26),0) -> 0
C31: Nota más baja | D31: =IFERROR(MIN(I3:I26),0) -> 0
C32: Aprobados (61 pts o más) | D32: =COUNTIF(I3:I26,">=61") -> 0
C33: Reprobados (menos de 61 pts) | D33: =COUNT(I3:I26)-COUNTIF(I3:I26,">=61") -> 16

Sheet Plantilla
A1: UNIVERSIDAD DE SAN CARLOS DE GUATEMALA
A2: FACULTAD DE INGENIERÍA
A3: ESCUELA DE CIENCIAS Y SISTEMAS
A4: Introducción a la Programación y Computación 1, Sección B
A5: Ing William Estuardo Escobar Argueta
A6: Aux. Fernando José Vicente Velásquez
A8: Hoja de Calificación – Proyecto 1: Centro de Rescate Animal: Gestión de Refugio y Adopciones
A10: Fecha de calificación:
A11: Nombre del estudiante: | C11: =VLOOKUP(C12, Consolidado!$B$3:$C$26, 2, 0) -> #N/A
A12: Carné:
A14: Descripción de Ponderación | B14: Valor | C14: Observación | D14: Punteo
A15: 1. HABILIDADES – CÓMO SE PROGRAMA | B15: =B16+B21+B25 -> 20 | D15: =IF(D16+D21+D25=0,"",D16+D21+D25)
A16: 1.1 Documentación | B16: =SUM(B17:B20) -> 8 | D16: =SUM(D17:D20) -> 0
A17: Manual técnico detallado completo y coherente con el código | B17: 2
A18: Manual de usuario con capturas reales y guia para el usuario | B18: 2
A19: Diagramas (flujo, módulos, matriz de ubicaciones) | B19: 2
A20: Informe realizado con herramienta https://aicodedetector.org/ | B20: 2
A21: 1.2 Repositorio GitHub | B21: =SUM(B22:B24) -> 6 | D21: =SUM(D22:D24) -> 0
A22: Formato de nombre correcto y auxiliar agregado como colaborador | B22: 2
A23: Commits progresivos, no concentrados al final | B23: 2
A24: Estructura de carpetas ordenada y proyecto compilable desde el repo | B24: 2
A25: 1.3 Buenas prácticas de código y reportes HTML | B25: =SUM(B26:B28) -> 6 | D25: =SUM(D26:D28) -> 0
A26: Arquitectura ordenada (separación tipo MVC, sin clases gigantes) | B26: 2
A27: Nombres de variables/métodos claros y comentarios útiles | B27: 2
A28: Reportes HTML generados correctamente (formato de nombre, contenido) | B28: 2
A29: 2. CONOCIMIENTO – QUÉ SE PROGRAMA | B29: =B30+B34+B40+B44+B49+B53+B58+B63 -> 55 | D29: =IF(D30+D34+D40+D44+D49+D53+D58+D63=0,"",D30+D34+D40+D44+D49+D53+D58+D63)
A30: 2.1 Autenticación y roles | B30: =SUM(B31:B33) -> 5 | D30: =SUM(D31:D33) -> 0
A31: Login válido contra archivo de usuarios | B31: 2
A32: Permisos diferenciados admin/auxiliar | B32: 2
A33: Manejo de intentos fallidos | B33: 1
A34: 2.2 Animales | B34: =SUM(B35:B39) -> 10 | D34: =SUM(D35:D39) -> 0
A35: Registro con generación de código y validaciones | B35: 3
A36: Búsqueda por código/nombre/especie/estado | B36: 2
A37: Edición de estado clínico y de adopción | B37: 2
A38: Listado y filtro de activos | B38: 1
A39: Eliminación lógica sin romper referencias | B39: 2
A40: 2.3 Adoptantes | B40: =SUM(B41:B43) -> 6 | D40: =SUM(D41:D43) -> 0
A41: Registro con validación de documento/teléfono | B41: 2
A42: Búsqueda por código/nombre/documento | B42: 2
A43: Edición y listado de activos | B43: 2
...

Sheet 202400482
A1: UNIVERSIDAD DE SAN CARLOS DE GUATEMALA
A2: FACULTAD DE INGENIERÍA
A3: ESCUELA DE CIENCIAS Y SISTEMAS
A4: Introducción a la Programación y Computación 1, Sección B
A5: Ing William Estuardo Escobar Argueta
A6: Aux. Fernando José Vicente Velásquez
A8: Hoja de Calificación – Proyecto 1: Centro de Rescate Animal: Gestión de Refugio y Adopciones
A10: Fecha de calificación: | C10: 46252
A11: Nombre del estudiante: | C11: =VLOOKUP(C12, Consolidado!$B$3:$C$26, 2, 0) -> ADRIAN EDUARDO ALVAREZ ZAMBRANO
A12: Carné: | C12: 202400482
A14: Descripción de Ponderación | B14: Valor | C14: Observación | D14: Punteo
A15: 1. HABILIDADES – CÓMO SE PROGRAMA | B15: =B16+B21+B25 -> 20 | D15: =IF(D16+D21+D25=0,"",D16+D21+D25)
A16: 1.1 Documentación | B16: =SUM(B17:B20) -> 8 | D16: =SUM(D17:D20) -> 0
A17: Manual técnico detallado completo y coherente con el código | B17: 2
A18: Manual de usuario con capturas reales y guia para el usuario | B18: 2
A19: Diagramas (flujo, módulos, matriz de ubicaciones) | B19: 2
A20: Informe realizado con herramienta https://aicodedetector.org/ | B20: 2
A21: 1.2 Repositorio GitHub | B21: =SUM(B22:B24) -> 6 | D21: =SUM(D22:D24) -> 0
A22: Formato de nombre correcto y auxiliar agregado como colaborador | B22: 2
A23: Commits progresivos, no concentrados al final | B23: 2
A24: Estructura de carpetas ordenada y proyecto compilable desde el repo | B24: 2
A25: 1.3 Buenas prácticas de código y reportes HTML | B25: =SUM(B26:B28) -> 6 | D25: =SUM(D26:D28) -> 0
A26: Arquitectura ordenada (separación tipo MVC, sin clases gigantes) | B26: 2
A27: Nombres de variables/métodos claros y comentarios útiles | B27: 2
A28: Reportes HTML generados correctamente (formato de nombre, contenido) | B28: 2
A29: 2. CONOCIMIENTO – QUÉ SE PROGRAMA | B29: =B30+B34+B40+B44+B49+B53+B58+B63 -> 55 | D29: =IF(D30+D34+D40+D44+D49+D53+D58+D63=0,"",D30+D34+D40+D44+D49+D53+D58+D63)
A30: 2.1 Autenticación y roles | B30: =SUM(B31:B33) -> 5 | D30: =SUM(D31:D33) -> 0
A31: Login válido contra archivo de usuarios | B31: 2
A32: Permisos diferenciados admin/auxiliar | B32: 2
A33: Manejo de intentos fallidos | B33: 1
A34: 2.2 Animales | B34: =SUM(B35:B39) -> 10 | D34: =SUM(D35:D39) -> 0
A35: Registro con generación de código y validaciones | B35: 3
A36: Búsqueda por código/nombre/especie/estado | B36: 2
A37: Edición de estado clínico y de adopción | B37: 2
A38: Listado y filtro de activos | B38: 1
A39: Eliminación lógica sin romper referencias | B39: 2
A40: 2.3 Adoptantes | B40: =SUM(B41:B43) -> 6 | D40: =SUM(D41:D43) -> 0
A41: Registro con validación de documento/teléfono | B41: 2
A42: Búsqueda por código/nombre/documento | B42: 2
A43: Edición y listado de activos | B43: 2
...

Sheet 202400155
A1: UNIVERSIDAD DE SAN CARLOS DE GUATEMALA
A2: FACULTAD DE INGENIERÍA
A3: ESCUELA DE CIENCIAS Y SISTEMAS
A4: Introducción a la Programación y Computación 1, Sección B
A5: Ing William Estuardo Escobar Argueta
A6: Aux. Fernando José Vicente Velásquez
A8: Hoja de Calificación – Proyecto 1: Centro de Rescate Animal: Gestión de Refugio y Adopciones
A10: Fecha de calificación: | C10: 46283
A11: Nombre del estudiante: | C11: =VLOOKUP(C12, Consolidado!$B$3:$C$26, 2, 0) -> ESVIN FERNANDO ORTEGA GONZÁLEZ
A12: Carné: | C12: 202400155
A14: Descripción de Ponderación | B14: Valor | C14: Observación | D14: Punteo
A15: 1. HABILIDADES – CÓMO SE PROGRAMA | B15: =B16+B21+B25 -> 20 | D15: =IF(D16+D21+D25=0,"",D16+D21+D25) -> 18
A16: 1.1 Documentación | B16: =SUM(B17:B20) -> 8 | D16: =SUM(D17:D20) -> 6
A17: Manual técnico detallado completo y coherente con el código | B17: 2 | D17: 2
A18: Manual de usuario con capturas reales y guia para el usuario | B18: 2 | D18: 2
A19: Diagramas (flujo, módulos, matriz de ubicaciones) | B19: 2 | D19: 2
A20: Informe realizado con herramienta https://aicodedetector.org/ | B20: 2 | D20: 0
A21: 1.2 Repositorio GitHub | B21: =SUM(B22:B24) -> 6 | D21: =SUM(D22:D24) -> 6
A22: Formato de nombre correcto y auxiliar agregado como colaborador | B22: 2 | D22: 2
A23: Commits progresivos, no concentrados al final | B23: 2 | D23: 2
A24: Estructura de carpetas ordenada y proyecto compilable desde el repo | B24: 2 | D24: 2
A25: 1.3 Buenas prácticas de código y reportes HTML | B25: =SUM(B26:B28) -> 6 | D25: =SUM(D26:D28) -> 6
A26: Arquitectura ordenada (separación tipo MVC, sin clases gigantes) | B26: 2 | D26: 2
A27: Nombres de variables/métodos claros y comentarios útiles | B27: 2 | D27: 2
A28: Reportes HTML generados correctamente (formato de nombre, contenido) | B28: 2 | D28: 2
A29: 2. CONOCIMIENTO – QUÉ SE PROGRAMA | B29: =B30+B34+B40+B44+B49+B53+B58+B63 -> 55 | D29: =IF(D30+D34+D40+D44+D49+D53+D58+D63=0,"",D30+D34+D40+D44+D49+D53+D58+D63) -> 47
A30: 2.1 Autenticación y roles | B30: =SUM(B31:B33) -> 5 | D30: =SUM(D31:D33) -> 2
A31: Login válido contra archivo de usuarios | B31: 2 | D31: 2
A32: Permisos diferenciados admin/auxiliar | B32: 2 | D32: 0
A33: Manejo de intentos fallidos | B33: 1 | D33: 0
A34: 2.2 Animales | B34: =SUM(B35:B39) -> 10 | D34: =SUM(D35:D39) -> 10
A35: Registro con generación de código y validaciones | B35: 3 | D35: 3
A36: Búsqueda por código/nombre/especie/estado | B36: 2 | D36: 2
A37: Edición de estado clínico y de adopción | B37: 2 | D37: 2
A38: Listado y filtro de activos | B38: 1 | D38: 1
A39: Eliminación lógica sin romper referencias | B39: 2 | D39: 2
A40: 2.3 Adoptantes | B40: =SUM(B41:B43) -> 6 | D40: =SUM(D41:D43) -> 6
A41: Registro con validación de documento/teléfono | B41: 2 | D41: 2
A42: Búsqueda por código/nombre/documento | B42: 2 | D42: 2
A43: Edición y listado de activos | B43: 2 | D43: 2
...

Sheet 202400066
A1: UNIVERSIDAD DE SAN CARLOS DE GUATEMALA
A2: FACULTAD DE INGENIERÍA
A3: ESCUELA DE CIENCIAS Y SISTEMAS
A4: Introducción a la Programación y Computación 1, Sección B
A5: Ing William Estuardo Escobar Argueta
A6: Aux. Fernando José Vicente Velásquez
A8: Hoja de Calificación – Proyecto 1: Centro de Rescate Animal: Gestión de Refugio y Adopciones
A10: Fecha de calificación:
A11: Nombre del estudiante: | C11: =VLOOKUP(C12, Consolidado!$B$3:$C$26, 2, 0) -> DIEGO SEBASTIAN ALVARADO MORATAYA
A12: Carné: | C12: 202400066
A14: Descripción de Ponderación | B14: Valor | C14: Observación | D14: Punteo
A15: 1. HABILIDADES – CÓMO SE PROGRAMA | B15: =B16+B21+B25 -> 20 | D15: =IF(D16+D21+D25=0,"",D16+D21+D25) -> 18
A16: 1.1 Documentación | B16: =SUM(B17:B20) -> 8 | D16: =SUM(D17:D20) -> 6
A17: Manual técnico detallado completo y coherente con el código | B17: 2 | D17: 2
A18: Manual de usuario con capturas reales y guia para el usuario | B18: 2 | D18: 2
A19: Diagramas (flujo, módulos, matriz de ubicaciones) | B19: 2 | D19: 2
A20: Informe realizado con herramienta https://aicodedetector.org/ | B20: 2 | D20: 0
A21: 1.2 Repositorio GitHub | B21: =SUM(B22:B24) -> 6 | D21: =SUM(D22:D24) -> 6
A22: Formato de nombre correcto y auxiliar agregado como colaborador | B22: 2 | D22: 2
A23: Commits progresivos, no concentrados al final | B23: 2 | D23: 2
A24: Estructura de carpetas ordenada y proyecto compilable desde el repo | B24: 2 | D24: 2
A25: 1.3 Buenas prácticas de código y reportes HTML | B25: =SUM(B26:B28) -> 6 | D25: =SUM(D26:D28) -> 6
A26: Arquitectura ordenada (separación tipo MVC, sin clases gigantes) | B26: 2 | D26: 2
A27: Nombres de variables/métodos claros y comentarios útiles | B27: 2 | D27: 2
A28: Reportes HTML generados correctamente (formato de nombre, contenido) | B28: 2 | D28: 2
A29: 2. CONOCIMIENTO – QUÉ SE PROGRAMA | B29: =B30+B34+B40+B44+B49+B53+B58+B63 -> 55 | D29: =IF(D30+D34+D40+D44+D49+D53+D58+D63=0,"",D30+D34+D40+D44+D49+D53+D58+D63) -> 41.5
A30: 2.1 Autenticación y roles | B30: =SUM(B31:B33) -> 5 | D30: =SUM(D31:D33) -> 2
A31: Login válido contra archivo de usuarios | B31: 2 | D31: 2
A32: Permisos diferenciados admin/auxiliar | B32: 2 | D32: 0
A33: Manejo de intentos fallidos | B33: 1 | D33: 0
A34: 2.2 Animales | B34: =SUM(B35:B39) -> 10 | D34: =SUM(D35:D39) -> 9.5
A35: Registro con generación de código y validaciones | B35: 3 | D35: 3
A36: Búsqueda por código/nombre/especie/estado | B36: 2 | D36: 2
A37: Edición de estado clínico y de adopción | B37: 2 | D37: 2
A38: Listado y filtro de activos | B38: 1 | D38: 0.5
A39: Eliminación lógica sin romper referencias | B39: 2 | D39: 2
A40: 2.3 Adoptantes | B40: =SUM(B41:B43) -> 6 | D40: =SUM(D41:D43) -> 2
A41: Registro con validación de documento/teléfono | B41: 2 | D41: 2
A42: Búsqueda por código/nombre/documento | B42: 2 | D42: 0
A43: Edición y listado de activos | B43: 2 | D43: 0
...

Sheet 202507586
A1: UNIVERSIDAD DE SAN CARLOS DE GUATEMALA
A2: FACULTAD DE INGENIERÍA
A3: ESCUELA DE CIENCIAS Y SISTEMAS
A4: Introducción a la Programación y Computación 1, Sección B
A5: Ing William Estuardo Escobar Argueta
A6: Aux. Fernando José Vicente Velásquez
A8: Hoja de Calificación – Proyecto 1: Centro de Rescate Animal: Gestión de Refugio y Adopciones
A10: Fecha de calificación:
A11: Nombre del estudiante: | C11: =VLOOKUP(C12, Consolidado!$B$3:$C$26, 2, 0) -> KEVYN JOSUÉ APÉN OTZOY
A12: Carné: | C12: 202507586
A14: Descripción de Ponderación | B14: Valor | C14: Observación | D14: Punteo
A15: 1. HABILIDADES – CÓMO SE PROGRAMA | B15: =B16+B21+B25 -> 20 | D15: =IF(D16+D21+D25=0,"",D16+D21+D25) -> 20
A16: 1.1 Documentación | B16: =SUM(B17:B20) -> 8 | D16: =SUM(D17:D20) -> 8
A17: Manual técnico detallado completo y coherente con el código | B17: 2 | D17: 2
A18: Manual de usuario con capturas reales y guia para el usuario | B18: 2 | D18: 2
A19: Diagramas (flujo, módulos, matriz de ubicaciones) | B19: 2 | D19: 2
A20: Informe realizado con herramienta https://aicodedetector.org/ | B20: 2 | D20: 2
A21: 1.2 Repositorio GitHub | B21: =SUM(B22:B24) -> 6 | D21: =SUM(D22:D24) -> 6
A22: Formato de nombre correcto y auxiliar agregado como colaborador | B22: 2 | D22: 2
A23: Commits progresivos, no concentrados al final | B23: 2 | D23: 2
A24: Estructura de carpetas ordenada y proyecto compilable desde el repo | B24: 2 | D24: 2
A25: 1.3 Buenas prácticas de código y reportes HTML | B25: =SUM(B26:B28) -> 6 | D25: =SUM(D26:D28) -> 6
A26: Arquitectura ordenada (separación tipo MVC, sin clases gigantes) | B26: 2 | D26: 2
A27: Nombres de variables/métodos claros y comentarios útiles | B27: 2 | D27: 2
A28: Reportes HTML generados correctamente (formato de nombre, contenido) | B28: 2 | D28: 2
A29: 2. CONOCIMIENTO – QUÉ SE PROGRAMA | B29: =B30+B34+B40+B44+B49+B53+B58+B63 -> 55 | D29: =IF(D30+D34+D40+D44+D49+D53+D58+D63=0,"",D30+D34+D40+D44+D49+D53+D58+D63) -> 22
A30: 2.1 Autenticación y roles | B30: =SUM(B31:B33) -> 5 | D30: =SUM(D31:D33) -> 3
A31: Login válido contra archivo de usuarios | B31: 2 | D31: 2
A32: Permisos diferenciados admin/auxiliar | B32: 2 | D32: 1
A33: Manejo de intentos fallidos | B33: 1 | D33: 0
A34: 2.2 Animales | B34: =SUM(B35:B39) -> 10 | D34: =SUM(D35:D39) -> 3
A35: Registro con generación de código y validaciones | B35: 3 | D35: 3
A36: Búsqueda por código/nombre/especie/estado | B36: 2 | D36: 0
A37: Edición de estado clínico y de adopción | B37: 2 | D37: 0
A38: Listado y filtro de activos | B38: 1 | D38: 0
A39: Eliminación lógica sin romper referencias | B39: 2 | D39: 0
A40: 2.3 Adoptantes | B40: =SUM(B41:B43) -> 6 | D40: =SUM(D41:D43) -> 2
A41: Registro con validación de documento/teléfono | B41: 2 | D41: 2
A42: Búsqueda por código/nombre/documento | B42: 2 | D42: 0
A43: Edición y listado de activos | B43: 2 | D43: 0
...

Sheet 202404528
A1: UNIVERSIDAD DE SAN CARLOS DE GUATEMALA
A2: FACULTAD DE INGENIERÍA
A3: ESCUELA DE CIENCIAS Y SISTEMAS
A4: Introducción a la Programación y Computación 1, Sección B
A5: Ing William Estuardo Escobar Argueta
A6: Aux. Fernando José Vicente Velásquez
A8: Hoja de Calificación – Proyecto 1: Centro de Rescate Animal: Gestión de Refugio y Adopciones
A10: Fecha de calificación:
A11: Nombre del estudiante: | C11: =VLOOKUP(C12, Consolidado!$B$3:$C$26, 2, 0) -> MELISSA GRISSEL PEREZ RIVAS
A12: Carné: | C12: 202404528
A14: Descripción de Ponderación | B14: Valor | C14: Observación | D14: Punteo
A15: 1. HABILIDADES – CÓMO SE PROGRAMA | B15: =B16+B21+B25 -> 20 | D15: =IF(D16+D21+D25=0,"",D16+D21+D25) -> 16
A16: 1.1 Documentación | B16: =SUM(B17:B20) -> 8 | D16: =SUM(D17:D20) -> 6
A17: Manual técnico detallado completo y coherente con el código | B17: 2 | D17: 2
A18: Manual de usuario con capturas reales y guia para el usuario | B18: 2 | D18: 2
A19: Diagramas (flujo, módulos, matriz de ubicaciones) | B19: 2 | D19: 2
A20: Informe realizado con herramienta https://aicodedetector.org/ | B20: 2 | D20: 0
A21: 1.2 Repositorio GitHub | B21: =SUM(B22:B24) -> 6 | D21: =SUM(D22:D24) -> 6
A22: Formato de nombre correcto y auxiliar agregado como colaborador | B22: 2 | D22: 2
A23: Commits progresivos, no concentrados al final | B23: 2 | D23: 2
A24: Estructura de carpetas ordenada y proyecto compilable desde el repo | B24: 2 | D24: 2
A25: 1.3 Buenas prácticas de código y reportes HTML | B25: =SUM(B26:B28) -> 6 | D25: =SUM(D26:D28) -> 4
A26: Arquitectura ordenada (separación tipo MVC, sin clases gigantes) | B26: 2 | D26: 2
A27: Nombres de variables/métodos claros y comentarios útiles | B27: 2 | D27: 0
A28: Reportes HTML generados correctamente (formato de nombre, contenido) | B28: 2 | D28: 2
A29: 2. CONOCIMIENTO – QUÉ SE PROGRAMA | B29: =B30+B34+B40+B44+B49+B53+B58+B63 -> 55 | D29: =IF(D30+D34+D40+D44+D49+D53+D58+D63=0,"",D30+D34+D40+D44+D49+D53+D58+D63) -> 40.5
A30: 2.1 Autenticación y roles | B30: =SUM(B31:B33) -> 5 | D30: =SUM(D31:D33) -> 2.5
A31: Login válido contra archivo de usuarios | B31: 2 | D31: 2
A32: Permisos diferenciados admin/auxiliar | B32: 2 | D32: 0
A33: Manejo de intentos fallidos | B33: 1 | D33: 0.5
A34: 2.2 Animales | B34: =SUM(B35:B39) -> 10 | D34: =SUM(D35:D39) -> 4
A35: Registro con generación de código y validaciones | B35: 3 | D35: 3
A36: Búsqueda por código/nombre/especie/estado | B36: 2 | D36: 0
A37: Edición de estado clínico y de adopción | B37: 2 | D37: 0
A38: Listado y filtro de activos | B38: 1 | D38: 1
A39: Eliminación lógica sin romper referencias | B39: 2 | D39: 0
A40: 2.3 Adoptantes | B40: =SUM(B41:B43) -> 6 | D40: =SUM(D41:D43) -> 3
A41: Registro con validación de documento/teléfono | B41: 2 | D41: 2
A42: Búsqueda por código/nombre/documento | B42: 2 | D42: 0
A43: Edición y listado de activos | B43: 2 | D43: 1
...

Sheet 202405048
A1: UNIVERSIDAD DE SAN CARLOS DE GUATEMALA
A2: FACULTAD DE INGENIERÍA
A3: ESCUELA DE CIENCIAS Y SISTEMAS
A4: Introducción a la Programación y Computación 1, Sección B
A5: Ing William Estuardo Escobar Argueta
A6: Aux. Fernando José Vicente Velásquez
A8: Hoja de Calificación – Proyecto 1: Centro de Rescate Animal: Gestión de Refugio y Adopciones
A10: Fecha de calificación:
A11: Nombre del estudiante: | C11: =VLOOKUP(C12, Consolidado!$B$3:$C$26, 2, 0) -> MONIKA ESTEFANIA CRUZ PALACIOS
A12: Carné: | C12: 202405048
A14: Descripción de Ponderación | B14: Valor | C14: Observación | D14: Punteo
A15: 1. HABILIDADES – CÓMO SE PROGRAMA | B15: =B16+B21+B25 -> 20 | D15: =IF(D16+D21+D25=0,"",D16+D21+D25) -> 18
A16: 1.1 Documentación | B16: =SUM(B17:B20) -> 8 | D16: =SUM(D17:D20) -> 8
A17: Manual técnico detallado completo y coherente con el código | B17: 2 | D17: 2
A18: Manual de usuario con capturas reales y guia para el usuario | B18: 2 | D18: 2
A19: Diagramas (flujo, módulos, matriz de ubicaciones) | B19: 2 | D19: 2
A20: Informe realizado con herramienta https://aicodedetector.org/ | B20: 2 | D20: 2
A21: 1.2 Repositorio GitHub | B21: =SUM(B22:B24) -> 6 | D21: =SUM(D22:D24) -> 6
A22: Formato de nombre correcto y auxiliar agregado como colaborador | B22: 2 | D22: 2
A23: Commits progresivos, no concentrados al final | B23: 2 | D23: 2
A24: Estructura de carpetas ordenada y proyecto compilable desde el repo | B24: 2 | D24: 2
A25: 1.3 Buenas prácticas de código y reportes HTML | B25: =SUM(B26:B28) -> 6 | D25: =SUM(D26:D28) -> 4
A26: Arquitectura ordenada (separación tipo MVC, sin clases gigantes) | B26: 2 | D26: 2
A27: Nombres de variables/métodos claros y comentarios útiles | B27: 2 | D27: 2
A28: Reportes HTML generados correctamente (formato de nombre, contenido) | B28: 2 | D28: 0
A29: 2. CONOCIMIENTO – QUÉ SE PROGRAMA | B29: =B30+B34+B40+B44+B49+B53+B58+B63 -> 55 | D29: =IF(D30+D34+D40+D44+D49+D53+D58+D63=0,"",D30+D34+D40+D44+D49+D53+D58+D63) -> 47
A30: 2.1 Autenticación y roles | B30: =SUM(B31:B33) -> 5 | D30: =SUM(D31:D33) -> 3
A31: Login válido contra archivo de usuarios | B31: 2 | D31: 2
A32: Permisos diferenciados admin/auxiliar | B32: 2 | D32: 1
A33: Manejo de intentos fallidos | B33: 1 | D33: 0
A34: 2.2 Animales | B34: =SUM(B35:B39) -> 10 | D34: =SUM(D35:D39) -> 10
A35: Registro con generación de código y validaciones | B35: 3 | D35: 3
A36: Búsqueda por código/nombre/especie/estado | B36: 2 | D36: 2
A37: Edición de estado clínico y de adopción | B37: 2 | D37: 2
A38: Listado y filtro de activos | B38: 1 | D38: 1
A39: Eliminación lógica sin romper referencias | B39: 2 | D39: 2
A40: 2.3 Adoptantes | B40: =SUM(B41:B43) -> 6 | D40: =SUM(D41:D43) -> 6
A41: Registro con validación de documento/teléfono | B41: 2 | D41: 2
A42: Búsqueda por código/nombre/documento | B42: 2 | D42: 2
A43: Edición y listado de activos | B43: 2 | D43: 2
...

Sheet 202501625
A1: UNIVERSIDAD DE SAN CARLOS DE GUATEMALA
A2: FACULTAD DE INGENIERÍA
A3: ESCUELA DE CIENCIAS Y SISTEMAS
A4: Introducción a la Programación y Computación 1, Sección B
A5: Ing William Estuardo Escobar Argueta
A6: Aux. Fernando José Vicente Velásquez
A8: Hoja de Calificación – Proyecto 1: Centro de Rescate Animal: Gestión de Refugio y Adopciones
A10: Fecha de calificación:
A11: Nombre del estudiante: | C11: =VLOOKUP(C12, Consolidado!$B$3:$C$26, 2, 0) -> CHUNG MIN KIM CHEN
A12: Carné: | C12: 202501625
A14: Descripción de Ponderación | B14: Valor | C14: Observación | D14: Punteo
A15: 1. HABILIDADES – CÓMO SE PROGRAMA | B15: =B16+B21+B25 -> 20 | D15: =IF(D16+D21+D25=0,"",D16+D21+D25) -> 20
A16: 1.1 Documentación | B16: =SUM(B17:B20) -> 8 | D16: =SUM(D17:D20) -> 8
A17: Manual técnico detallado completo y coherente con el código | B17: 2 | D17: 2
A18: Manual de usuario con capturas reales y guia para el usuario | B18: 2 | D18: 2
A19: Diagramas (flujo, módulos, matriz de ubicaciones) | B19: 2 | D19: 2
A20: Informe realizado con herramienta https://aicodedetector.org/ | B20: 2 | D20: 2
A21: 1.2 Repositorio GitHub | B21: =SUM(B22:B24) -> 6 | D21: =SUM(D22:D24) -> 6
A22: Formato de nombre correcto y auxiliar agregado como colaborador | B22: 2 | D22: 2
A23: Commits progresivos, no concentrados al final | B23: 2 | D23: 2
A24: Estructura de carpetas ordenada y proyecto compilable desde el repo | B24: 2 | D24: 2
A25: 1.3 Buenas prácticas de código y reportes HTML | B25: =SUM(B26:B28) -> 6 | D25: =SUM(D26:D28) -> 6
A26: Arquitectura ordenada (separación tipo MVC, sin clases gigantes) | B26: 2 | D26: 2
A27: Nombres de variables/métodos claros y comentarios útiles | B27: 2 | D27: 2
A28: Reportes HTML generados correctamente (formato de nombre, contenido) | B28: 2 | D28: 2
A29: 2. CONOCIMIENTO – QUÉ SE PROGRAMA | B29: =B30+B34+B40+B44+B49+B53+B58+B63 -> 55 | D29: =IF(D30+D34+D40+D44+D49+D53+D58+D63=0,"",D30+D34+D40+D44+D49+D53+D58+D63) -> 51
A30: 2.1 Autenticación y roles | B30: =SUM(B31:B33) -> 5 | D30: =SUM(D31:D33) -> 3
A31: Login válido contra archivo de usuarios | B31: 2 | D31: 2
A32: Permisos diferenciados admin/auxiliar | B32: 2 | D32: 1
A33: Manejo de intentos fallidos | B33: 1 | D33: 0
A34: 2.2 Animales | B34: =SUM(B35:B39) -> 10 | D34: =SUM(D35:D39) -> 10
A35: Registro con generación de código y validaciones | B35: 3 | D35: 3
A36: Búsqueda por código/nombre/especie/estado | B36: 2 | D36: 2
A37: Edición de estado clínico y de adopción | B37: 2 | D37: 2
A38: Listado y filtro de activos | B38: 1 | D38: 1
A39: Eliminación lógica sin romper referencias | B39: 2 | D39: 2
A40: 2.3 Adoptantes | B40: =SUM(B41:B43) -> 6 | D40: =SUM(D41:D43) -> 6
A41: Registro con validación de documento/teléfono | B41: 2 | D41: 2
A42: Búsqueda por código/nombre/documento | B42: 2 | D42: 2
A43: Edición y listado de activos | B43: 2 | D43: 2
...

Sheet 202406816
A1: UNIVERSIDAD DE SAN CARLOS DE GUATEMALA
A2: FACULTAD DE INGENIERÍA
A3: ESCUELA DE CIENCIAS Y SISTEMAS
A4: Introducción a la Programación y Computación 1, Sección B
A5: Ing William Estuardo Escobar Argueta
A6: Aux. Fernando José Vicente Velásquez
A8: Hoja de Calificación – Proyecto 1: Centro de Rescate Animal: Gestión de Refugio y Adopciones
A10: Fecha de calificación:
A11: Nombre del estudiante: | C11: =VLOOKUP(C12, Consolidado!$B$3:$C$26, 2, 0) -> EVELYN ARACELY CARDONA AGUILON
A12: Carné: | C12: 202406816
A14: Descripción de Ponderación | B14: Valor | C14: Observación | D14: Punteo
A15: 1. HABILIDADES – CÓMO SE PROGRAMA | B15: =B16+B21+B25 -> 20 | D15: =IF(D16+D21+D25=0,"",D16+D21+D25) -> 17
A16: 1.1 Documentación | B16: =SUM(B17:B20) -> 8 | D16: =SUM(D17:D20) -> 8
A17: Manual técnico detallado completo y coherente con el código | B17: 2 | D17: 2
A18: Manual de usuario con capturas reales y guia para el usuario | B18: 2 | D18: 2
A19: Diagramas (flujo, módulos, matriz de ubicaciones) | B19: 2 | D19: 2
A20: Informe realizado con herramienta https://aicodedetector.org/ | B20: 2 | D20: 2
A21: 1.2 Repositorio GitHub | B21: =SUM(B22:B24) -> 6 | D21: =SUM(D22:D24) -> 6
A22: Formato de nombre correcto y auxiliar agregado como colaborador | B22: 2 | D22: 2
A23: Commits progresivos, no concentrados al final | B23: 2 | D23: 2
A24: Estructura de carpetas ordenada y proyecto compilable desde el repo | B24: 2 | D24: 2
A25: 1.3 Buenas prácticas de código y reportes HTML | B25: =SUM(B26:B28) -> 6 | D25: =SUM(D26:D28) -> 3
A26: Arquitectura ordenada (separación tipo MVC, sin clases gigantes) | B26: 2 | D26: 1
A27: Nombres de variables/métodos claros y comentarios útiles | B27: 2 | D27: 1
A28: Reportes HTML generados correctamente (formato de nombre, contenido) | B28: 2 | D28: 1
A29: 2. CONOCIMIENTO – QUÉ SE PROGRAMA | B29: =B30+B34+B40+B44+B49+B53+B58+B63 -> 55 | D29: =IF(D30+D34+D40+D44+D49+D53+D58+D63=0,"",D30+D34+D40+D44+D49+D53+D58+D63) -> 50.5
A30: 2.1 Autenticación y roles | B30: =SUM(B31:B33) -> 5 | D30: =SUM(D31:D33) -> 3.5
A31: Login válido contra archivo de usuarios | B31: 2 | D31: 2
A32: Permisos diferenciados admin/auxiliar | B32: 2 | D32: 1
A33: Manejo de intentos fallidos | B33: 1 | D33: 0.5
A34: 2.2 Animales | B34: =SUM(B35:B39) -> 10 | D34: =SUM(D35:D39) -> 10
A35: Registro con generación de código y validaciones | B35: 3 | D35: 3
A36: Búsqueda por código/nombre/especie/estado | B36: 2 | D36: 2
A37: Edición de estado clínico y de adopción | B37: 2 | D37: 2
A38: Listado y filtro de activos | B38: 1 | D38: 1
A39: Eliminación lógica sin romper referencias | B39: 2 | D39: 2
A40: 2.3 Adoptantes | B40: =SUM(B41:B43) -> 6 | D40: =SUM(D41:D43) -> 6
A41: Registro con validación de documento/teléfono | B41: 2 | D41: 2
A42: Búsqueda por código/nombre/documento | B42: 2 | D42: 2
A43: Edición y listado de activos | B43: 2 | D43: 2
...

Sheet 202501349
A1: UNIVERSIDAD DE SAN CARLOS DE GUATEMALA
A2: FACULTAD DE INGENIERÍA
A3: ESCUELA DE CIENCIAS Y SISTEMAS
A4: Introducción a la Programación y Computación 1, Sección B
A5: Ing William Estuardo Escobar Argueta
A6: Aux. Fernando José Vicente Velásquez
A8: Hoja de Calificación – Proyecto 1: Centro de Rescate Animal: Gestión de Refugio y Adopciones
A10: Fecha de calificación: | C10: 46283
A11: Nombre del estudiante: | C11: =VLOOKUP(C12, Consolidado!$B$3:$C$26, 2, 0) -> DIEGO JOSÉ GÓMEZ LÓPEZ
A12: Carné: | C12: 202501349
A14: Descripción de Ponderación | B14: Valor | C14: Observación | D14: Punteo
A15: 1. HABILIDADES – CÓMO SE PROGRAMA | B15: =B16+B21+B25 -> 20 | D15: =IF(D16+D21+D25=0,"",D16+D21+D25) -> 20
A16: 1.1 Documentación | B16: =SUM(B17:B20) -> 8 | D16: =SUM(D17:D20) -> 8
A17: Manual técnico detallado completo y coherente con el código | B17: 2 | D17: 2
A18: Manual de usuario con capturas reales y guia para el usuario | B18: 2 | D18: 2
A19: Diagramas (flujo, módulos, matriz de ubicaciones) | B19: 2 | D19: 2
A20: Informe realizado con herramienta https://aicodedetector.org/ | B20: 2 | D20: 2
A21: 1.2 Repositorio GitHub | B21: =SUM(B22:B24) -> 6 | D21: =SUM(D22:D24) -> 6
A22: Formato de nombre correcto y auxiliar agregado como colaborador | B22: 2 | D22: 2
A23: Commits progresivos, no concentrados al final | B23: 2 | D23: 2
A24: Estructura de carpetas ordenada y proyecto compilable desde el repo | B24: 2 | D24: 2
A25: 1.3 Buenas prácticas de código y reportes HTML | B25: =SUM(B26:B28) -> 6 | D25: =SUM(D26:D28) -> 6
A26: Arquitectura ordenada (separación tipo MVC, sin clases gigantes) | B26: 2 | D26: 2
A27: Nombres de variables/métodos claros y comentarios útiles | B27: 2 | D27: 2
A28: Reportes HTML generados correctamente (formato de nombre, contenido) | B28: 2 | D28: 2
A29: 2. CONOCIMIENTO – QUÉ SE PROGRAMA | B29: =B30+B34+B40+B44+B49+B53+B58+B63 -> 55 | D29: =IF(D30+D34+D40+D44+D49+D53+D58+D63=0,"",D30+D34+D40+D44+D49+D53+D58+D63) -> 45.5
A30: 2.1 Autenticación y roles | B30: =SUM(B31:B33) -> 5 | D30: =SUM(D31:D33) -> 3
A31: Login válido contra archivo de usuarios | B31: 2 | D31: 2
A32: Permisos diferenciados admin/auxiliar | B32: 2 | D32: 1
A33: Manejo de intentos fallidos | B33: 1 | D33: 0
A34: 2.2 Animales | B34: =SUM(B35:B39) -> 10 | D34: =SUM(D35:D39) -> 9.5
A35: Registro con generación de código y validaciones | B35: 3 | D35: 3
A36: Búsqueda por código/nombre/especie/estado | B36: 2 | D36: 2
A37: Edición de estado clínico y de adopción | B37: 2 | D37: 2
A38: Listado y filtro de activos | B38: 1 | D38: 0.5
A39: Eliminación lógica sin romper referencias | B39: 2 | D39: 2
A40: 2.3 Adoptantes | B40: =SUM(B41:B43) -> 6 | D40: =SUM(D41:D43) -> 6
A41: Registro con validación de documento/teléfono | B41: 2 | D41: 2
A42: Búsqueda por código/nombre/documento | B42: 2 | D42: 2
A43: Edición y listado de activos | B43: 2 | D43: 2
...

Sheet 202403338
A1: UNIVERSIDAD DE SAN CARLOS DE GUATEMALA
A2: FACULTAD DE INGENIERÍA
A3: ESCUELA DE CIENCIAS Y SISTEMAS
A4: Introducción a la Programación y Computación 1, Sección B
A5: Ing William Estuardo Escobar Argueta
A6: Aux. Fernando José Vicente Velásquez
A8: Hoja de Calificación – Proyecto 1: Centro de Rescate Animal: Gestión de Refugio y Adopciones
A10: Fecha de calificación: | C10: 46282
A11: Nombre del estudiante: | C11: =VLOOKUP(C12, Consolidado!$B$3:$C$26, 2, 0) -> ANDY RAÍ TELÓN GABRIEL
A12: Carné: | C12: 202403338
A14: Descripción de Ponderación | B14: Valor | C14: Observación | D14: Punteo
A15: 1. HABILIDADES – CÓMO SE PROGRAMA | B15: =B16+B21+B25 -> 20 | D15: =IF(D16+D21+D25=0,"",D16+D21+D25) -> 15
A16: 1.1 Documentación | B16: =SUM(B17:B20) -> 8 | D16: =SUM(D17:D20) -> 3
A17: Manual técnico detallado completo y coherente con el código | B17: 2 | D17: 2
A18: Manual de usuario con capturas reales y guia para el usuario | B18: 2 | D18: 1
A19: Diagramas (flujo, módulos, matriz de ubicaciones) | B19: 2 | D19: 0
A20: Informe realizado con herramienta https://aicodedetector.org/ | B20: 2 | D20: 0
A21: 1.2 Repositorio GitHub | B21: =SUM(B22:B24) -> 6 | D21: =SUM(D22:D24) -> 6
A22: Formato de nombre correcto y auxiliar agregado como colaborador | B22: 2 | D22: 2
A23: Commits progresivos, no concentrados al final | B23: 2 | D23: 2
A24: Estructura de carpetas ordenada y proyecto compilable desde el repo | B24: 2 | D24: 2
A25: 1.3 Buenas prácticas de código y reportes HTML | B25: =SUM(B26:B28) -> 6 | D25: =SUM(D26:D28) -> 6
A26: Arquitectura ordenada (separación tipo MVC, sin clases gigantes) | B26: 2 | D26: 2
A27: Nombres de variables/métodos claros y comentarios útiles | B27: 2 | D27: 2
A28: Reportes HTML generados correctamente (formato de nombre, contenido) | B28: 2 | D28: 2
A29: 2. CONOCIMIENTO – QUÉ SE PROGRAMA | B29: =B30+B34+B40+B44+B49+B53+B58+B63 -> 55 | D29: =IF(D30+D34+D40+D44+D49+D53+D58+D63=0,"",D30+D34+D40+D44+D49+D53+D58+D63) -> 50.5
A30: 2.1 Autenticación y roles | B30: =SUM(B31:B33) -> 5 | D30: =SUM(D31:D33) -> 2
A31: Login válido contra archivo de usuarios | B31: 2 | D31: 2
A32: Permisos diferenciados admin/auxiliar | B32: 2 | D32: 0
A33: Manejo de intentos fallidos | B33: 1 | D33: 0
A34: 2.2 Animales | B34: =SUM(B35:B39) -> 10 | D34: =SUM(D35:D39) -> 10
A35: Registro con generación de código y validaciones | B35: 3 | D35: 3
A36: Búsqueda por código/nombre/especie/estado | B36: 2 | D36: 2
A37: Edición de estado clínico y de adopción | B37: 2 | D37: 2
A38: Listado y filtro de activos | B38: 1 | D38: 1
A39: Eliminación lógica sin romper referencias | B39: 2 | D39: 2
A40: 2.3 Adoptantes | B40: =SUM(B41:B43) -> 6 | D40: =SUM(D41:D43) -> 6
A41: Registro con validación de documento/teléfono | B41: 2 | D41: 2
A42: Búsqueda por código/nombre/documento | B42: 2 | D42: 2
A43: Edición y listado de activos | B43: 2 | D43: 2
...

Sheet 202505830
A1: UNIVERSIDAD DE SAN CARLOS DE GUATEMALA
A2: FACULTAD DE INGENIERÍA
A3: ESCUELA DE CIENCIAS Y SISTEMAS
A4: Introducción a la Programación y Computación 1, Sección B
A5: Ing William Estuardo Escobar Argueta
A6: Aux. Fernando José Vicente Velásquez
A8: Hoja de Calificación – Proyecto 1: Centro de Rescate Animal: Gestión de Refugio y Adopciones
A10: Fecha de calificación: | C10: 46282
A11: Nombre del estudiante: | C11: =VLOOKUP(C12, Consolidado!$B$3:$C$26, 2, 0) -> NAOMI ROCIO AXPUAC VELASQUEZ
A12: Carné: | C12: 202505830
A14: Descripción de Ponderación | B14: Valor | C14: Observación | D14: Punteo
A15: 1. HABILIDADES – CÓMO SE PROGRAMA | B15: =B16+B21+B25 -> 20 | D15: =IF(D16+D21+D25=0,"",D16+D21+D25) -> 20
A16: 1.1 Documentación | B16: =SUM(B17:B20) -> 8 | D16: =SUM(D17:D20) -> 8
A17: Manual técnico detallado completo y coherente con el código | B17: 2 | D17: 2
A18: Manual de usuario con capturas reales y guia para el usuario | B18: 2 | D18: 2
A19: Diagramas (flujo, módulos, matriz de ubicaciones) | B19: 2 | D19: 2
A20: Informe realizado con herramienta https://aicodedetector.org/ | B20: 2 | D20: 2
A21: 1.2 Repositorio GitHub | B21: =SUM(B22:B24) -> 6 | D21: =SUM(D22:D24) -> 6
A22: Formato de nombre correcto y auxiliar agregado como colaborador | B22: 2 | D22: 2
A23: Commits progresivos, no concentrados al final | B23: 2 | D23: 2
A24: Estructura de carpetas ordenada y proyecto compilable desde el repo | B24: 2 | D24: 2
A25: 1.3 Buenas prácticas de código y reportes HTML | B25: =SUM(B26:B28) -> 6 | D25: =SUM(D26:D28) -> 6
A26: Arquitectura ordenada (separación tipo MVC, sin clases gigantes) | B26: 2 | D26: 2
A27: Nombres de variables/métodos claros y comentarios útiles | B27: 2 | D27: 2
A28: Reportes HTML generados correctamente (formato de nombre, contenido) | B28: 2 | D28: 2
A29: 2. CONOCIMIENTO – QUÉ SE PROGRAMA | B29: =B30+B34+B40+B44+B49+B53+B58+B63 -> 55 | D29: =IF(D30+D34+D40+D44+D49+D53+D58+D63=0,"",D30+D34+D40+D44+D49+D53+D58+D63) -> 42.5
A30: 2.1 Autenticación y roles | B30: =SUM(B31:B33) -> 5 | D30: =SUM(D31:D33) -> 2
A31: Login válido contra archivo de usuarios | B31: 2 | D31: 2
A32: Permisos diferenciados admin/auxiliar | B32: 2 | D32: 0
A33: Manejo de intentos fallidos | B33: 1 | D33: 0
A34: 2.2 Animales | B34: =SUM(B35:B39) -> 10 | D34: =SUM(D35:D39) -> 10
A35: Registro con generación de código y validaciones | B35: 3 | D35: 3
A36: Búsqueda por código/nombre/especie/estado | B36: 2 | D36: 2
A37: Edición de estado clínico y de adopción | B37: 2 | D37: 2
A38: Listado y filtro de activos | B38: 1 | D38: 1
A39: Eliminación lógica sin romper referencias | B39: 2 | D39: 2
A40: 2.3 Adoptantes | B40: =SUM(B41:B43) -> 6 | D40: =SUM(D41:D43) -> 5
A41: Registro con validación de documento/teléfono | B41: 2 | D41: 2
A42: Búsqueda por código/nombre/documento | B42: 2 | D42: 2
A43: Edición y listado de activos | B43: 2 | D43: 1
...

Sheet 202201204
A1: UNIVERSIDAD DE SAN CARLOS DE GUATEMALA
A2: FACULTAD DE INGENIERÍA
A3: ESCUELA DE CIENCIAS Y SISTEMAS
A4: Introducción a la Programación y Computación 1, Sección B
A5: Ing William Estuardo Escobar Argueta
A6: Aux. Fernando José Vicente Velásquez
A8: Hoja de Calificación – Proyecto 1: Centro de Rescate Animal: Gestión de Refugio y Adopciones
A10: Fecha de calificación: | C10: 46282
A11: Nombre del estudiante: | C11: =VLOOKUP(C12, Consolidado!$B$3:$C$26, 2, 0) -> BRYAN ALEXANDER MARTÍNEZ FLORES
A12: Carné: | C12: 202201204
A14: Descripción de Ponderación | B14: Valor | C14: Observación | D14: Punteo
A15: 1. HABILIDADES – CÓMO SE PROGRAMA | B15: =B16+B21+B25 -> 20 | D15: =IF(D16+D21+D25=0,"",D16+D21+D25) -> 12
A16: 1.1 Documentación | B16: =SUM(B17:B20) -> 8 | D16: =SUM(D17:D20) -> 0
A17: Manual técnico detallado completo y coherente con el código | B17: 2 | D17: 0
A18: Manual de usuario con capturas reales y guia para el usuario | B18: 2 | D18: 0
A19: Diagramas (flujo, módulos, matriz de ubicaciones) | B19: 2 | D19: 0
A20: Informe realizado con herramienta https://aicodedetector.org/ | B20: 2 | D20: 0
A21: 1.2 Repositorio GitHub | B21: =SUM(B22:B24) -> 6 | D21: =SUM(D22:D24) -> 6
A22: Formato de nombre correcto y auxiliar agregado como colaborador | B22: 2 | D22: 2
A23: Commits progresivos, no concentrados al final | B23: 2 | D23: 2
A24: Estructura de carpetas ordenada y proyecto compilable desde el repo | B24: 2 | D24: 2
A25: 1.3 Buenas prácticas de código y reportes HTML | B25: =SUM(B26:B28) -> 6 | D25: =SUM(D26:D28) -> 6
A26: Arquitectura ordenada (separación tipo MVC, sin clases gigantes) | B26: 2 | D26: 2
A27: Nombres de variables/métodos claros y comentarios útiles | B27: 2 | D27: 2
A28: Reportes HTML generados correctamente (formato de nombre, contenido) | B28: 2 | D28: 2
A29: 2. CONOCIMIENTO – QUÉ SE PROGRAMA | B29: =B30+B34+B40+B44+B49+B53+B58+B63 -> 55 | D29: =IF(D30+D34+D40+D44+D49+D53+D58+D63=0,"",D30+D34+D40+D44+D49+D53+D58+D63) -> 35
A30: 2.1 Autenticación y roles | B30: =SUM(B31:B33) -> 5 | D30: =SUM(D31:D33) -> 0
A31: Login válido contra archivo de usuarios | B31: 2 | D31: 0
A32: Permisos diferenciados admin/auxiliar | B32: 2 | D32: 0
A33: Manejo de intentos fallidos | B33: 1 | D33: 0
A34: 2.2 Animales | B34: =SUM(B35:B39) -> 10 | D34: =SUM(D35:D39) -> 10
A35: Registro con generación de código y validaciones | B35: 3 | D35: 3
A36: Búsqueda por código/nombre/especie/estado | B36: 2 | D36: 2
A37: Edición de estado clínico y de adopción | B37: 2 | D37: 2
A38: Listado y filtro de activos | B38: 1 | D38: 1
A39: Eliminación lógica sin romper referencias | B39: 2 | D39: 2
A40: 2.3 Adoptantes | B40: =SUM(B41:B43) -> 6 | D40: =SUM(D41:D43) -> 4
A41: Registro con validación de documento/teléfono | B41: 2 | D41: 2
A42: Búsqueda por código/nombre/documento | B42: 2 | D42: 2
A43: Edición y listado de activos | B43: 2 | D43: 0
...

Sheet 202308203
A1: UNIVERSIDAD DE SAN CARLOS DE GUATEMALA
A2: FACULTAD DE INGENIERÍA
A3: ESCUELA DE CIENCIAS Y SISTEMAS
A4: Introducción a la Programación y Computación 1, Sección B
A5: Ing William Estuardo Escobar Argueta
A6: Aux. Fernando José Vicente Velásquez
A8: Hoja de Calificación – Proyecto 1: Centro de Rescate Animal: Gestión de Refugio y Adopciones
A10: Fecha de calificación:
A11: Nombre del estudiante: | C11: =VLOOKUP(C12, Consolidado!$B$3:$C$26, 2, 0) -> HANS CRISTIAN MEYER DIAZ
A12: Carné: | C12: 202308203
A14: Descripción de Ponderación | B14: Valor | C14: Observación | D14: Punteo
A15: 1. HABILIDADES – CÓMO SE PROGRAMA | B15: =B16+B21+B25 -> 20 | D15: =IF(D16+D21+D25=0,"",D16+D21+D25) -> 16
A16: 1.1 Documentación | B16: =SUM(B17:B20) -> 8 | D16: =SUM(D17:D20) -> 6
A17: Manual técnico detallado completo y coherente con el código | B17: 2 | D17: 2
A18: Manual de usuario con capturas reales y guia para el usuario | B18: 2 | D18: 2
A19: Diagramas (flujo, módulos, matriz de ubicaciones) | B19: 2 | D19: 0
A20: Informe realizado con herramienta https://aicodedetector.org/ | B20: 2 | D20: 2
A21: 1.2 Repositorio GitHub | B21: =SUM(B22:B24) -> 6 | D21: =SUM(D22:D24) -> 6
A22: Formato de nombre correcto y auxiliar agregado como colaborador | B22: 2 | D22: 2
A23: Commits progresivos, no concentrados al final | B23: 2 | D23: 2
A24: Estructura de carpetas ordenada y proyecto compilable desde el repo | B24: 2 | D24: 2
A25: 1.3 Buenas prácticas de código y reportes HTML | B25: =SUM(B26:B28) -> 6 | D25: =SUM(D26:D28) -> 4
A26: Arquitectura ordenada (separación tipo MVC, sin clases gigantes) | B26: 2 | D26: 2
A27: Nombres de variables/métodos claros y comentarios útiles | B27: 2 | D27: 2
A28: Reportes HTML generados correctamente (formato de nombre, contenido) | B28: 2 | D28: 0
A29: 2. CONOCIMIENTO – QUÉ SE PROGRAMA | B29: =B30+B34+B40+B44+B49+B53+B58+B63 -> 55 | D29: =IF(D30+D34+D40+D44+D49+D53+D58+D63=0,"",D30+D34+D40+D44+D49+D53+D58+D63) -> 36.5
A30: 2.1 Autenticación y roles | B30: =SUM(B31:B33) -> 5 | D30: =SUM(D31:D33) -> 1.5
A31: Login válido contra archivo de usuarios | B31: 2 | D31: 1
A32: Permisos diferenciados admin/auxiliar | B32: 2 | D32: 0
A33: Manejo de intentos fallidos | B33: 1 | D33: 0.5
A34: 2.2 Animales | B34: =SUM(B35:B39) -> 10 | D34: =SUM(D35:D39) -> 4
A35: Registro con generación de código y validaciones | B35: 3 | D35: 2
A36: Búsqueda por código/nombre/especie/estado | B36: 2 | D36: 0
A37: Edición de estado clínico y de adopción | B37: 2 | D37: 2
A38: Listado y filtro de activos | B38: 1 | D38: 0
A39: Eliminación lógica sin romper referencias | B39: 2 | D39: 0
A40: 2.3 Adoptantes | B40: =SUM(B41:B43) -> 6 | D40: =SUM(D41:D43) -> 5
A41: Registro con validación de documento/teléfono | B41: 2 | D41: 2
A42: Búsqueda por código/nombre/documento | B42: 2 | D42: 2
A43: Edición y listado de activos | B43: 2 | D43: 1
...

Sheet 202407699
A1: UNIVERSIDAD DE SAN CARLOS DE GUATEMALA
A2: FACULTAD DE INGENIERÍA
A3: ESCUELA DE CIENCIAS Y SISTEMAS
A4: Introducción a la Programación y Computación 1, Sección B
A5: Ing William Estuardo Escobar Argueta
A6: Aux. Fernando José Vicente Velásquez
A8: Hoja de Calificación – Proyecto 1: Centro de Rescate Animal: Gestión de Refugio y Adopciones
A10: Fecha de calificación: | C10: 46282
A11: Nombre del estudiante: | C11: =VLOOKUP(C12, Consolidado!$B$3:$C$26, 2, 0) -> KEVIN ANDRE MENDOZA VILLEDA
A12: Carné: | C12: 202407699
A14: Descripción de Ponderación | B14: Valor | C14: Observación | D14: Punteo
A15: 1. HABILIDADES – CÓMO SE PROGRAMA | B15: =B16+B21+B25 -> 20 | D15: =IF(D16+D21+D25=0,"",D16+D21+D25)
A16: 1.1 Documentación | B16: =SUM(B17:B20) -> 8 | D16: =SUM(D17:D20) -> 0
A17: Manual técnico detallado completo y coherente con el código | B17: 2
A18: Manual de usuario con capturas reales y guia para el usuario | B18: 2
A19: Diagramas (flujo, módulos, matriz de ubicaciones) | B19: 2
A20: Informe realizado con herramienta https://aicodedetector.org/ | B20: 2
A21: 1.2 Repositorio GitHub | B21: =SUM(B22:B24) -> 6 | D21: =SUM(D22:D24) -> 0
A22: Formato de nombre correcto y auxiliar agregado como colaborador | B22: 2
A23: Commits progresivos, no concentrados al final | B23: 2
A24: Estructura de carpetas ordenada y proyecto compilable desde el repo | B24: 2
A25: 1.3 Buenas prácticas de código y reportes HTML | B25: =SUM(B26:B28) -> 6 | D25: =SUM(D26:D28) -> 0
A26: Arquitectura ordenada (separación tipo MVC, sin clases gigantes) | B26: 2
A27: Nombres de variables/métodos claros y comentarios útiles | B27: 2
A28: Reportes HTML generados correctamente (formato de nombre, contenido) | B28: 2
A29: 2. CONOCIMIENTO – QUÉ SE PROGRAMA | B29: =B30+B34+B40+B44+B49+B53+B58+B63 -> 55 | D29: =IF(D30+D34+D40+D44+D49+D53+D58+D63=0,"",D30+D34+D40+D44+D49+D53+D58+D63)
A30: 2.1 Autenticación y roles | B30: =SUM(B31:B33) -> 5 | D30: =SUM(D31:D33) -> 0
A31: Login válido contra archivo de usuarios | B31: 2
A32: Permisos diferenciados admin/auxiliar | B32: 2
A33: Manejo de intentos fallidos | B33: 1
A34: 2.2 Animales | B34: =SUM(B35:B39) -> 10 | D34: =SUM(D35:D39) -> 0
A35: Registro con generación de código y validaciones | B35: 3
A36: Búsqueda por código/nombre/especie/estado | B36: 2
A37: Edición de estado clínico y de adopción | B37: 2
A38: Listado y filtro de activos | B38: 1
A39: Eliminación lógica sin romper referencias | B39: 2
A40: 2.3 Adoptantes | B40: =SUM(B41:B43) -> 6 | D40: =SUM(D41:D43) -> 0
A41: Registro con validación de documento/teléfono | B41: 2
A42: Búsqueda por código/nombre/documento | B42: 2
A43: Edición y listado de activos | B43: 2
...

Sheet 202502481
A1: UNIVERSIDAD DE SAN CARLOS DE GUATEMALA
A2: FACULTAD DE INGENIERÍA
A3: ESCUELA DE CIENCIAS Y SISTEMAS
A4: Introducción a la Programación y Computación 1, Sección B
A5: Ing William Estuardo Escobar Argueta
A6: Aux. Fernando José Vicente Velásquez
A8: Hoja de Calificación – Proyecto 1: Centro de Rescate Animal: Gestión de Refugio y Adopciones
A10: Fecha de calificación: | C10: 46282
A11: Nombre del estudiante: | C11: =VLOOKUP(C12, Consolidado!$B$3:$C$26, 2, 0) -> FRANCISCO JAVIER CHIVICHÓN FERNÁNDEZ
A12: Carné: | C12: 202502481
A14: Descripción de Ponderación | B14: Valor | C14: Observación | D14: Punteo
A15: 1. HABILIDADES – CÓMO SE PROGRAMA | B15: =B16+B21+B25 -> 20 | D15: =IF(D16+D21+D25=0,"",D16+D21+D25)
A16: 1.1 Documentación | B16: =SUM(B17:B20) -> 8 | D16: =SUM(D17:D20) -> 0
A17: Manual técnico detallado completo y coherente con el código | B17: 2
A18: Manual de usuario con capturas reales y guia para el usuario | B18: 2
A19: Diagramas (flujo, módulos, matriz de ubicaciones) | B19: 2
A20: Informe realizado con herramienta https://aicodedetector.org/ | B20: 2
A21: 1.2 Repositorio GitHub | B21: =SUM(B22:B24) -> 6 | D21: =SUM(D22:D24) -> 0
A22: Formato de nombre correcto y auxiliar agregado como colaborador | B22: 2
A23: Commits progresivos, no concentrados al final | B23: 2
A24: Estructura de carpetas ordenada y proyecto compilable desde el repo | B24: 2
A25: 1.3 Buenas prácticas de código y reportes HTML | B25: =SUM(B26:B28) -> 6 | D25: =SUM(D26:D28) -> 0
A26: Arquitectura ordenada (separación tipo MVC, sin clases gigantes) | B26: 2
A27: Nombres de variables/métodos claros y comentarios útiles | B27: 2
A28: Reportes HTML generados correctamente (formato de nombre, contenido) | B28: 2
A29: 2. CONOCIMIENTO – QUÉ SE PROGRAMA | B29: =B30+B34+B40+B44+B49+B53+B58+B63 -> 55 | D29: =IF(D30+D34+D40+D44+D49+D53+D58+D63=0,"",D30+D34+D40+D44+D49+D53+D58+D63)
A30: 2.1 Autenticación y roles | B30: =SUM(B31:B33) -> 5 | D30: =SUM(D31:D33) -> 0
A31: Login válido contra archivo de usuarios | B31: 2
A32: Permisos diferenciados admin/auxiliar | B32: 2
A33: Manejo de intentos fallidos | B33: 1
A34: 2.2 Animales | B34: =SUM(B35:B39) -> 10 | D34: =SUM(D35:D39) -> 0
A35: Registro con generación de código y validaciones | B35: 3
A36: Búsqueda por código/nombre/especie/estado | B36: 2
A37: Edición de estado clínico y de adopción | B37: 2
A38: Listado y filtro de activos | B38: 1
A39: Eliminación lógica sin romper referencias | B39: 2
A40: 2.3 Adoptantes | B40: =SUM(B41:B43) -> 6 | D40: =SUM(D41:D43) -> 0
A41: Registro con validación de documento/teléfono | B41: 2
A42: Búsqueda por código/nombre/documento | B42: 2
A43: Edición y listado de activos | B43: 2
...

Sheet 202501470
A1: UNIVERSIDAD DE SAN CARLOS DE GUATEMALA
A2: FACULTAD DE INGENIERÍA
A3: ESCUELA DE CIENCIAS Y SISTEMAS
A4: Introducción a la Programación y Computación 1, Sección B
A5: Ing William Estuardo Escobar Argueta
A6: Aux. Fernando José Vicente Velásquez
A8: Hoja de Calificación – Proyecto 1: Centro de Rescate Animal: Gestión de Refugio y Adopciones
A10: Fecha de calificación:
A11: Nombre del estudiante: | C11: =VLOOKUP(C12, Consolidado!$B$3:$C$26, 2, 0) -> CARLOS ANDRÉS HERNÁNDEZ VÁSQUEZ
A12: Carné: | C12: 202501470
A14: Descripción de Ponderación | B14: Valor | C14: Observación | D14: Punteo
A15: 1. HABILIDADES – CÓMO SE PROGRAMA | B15: =B16+B21+B25 -> 20 | D15: =IF(D16+D21+D25=0,"",D16+D21+D25) -> 14
A16: 1.1 Documentación | B16: =SUM(B17:B20) -> 8 | D16: =IF(SUM(D17:D20)=0,"",SUM(D17:D20)) -> 3
A17: Manual técnico detallado completo y coherente con el código | B17: 2 | D17: 2
A18: Manual de usuario con capturas reales y guia para el usuario | B18: 2 | D18: 1
A19: Diagramas (flujo, módulos, matriz de ubicaciones) | B19: 2 | D19: 0
A20: Informe realizado con herramienta https://aicodedetector.org/ | B20: 2 | D20: 0
A21: 1.2 Repositorio GitHub | B21: =SUM(B22:B24) -> 6 | D21: =IF(SUM(D22:D24)=0,"",SUM(D22:D24)) -> 5
A22: Formato de nombre correcto y auxiliar agregado como colaborador | B22: 2 | D22: 2
A23: Commits progresivos, no concentrados al final | B23: 2 | D23: 2
A24: Estructura de carpetas ordenada y proyecto compilable desde el repo | B24: 2 | D24: 1
A25: 1.3 Buenas prácticas de código y reportes HTML | B25: =SUM(B26:B28) -> 6 | D25: =IF(SUM(D26:D28)=0,"",SUM(D26:D28)) -> 6
A26: Arquitectura ordenada (separación tipo MVC, sin clases gigantes) | B26: 2 | D26: 2
A27: Nombres de variables/métodos claros y comentarios útiles | B27: 2 | D27: 2
A28: Reportes HTML generados correctamente (formato de nombre, contenido) | B28: 2 | D28: 2
A29: 2. CONOCIMIENTO – QUÉ SE PROGRAMA | B29: =B30+B34+B40+B44+B49+B53+B58+B63 -> 55 | D29: =IF(D30+D34+D40+D44+D49+D53+D58+D63=0,"",D30+D34+D40+D44+D49+D53+D58+D63) -> 33
A30: 2.1 Autenticación y roles | B30: =SUM(B31:B33) -> 5 | D30: 5
A31: Login válido contra archivo de usuarios | B31: 2 | D31: 2
A32: Permisos diferenciados admin/auxiliar | B32: 2 | D32: 0
A33: Manejo de intentos fallidos | B33: 1 | D33: 0
A34: 2.2 Animales | B34: =SUM(B35:B39) -> 10 | D34: =SUM(D35:D39) -> 2
A35: Registro con generación de código y validaciones | B35: 3 | D35: 2
A36: Búsqueda por código/nombre/especie/estado | B36: 2 | D36: 0
A37: Edición de estado clínico y de adopción | B37: 2 | D37: 0
A38: Listado y filtro de activos | B38: 1 | D38: 0
A39: Eliminación lógica sin romper referencias | B39: 2 | D39: 0
