Workbook

Sheet Plantilla
A1: UNIVERSIDAD DE SAN CARLOS DE GUATEMALA
A2: FACULTAD DE INGENIERÍA
A3: ESCUELA DE CIENCIAS Y SISTEMAS
A4: Introducción a la Programación y Computación 1, Sección B
A5: Ing. William Estuardo Escobar Argueta
A6: Aux. Fernando José Vicente Velásquez
A8: Hoja de Calificación – Proyecto 2: Parque Residencial: Sistema de Gestión de Parqueo
A10: Fecha de calificación:
A11: Nombre del estudiante: | C11: =VLOOKUP(C12, Consolidado!$B$3:$C$26, 2, 0) -> MARTA GABRIELA GÓMEZ DIMAYUGA
A12: Carné: | C12: 201503481
A14: Descripción de Ponderación | B14: Valor | C14: Observación | D14: Punteo
A15: 1. HABILIDADES – CÓMO SE PROGRAMA | B15: =B16+B21+B25 -> 15 | D15: =IF(N(D16)+N(D21)+N(D25)=0,"",N(D16)+N(D21)+N(D25))
A16: 1.1 Documentación | B16: =SUM(B17:B20) -> 6 | D16: =IF(SUM(D17:D20)=0,"",SUM(D17:D20))
A17: Manual técnico: arquitectura, diagrama de clases, estructuras, hilos y formato de archivos | B17: 2
A18: Manual de usuario con capturas reales de cada panel (residentes, vehículos, visitantes, simulación, eventos) | B18: 1.5
A19: Informe de desarrollo: plan por etapas, avance, problemas encontrados y soluciones | B19: 1.5
A20: Informe realizado con herramienta https://aicodedetector.org/ | B20: 1
A21: 1.2 Repositorio GitHub | B21: =SUM(B22:B24) -> 4 | D21: =IF(SUM(D22:D24)=0,"",SUM(D22:D24))
A22: Formato de nombre correcto y auxiliar agregado como colaborador | B22: 1
A23: Commits incrementales y semánticos (feat:, fix:, docs:), no concentrados al final | B23: 2
A24: Proyecto compilable desde el repo, .jar ejecutable y archivos .txt de ejemplo incluidos | B24: 1
A25: 1.3 Buenas prácticas de código e interfaz | B25: =SUM(B26:B28) -> 5 | D25: =IF(SUM(D26:D28)=0,"",SUM(D26:D28))
A26: Organización en paquetes (estructuras, modelo, hilos, persistencia, vista) con POO y sin sobreingeniería | B26: 2
A27: Nombres de variables/métodos claros y comentarios útiles | B27: 1
A28: Swing codificado manualmente y actualización de la UI desde hilos con SwingUtilities.invokeLater | B28: 2
A29: 2. CONOCIMIENTO – QUÉ SE PROGRAMA | B29: =B30+B34+B37+B42+B45+B48+B53+B56+B59 -> 35 | D29: =IF(N(D30)+N(D34)+N(D37)+N(D42)+N(D45)+N(D48)+N(D53)+N(D56)+N(D59)=0,"",N(D30)+N(D34)+N(D37)+N(D42)+N(D45)+N(D48)+N(D53)+N(D56)+N(D59))
A30: 2.1 Lista doblemente enlazada – Residentes | B30: =SUM(B31:B33) -> 5 | D30: =IF(SUM(D31:D33)=0,"",SUM(D31:D33))
A31: Nodo propio con anterior/siguiente; insertar y buscar residentes (ID, nombre, casa, socio) | B31: 2
A32: Eliminar y actualizar residentes manteniendo correctamente las referencias | B32: 2
A33: Recorrido de la lista en ambos sentidos y visualización de los residentes | B33: 1
A34: 2.2 Lista simplemente enlazada – Vehículos | B34: =SUM(B35:B36) -> 3 | D34: =IF(SUM(D35:D36)=0,"",SUM(D35:D36))
A35: Lista propia por residente: insertar, eliminar y recorrer vehículos (placa, marca, modelo, color, tipo, estado) | B35: 2
A36: Validación de 0 a 3 vehículos: impide registrar un cuarto vehículo | B36: 1
A37: 2.3 Lista doble de listas simples – Parqueo | B37: =SUM(B38:B41) -> 7 | D37: =IF(SUM(D38:D41)=0,"",SUM(D38:D41))
A38: 150 nodos que representan espacios físicos (ID, estado, vehículo estacionado, tipo socio/general) | B38: 2
A39: Enlaces arriba/abajo y enlace simple que reflejan la distribución A–C (25) y E–I (15) | B39: 2
A40: Recorrido para buscar espacio libre por tipo, asignación y liberación correcta del espacio | B40: 2
A41: Validación del área de socios: ningún vehículo no autorizado ocupa A–C (reglas documentadas) | B41: 1
A42: 2.4 Colas FIFO – Entrada y salida | B42: =SUM(B43:B44) -> 3 | D42: =IF(SUM(D43:D44)=0,"",SUM(D43:D44))
A43: Cola de entrada manual (FIFO) consumida por las 3 garitas de entrada | B43: 1.5
...

Sheet 202201204
A1: UNIVERSIDAD DE SAN CARLOS DE GUATEMALA
A2: FACULTAD DE INGENIERÍA
A3: ESCUELA DE CIENCIAS Y SISTEMAS
A4: Introducción a la Programación y Computación 1, Sección B
A5: Ing. William Estuardo Escobar Argueta
A6: Aux. Fernando José Vicente Velásquez
A8: Hoja de Calificación – Proyecto 2: Parque Residencial: Sistema de Gestión de Parqueo
A10: Fecha de calificación:
A11: Nombre del estudiante: | C11: =VLOOKUP(C12, Consolidado!$B$3:$C$26, 2, 0) -> MARTA GABRIELA GÓMEZ DIMAYUGA
A12: Carné: | C12: 201503481
A14: Descripción de Ponderación | B14: Valor | C14: Observación | D14: Punteo
A15: 1. HABILIDADES – CÓMO SE PROGRAMA | B15: =B16+B21+B25 -> 15 | D15: =IF(N(D16)+N(D21)+N(D25)=0,"",N(D16)+N(D21)+N(D25))
A16: 1.1 Documentación | B16: =SUM(B17:B20) -> 6 | D16: =IF(SUM(D17:D20)=0,"",SUM(D17:D20))
A17: Manual técnico: arquitectura, diagrama de clases, estructuras, hilos y formato de archivos | B17: 2
A18: Manual de usuario con capturas reales de cada panel (residentes, vehículos, visitantes, simulación, eventos) | B18: 1.5
A19: Informe de desarrollo: plan por etapas, avance, problemas encontrados y soluciones | B19: 1.5
A20: Informe realizado con herramienta https://aicodedetector.org/ | B20: 1
A21: 1.2 Repositorio GitHub | B21: =SUM(B22:B24) -> 4 | D21: =IF(SUM(D22:D24)=0,"",SUM(D22:D24))
A22: Formato de nombre correcto y auxiliar agregado como colaborador | B22: 1
A23: Commits incrementales y semánticos (feat:, fix:, docs:), no concentrados al final | B23: 2
A24: Proyecto compilable desde el repo, .jar ejecutable y archivos .txt de ejemplo incluidos | B24: 1
A25: 1.3 Buenas prácticas de código e interfaz | B25: =SUM(B26:B28) -> 5 | D25: =IF(SUM(D26:D28)=0,"",SUM(D26:D28))
A26: Organización en paquetes (estructuras, modelo, hilos, persistencia, vista) con POO y sin sobreingeniería | B26: 2
A27: Nombres de variables/métodos claros y comentarios útiles | B27: 1
A28: Swing codificado manualmente y actualización de la UI desde hilos con SwingUtilities.invokeLater | B28: 2
A29: 2. CONOCIMIENTO – QUÉ SE PROGRAMA | B29: =B30+B34+B37+B42+B45+B48+B53+B56+B59 -> 35 | D29: =IF(N(D30)+N(D34)+N(D37)+N(D42)+N(D45)+N(D48)+N(D53)+N(D56)+N(D59)=0,"",N(D30)+N(D34)+N(D37)+N(D42)+N(D45)+N(D48)+N(D53)+N(D56)+N(D59))
A30: 2.1 Lista doblemente enlazada – Residentes | B30: =SUM(B31:B33) -> 5 | D30: =IF(SUM(D31:D33)=0,"",SUM(D31:D33))
A31: Nodo propio con anterior/siguiente; insertar y buscar residentes (ID, nombre, casa, socio) | B31: 2
A32: Eliminar y actualizar residentes manteniendo correctamente las referencias | B32: 2
A33: Recorrido de la lista en ambos sentidos y visualización de los residentes | B33: 1
A34: 2.2 Lista simplemente enlazada – Vehículos | B34: =SUM(B35:B36) -> 3 | D34: =IF(SUM(D35:D36)=0,"",SUM(D35:D36))
A35: Lista propia por residente: insertar, eliminar y recorrer vehículos (placa, marca, modelo, color, tipo, estado) | B35: 2
A36: Validación de 0 a 3 vehículos: impide registrar un cuarto vehículo | B36: 1
A37: 2.3 Lista doble de listas simples – Parqueo | B37: =SUM(B38:B41) -> 7 | D37: =IF(SUM(D38:D41)=0,"",SUM(D38:D41))
A38: 150 nodos que representan espacios físicos (ID, estado, vehículo estacionado, tipo socio/general) | B38: 2
A39: Enlaces arriba/abajo y enlace simple que reflejan la distribución A–C (25) y E–I (15) | B39: 2
A40: Recorrido para buscar espacio libre por tipo, asignación y liberación correcta del espacio | B40: 2
A41: Validación del área de socios: ningún vehículo no autorizado ocupa A–C (reglas documentadas) | B41: 1
A42: 2.4 Colas FIFO – Entrada y salida | B42: =SUM(B43:B44) -> 3 | D42: =IF(SUM(D43:D44)=0,"",SUM(D43:D44))
A43: Cola de entrada manual (FIFO) consumida por las 3 garitas de entrada | B43: 1.5
...

Sheet 202407699
A1: UNIVERSIDAD DE SAN CARLOS DE GUATEMALA
A2: FACULTAD DE INGENIERÍA
A3: ESCUELA DE CIENCIAS Y SISTEMAS
A4: Introducción a la Programación y Computación 1, Sección E
A5: Ing. William Estuardo Escobar Argueta
A6: Aux. Fernando José Vicente Velásquez
A8: Hoja de Calificación – Proyecto 2: Parque Residencial: Sistema de Gestión de Parqueo
A10: Fecha de calificación:
A11: Nombre del estudiante: | C11: =VLOOKUP(C12, Consolidado!$B$3:$C$26, 2, 0) -> #N/A
A12: Carné: | C12: 202407699
A14: Descripción de Ponderación | B14: Valor | C14: Observación | D14: Punteo
A15: 1. HABILIDADES – CÓMO SE PROGRAMA | B15: =B16+B21+B25 -> 15 | D15: =IF(N(D16)+N(D21)+N(D25)=0,"",N(D16)+N(D21)+N(D25)) -> 12.5
A16: 1.1 Documentación | B16: =SUM(B17:B20) -> 6 | D16: =IF(SUM(D17:D20)=0,"",SUM(D17:D20)) -> 4.5
A17: Manual técnico: arquitectura, diagrama de clases, estructuras, hilos y formato de archivos | B17: 2 | D17: 2
A18: Manual de usuario con capturas reales de cada panel (residentes, vehículos, visitantes, simulación, eventos) | B18: 1.5 | D18: 0.5
A19: Informe de desarrollo: plan por etapas, avance, problemas encontrados y soluciones | B19: 1.5 | D19: 1
A20: Informe realizado con herramienta https://aicodedetector.org/ | B20: 1 | D20: 1
A21: 1.2 Repositorio GitHub | B21: =SUM(B22:B24) -> 4 | D21: =IF(SUM(D22:D24)=0,"",SUM(D22:D24)) -> 3
A22: Formato de nombre correcto y auxiliar agregado como colaborador | B22: 1 | D22: 0
A23: Commits incrementales y semánticos (feat:, fix:, docs:), no concentrados al final | B23: 2 | D23: 2
A24: Proyecto compilable desde el repo, .jar ejecutable y archivos .txt de ejemplo incluidos | B24: 1 | D24: 1
A25: 1.3 Buenas prácticas de código e interfaz | B25: =SUM(B26:B28) -> 5 | D25: =IF(SUM(D26:D28)=0,"",SUM(D26:D28)) -> 5
A26: Organización en paquetes (estructuras, modelo, hilos, persistencia, vista) con POO y sin sobreingeniería | B26: 2 | D26: 2
A27: Nombres de variables/métodos claros y comentarios útiles | B27: 1 | D27: 1
A28: Swing codificado manualmente y actualización de la UI desde hilos con SwingUtilities.invokeLater | B28: 2 | D28: 2
A29: 2. CONOCIMIENTO – QUÉ SE PROGRAMA | B29: =B30+B34+B37+B42+B45+B48+B53+B56+B59 -> 35 | D29: =IF(N(D30)+N(D34)+N(D37)+N(D42)+N(D45)+N(D48)+N(D53)+N(D56)+N(D59)=0,"",N(D30)+N(D34)+N(D37)+N(D42)+N(D45)+N(D48)+N(D53)+N(D56)+N(D59)) -> 35
A30: 2.1 Lista doblemente enlazada – Residentes | B30: =SUM(B31:B33) -> 5 | D30: =IF(SUM(D31:D33)=0,"",SUM(D31:D33)) -> 5
A31: Nodo propio con anterior/siguiente; insertar y buscar residentes (ID, nombre, casa, socio) | B31: 2 | D31: 2
A32: Eliminar y actualizar residentes manteniendo correctamente las referencias | B32: 2 | D32: 2
A33: Recorrido de la lista en ambos sentidos y visualización de los residentes | B33: 1 | D33: 1
A34: 2.2 Lista simplemente enlazada – Vehículos | B34: =SUM(B35:B36) -> 3 | D34: =IF(SUM(D35:D36)=0,"",SUM(D35:D36)) -> 3
A35: Lista propia por residente: insertar, eliminar y recorrer vehículos (placa, marca, modelo, color, tipo, estado) | B35: 2 | D35: 2
A36: Validación de 0 a 3 vehículos: impide registrar un cuarto vehículo | B36: 1 | D36: 1
A37: 2.3 Lista doble de listas simples – Parqueo | B37: =SUM(B38:B41) -> 7 | D37: =IF(SUM(D38:D41)=0,"",SUM(D38:D41)) -> 7
A38: 150 nodos que representan espacios físicos (ID, estado, vehículo estacionado, tipo socio/general) | B38: 2 | D38: 2
A39: Enlaces arriba/abajo y enlace simple que reflejan la distribución A–C (25) y E–I (15) | B39: 2 | D39: 2
A40: Recorrido para buscar espacio libre por tipo, asignación y liberación correcta del espacio | B40: 2 | D40: 2
A41: Validación del área de socios: ningún vehículo no autorizado ocupa A–C (reglas documentadas) | B41: 1 | D41: 1
A42: 2.4 Colas FIFO – Entrada y salida | B42: =SUM(B43:B44) -> 3 | D42: =IF(SUM(D43:D44)=0,"",SUM(D43:D44)) -> 3
A43: Cola de entrada manual (FIFO) consumida por las 3 garitas de entrada | B43: 1.5 | D43: 1.5
...

Sheet 202400066
A1: UNIVERSIDAD DE SAN CARLOS DE GUATEMALA
A2: FACULTAD DE INGENIERÍA
A3: ESCUELA DE CIENCIAS Y SISTEMAS
A4: Introducción a la Programación y Computación 1, Sección E
A5: Ing. William Estuardo Escobar Argueta
A6: Aux. Fernando José Vicente Velásquez
A8: Hoja de Calificación – Proyecto 2: Parque Residencial: Sistema de Gestión de Parqueo
A10: Fecha de calificación:
A11: Nombre del estudiante: | C11: =VLOOKUP(C12, Consolidado!$B$3:$C$26, 2, 0) -> #N/A
A12: Carné: | C12: 202400066
A14: Descripción de Ponderación | B14: Valor | C14: Observación | D14: Punteo
A15: 1. HABILIDADES – CÓMO SE PROGRAMA | B15: =B16+B21+B25 -> 15 | D15: =IF(N(D16)+N(D21)+N(D25)=0,"",N(D16)+N(D21)+N(D25)) -> 7.5
A16: 1.1 Documentación | B16: =SUM(B17:B20) -> 6 | D16: =IF(SUM(D17:D20)=0,"",SUM(D17:D20)) -> 5.5
A17: Manual técnico: arquitectura, diagrama de clases, estructuras, hilos y formato de archivos | B17: 2 | D17: 2
A18: Manual de usuario con capturas reales de cada panel (residentes, vehículos, visitantes, simulación, eventos) | B18: 1.5 | D18: 1
A19: Informe de desarrollo: plan por etapas, avance, problemas encontrados y soluciones | B19: 1.5 | D19: 1.5
A20: Informe realizado con herramienta https://aicodedetector.org/ | B20: 1 | D20: 1
A21: 1.2 Repositorio GitHub | B21: =SUM(B22:B24) -> 4 | D21: =IF(SUM(D22:D24)=0,"",SUM(D22:D24)) -> 2
A22: Formato de nombre correcto y auxiliar agregado como colaborador | B22: 1 | D22: 1
A23: Commits incrementales y semánticos (feat:, fix:, docs:), no concentrados al final | B23: 2 | D23: 0
A24: Proyecto compilable desde el repo, .jar ejecutable y archivos .txt de ejemplo incluidos | B24: 1 | D24: 1
A25: 1.3 Buenas prácticas de código e interfaz | B25: =SUM(B26:B28) -> 5
A26: Organización en paquetes (estructuras, modelo, hilos, persistencia, vista) con POO y sin sobreingeniería | B26: 2 | D26: 2
A27: Nombres de variables/métodos claros y comentarios útiles | B27: 1 | D27: 1
A28: Swing codificado manualmente y actualización de la UI desde hilos con SwingUtilities.invokeLater | B28: 2 | D28: 2
A29: 2. CONOCIMIENTO – QUÉ SE PROGRAMA | B29: =B30+B34+B37+B42+B45+B48+B53+B56+B59 -> 35 | D29: =IF(N(D30)+N(D34)+N(D37)+N(D42)+N(D45)+N(D48)+N(D53)+N(D56)+N(D59)=0,"",N(D30)+N(D34)+N(D37)+N(D42)+N(D45)+N(D48)+N(D53)+N(D56)+N(D59)) -> 35
A30: 2.1 Lista doblemente enlazada – Residentes | B30: =SUM(B31:B33) -> 5 | D30: =IF(SUM(D31:D33)=0,"",SUM(D31:D33)) -> 5
A31: Nodo propio con anterior/siguiente; insertar y buscar residentes (ID, nombre, casa, socio) | B31: 2 | D31: 2
A32: Eliminar y actualizar residentes manteniendo correctamente las referencias | B32: 2 | D32: 2
A33: Recorrido de la lista en ambos sentidos y visualización de los residentes | B33: 1 | D33: 1
A34: 2.2 Lista simplemente enlazada – Vehículos | B34: =SUM(B35:B36) -> 3 | D34: =IF(SUM(D35:D36)=0,"",SUM(D35:D36)) -> 3
A35: Lista propia por residente: insertar, eliminar y recorrer vehículos (placa, marca, modelo, color, tipo, estado) | B35: 2 | D35: 2
A36: Validación de 0 a 3 vehículos: impide registrar un cuarto vehículo | B36: 1 | D36: 1
A37: 2.3 Lista doble de listas simples – Parqueo | B37: =SUM(B38:B41) -> 7 | D37: =IF(SUM(D38:D41)=0,"",SUM(D38:D41)) -> 7
A38: 150 nodos que representan espacios físicos (ID, estado, vehículo estacionado, tipo socio/general) | B38: 2 | D38: 2
A39: Enlaces arriba/abajo y enlace simple que reflejan la distribución A–C (25) y E–I (15) | B39: 2 | D39: 2
A40: Recorrido para buscar espacio libre por tipo, asignación y liberación correcta del espacio | B40: 2 | D40: 2
A41: Validación del área de socios: ningún vehículo no autorizado ocupa A–C (reglas documentadas) | B41: 1 | D41: 1
A42: 2.4 Colas FIFO – Entrada y salida | B42: =SUM(B43:B44) -> 3 | D42: =IF(SUM(D43:D44)=0,"",SUM(D43:D44)) -> 3
A43: Cola de entrada manual (FIFO) consumida por las 3 garitas de entrada | B43: 1.5 | D43: 1.5
...

Sheet 202400155
A1: UNIVERSIDAD DE SAN CARLOS DE GUATEMALA
A2: FACULTAD DE INGENIERÍA
A3: ESCUELA DE CIENCIAS Y SISTEMAS
A4: Introducción a la Programación y Computación 1, Sección E
A5: Ing. William Estuardo Escobar Argueta
A6: Aux. Fernando José Vicente Velásquez
A8: Hoja de Calificación – Proyecto 2: Parque Residencial: Sistema de Gestión de Parqueo
A10: Fecha de calificación:
A11: Nombre del estudiante: | C11: =VLOOKUP(C12, Consolidado!$B$3:$C$26, 2, 0) -> #N/A
A12: Carné: | C12: 202400155
A14: Descripción de Ponderación | B14: Valor | C14: Observación | D14: Punteo
A15: 1. HABILIDADES – CÓMO SE PROGRAMA | B15: =B16+B21+B25 -> 15 | D15: =IF(N(D16)+N(D21)+N(D25)=0,"",N(D16)+N(D21)+N(D25)) -> 15
A16: 1.1 Documentación | B16: =SUM(B17:B20) -> 6 | D16: =IF(SUM(D17:D20)=0,"",SUM(D17:D20)) -> 6
A17: Manual técnico: arquitectura, diagrama de clases, estructuras, hilos y formato de archivos | B17: 2 | D17: 2
A18: Manual de usuario con capturas reales de cada panel (residentes, vehículos, visitantes, simulación, eventos) | B18: 1.5 | D18: 1.5
A19: Informe de desarrollo: plan por etapas, avance, problemas encontrados y soluciones | B19: 1.5 | D19: 1.5
A20: Informe realizado con herramienta https://aicodedetector.org/ | B20: 1 | D20: 1
A21: 1.2 Repositorio GitHub | B21: =SUM(B22:B24) -> 4 | D21: =IF(SUM(D22:D24)=0,"",SUM(D22:D24)) -> 4
A22: Formato de nombre correcto y auxiliar agregado como colaborador | B22: 1 | D22: 1
A23: Commits incrementales y semánticos (feat:, fix:, docs:), no concentrados al final | B23: 2 | D23: 2
A24: Proyecto compilable desde el repo, .jar ejecutable y archivos .txt de ejemplo incluidos | B24: 1 | D24: 1
A25: 1.3 Buenas prácticas de código e interfaz | B25: =SUM(B26:B28) -> 5 | D25: =IF(SUM(D26:D28)=0,"",SUM(D26:D28)) -> 5
A26: Organización en paquetes (estructuras, modelo, hilos, persistencia, vista) con POO y sin sobreingeniería | B26: 2 | D26: 2
A27: Nombres de variables/métodos claros y comentarios útiles | B27: 1 | D27: 1
A28: Swing codificado manualmente y actualización de la UI desde hilos con SwingUtilities.invokeLater | B28: 2 | D28: 2
A29: 2. CONOCIMIENTO – QUÉ SE PROGRAMA | B29: =B30+B34+B37+B42+B45+B48+B53+B56+B59 -> 35 | D29: =IF(N(D30)+N(D34)+N(D37)+N(D42)+N(D45)+N(D48)+N(D53)+N(D56)+N(D59)=0,"",N(D30)+N(D34)+N(D37)+N(D42)+N(D45)+N(D48)+N(D53)+N(D56)+N(D59)) -> 35
A30: 2.1 Lista doblemente enlazada – Residentes | B30: =SUM(B31:B33) -> 5 | D30: =IF(SUM(D31:D33)=0,"",SUM(D31:D33)) -> 5
A31: Nodo propio con anterior/siguiente; insertar y buscar residentes (ID, nombre, casa, socio) | B31: 2 | D31: 2
A32: Eliminar y actualizar residentes manteniendo correctamente las referencias | B32: 2 | D32: 2
A33: Recorrido de la lista en ambos sentidos y visualización de los residentes | B33: 1 | D33: 1
A34: 2.2 Lista simplemente enlazada – Vehículos | B34: =SUM(B35:B36) -> 3 | D34: =IF(SUM(D35:D36)=0,"",SUM(D35:D36)) -> 3
A35: Lista propia por residente: insertar, eliminar y recorrer vehículos (placa, marca, modelo, color, tipo, estado) | B35: 2 | D35: 2
A36: Validación de 0 a 3 vehículos: impide registrar un cuarto vehículo | B36: 1 | D36: 1
A37: 2.3 Lista doble de listas simples – Parqueo | B37: =SUM(B38:B41) -> 7 | D37: =IF(SUM(D38:D41)=0,"",SUM(D38:D41)) -> 7
A38: 150 nodos que representan espacios físicos (ID, estado, vehículo estacionado, tipo socio/general) | B38: 2 | D38: 2
A39: Enlaces arriba/abajo y enlace simple que reflejan la distribución A–C (25) y E–I (15) | B39: 2 | D39: 2
A40: Recorrido para buscar espacio libre por tipo, asignación y liberación correcta del espacio | B40: 2 | D40: 2
A41: Validación del área de socios: ningún vehículo no autorizado ocupa A–C (reglas documentadas) | B41: 1 | D41: 1
A42: 2.4 Colas FIFO – Entrada y salida | B42: =SUM(B43:B44) -> 3 | D42: =IF(SUM(D43:D44)=0,"",SUM(D43:D44)) -> 3
A43: Cola de entrada manual (FIFO) consumida por las 3 garitas de entrada | B43: 1.5 | D43: 1.5
...

Sheet 202405048
A1: UNIVERSIDAD DE SAN CARLOS DE GUATEMALA
A2: FACULTAD DE INGENIERÍA
A3: ESCUELA DE CIENCIAS Y SISTEMAS
A4: Introducción a la Programación y Computación 1, Sección E
A5: Ing. William Estuardo Escobar Argueta
A6: Aux. Fernando José Vicente Velásquez
A8: Hoja de Calificación – Proyecto 2: Parque Residencial: Sistema de Gestión de Parqueo
A10: Fecha de calificación:
A11: Nombre del estudiante: | C11: =VLOOKUP(C12, Consolidado!$B$3:$C$26, 2, 0) -> #N/A
A12: Carné: | C12: 202405048
A14: Descripción de Ponderación | B14: Valor | C14: Observación | D14: Punteo
A15: 1. HABILIDADES – CÓMO SE PROGRAMA | B15: =B16+B21+B25 -> 15 | D15: =IF(N(D16)+N(D21)+N(D25)=0,"",N(D16)+N(D21)+N(D25)) -> 15
A16: 1.1 Documentación | B16: =SUM(B17:B20) -> 6 | D16: =IF(SUM(D17:D20)=0,"",SUM(D17:D20)) -> 6
A17: Manual técnico: arquitectura, diagrama de clases, estructuras, hilos y formato de archivos | B17: 2 | D17: 2
A18: Manual de usuario con capturas reales de cada panel (residentes, vehículos, visitantes, simulación, eventos) | B18: 1.5 | D18: 1.5
A19: Informe de desarrollo: plan por etapas, avance, problemas encontrados y soluciones | B19: 1.5 | D19: 1.5
A20: Informe realizado con herramienta https://aicodedetector.org/ | B20: 1 | D20: 1
A21: 1.2 Repositorio GitHub | B21: =SUM(B22:B24) -> 4 | D21: =IF(SUM(D22:D24)=0,"",SUM(D22:D24)) -> 4
A22: Formato de nombre correcto y auxiliar agregado como colaborador | B22: 1 | D22: 1
A23: Commits incrementales y semánticos (feat:, fix:, docs:), no concentrados al final | B23: 2 | D23: 2
A24: Proyecto compilable desde el repo, .jar ejecutable y archivos .txt de ejemplo incluidos | B24: 1 | D24: 1
A25: 1.3 Buenas prácticas de código e interfaz | B25: =SUM(B26:B28) -> 5 | D25: =IF(SUM(D26:D28)=0,"",SUM(D26:D28)) -> 5
A26: Organización en paquetes (estructuras, modelo, hilos, persistencia, vista) con POO y sin sobreingeniería | B26: 2 | D26: 2
A27: Nombres de variables/métodos claros y comentarios útiles | B27: 1 | D27: 1
A28: Swing codificado manualmente y actualización de la UI desde hilos con SwingUtilities.invokeLater | B28: 2 | D28: 2
A29: 2. CONOCIMIENTO – QUÉ SE PROGRAMA | B29: =B30+B34+B37+B42+B45+B48+B53+B56+B59 -> 35 | D29: =IF(N(D30)+N(D34)+N(D37)+N(D42)+N(D45)+N(D48)+N(D53)+N(D56)+N(D59)=0,"",N(D30)+N(D34)+N(D37)+N(D42)+N(D45)+N(D48)+N(D53)+N(D56)+N(D59)) -> 35
A30: 2.1 Lista doblemente enlazada – Residentes | B30: =SUM(B31:B33) -> 5 | D30: =IF(SUM(D31:D33)=0,"",SUM(D31:D33)) -> 5
A31: Nodo propio con anterior/siguiente; insertar y buscar residentes (ID, nombre, casa, socio) | B31: 2 | D31: 2
A32: Eliminar y actualizar residentes manteniendo correctamente las referencias | B32: 2 | D32: 2
A33: Recorrido de la lista en ambos sentidos y visualización de los residentes | B33: 1 | D33: 1
A34: 2.2 Lista simplemente enlazada – Vehículos | B34: =SUM(B35:B36) -> 3 | D34: =IF(SUM(D35:D36)=0,"",SUM(D35:D36)) -> 3
A35: Lista propia por residente: insertar, eliminar y recorrer vehículos (placa, marca, modelo, color, tipo, estado) | B35: 2 | D35: 2
A36: Validación de 0 a 3 vehículos: impide registrar un cuarto vehículo | B36: 1 | D36: 1
A37: 2.3 Lista doble de listas simples – Parqueo | B37: =SUM(B38:B41) -> 7 | D37: =IF(SUM(D38:D41)=0,"",SUM(D38:D41)) -> 7
A38: 150 nodos que representan espacios físicos (ID, estado, vehículo estacionado, tipo socio/general) | B38: 2 | D38: 2
A39: Enlaces arriba/abajo y enlace simple que reflejan la distribución A–C (25) y E–I (15) | B39: 2 | D39: 2
A40: Recorrido para buscar espacio libre por tipo, asignación y liberación correcta del espacio | B40: 2 | D40: 2
A41: Validación del área de socios: ningún vehículo no autorizado ocupa A–C (reglas documentadas) | B41: 1 | D41: 1
A42: 2.4 Colas FIFO – Entrada y salida | B42: =SUM(B43:B44) -> 3 | D42: =IF(SUM(D43:D44)=0,"",SUM(D43:D44)) -> 3
A43: Cola de entrada manual (FIFO) consumida por las 3 garitas de entrada | B43: 1.5 | D43: 1.5
...

Sheet 202403338
A1: UNIVERSIDAD DE SAN CARLOS DE GUATEMALA
A2: FACULTAD DE INGENIERÍA
A3: ESCUELA DE CIENCIAS Y SISTEMAS
A4: Introducción a la Programación y Computación 1, Sección E
A5: Ing. William Estuardo Escobar Argueta
A6: Aux. Fernando José Vicente Velásquez
A8: Hoja de Calificación – Proyecto 2: Parque Residencial: Sistema de Gestión de Parqueo
A10: Fecha de calificación:
A11: Nombre del estudiante: | C11: =VLOOKUP(C12, Consolidado!$B$3:$C$26, 2, 0) -> #N/A
A12: Carné: | C12: 202403338
A14: Descripción de Ponderación | B14: Valor | C14: Observación | D14: Punteo
A15: 1. HABILIDADES – CÓMO SE PROGRAMA | B15: =B16+B21+B25 -> 15 | D15: =IF(N(D16)+N(D21)+N(D25)=0,"",N(D16)+N(D21)+N(D25)) -> 15
A16: 1.1 Documentación | B16: =SUM(B17:B20) -> 6 | D16: =IF(SUM(D17:D20)=0,"",SUM(D17:D20)) -> 6
A17: Manual técnico: arquitectura, diagrama de clases, estructuras, hilos y formato de archivos | B17: 2 | D17: 2
A18: Manual de usuario con capturas reales de cada panel (residentes, vehículos, visitantes, simulación, eventos) | B18: 1.5 | D18: 1.5
A19: Informe de desarrollo: plan por etapas, avance, problemas encontrados y soluciones | B19: 1.5 | D19: 1.5
A20: Informe realizado con herramienta https://aicodedetector.org/ | B20: 1 | D20: 1
A21: 1.2 Repositorio GitHub | B21: =SUM(B22:B24) -> 4 | D21: =IF(SUM(D22:D24)=0,"",SUM(D22:D24)) -> 4
A22: Formato de nombre correcto y auxiliar agregado como colaborador | B22: 1 | D22: 1
A23: Commits incrementales y semánticos (feat:, fix:, docs:), no concentrados al final | B23: 2 | D23: 2
A24: Proyecto compilable desde el repo, .jar ejecutable y archivos .txt de ejemplo incluidos | B24: 1 | D24: 1
A25: 1.3 Buenas prácticas de código e interfaz | B25: =SUM(B26:B28) -> 5 | D25: =IF(SUM(D26:D28)=0,"",SUM(D26:D28)) -> 5
A26: Organización en paquetes (estructuras, modelo, hilos, persistencia, vista) con POO y sin sobreingeniería | B26: 2 | D26: 2
A27: Nombres de variables/métodos claros y comentarios útiles | B27: 1 | D27: 1
A28: Swing codificado manualmente y actualización de la UI desde hilos con SwingUtilities.invokeLater | B28: 2 | D28: 2
A29: 2. CONOCIMIENTO – QUÉ SE PROGRAMA | B29: =B30+B34+B37+B42+B45+B48+B53+B56+B59 -> 35 | D29: =IF(N(D30)+N(D34)+N(D37)+N(D42)+N(D45)+N(D48)+N(D53)+N(D56)+N(D59)=0,"",N(D30)+N(D34)+N(D37)+N(D42)+N(D45)+N(D48)+N(D53)+N(D56)+N(D59)) -> 35
A30: 2.1 Lista doblemente enlazada – Residentes | B30: =SUM(B31:B33) -> 5 | D30: =IF(SUM(D31:D33)=0,"",SUM(D31:D33)) -> 5
A31: Nodo propio con anterior/siguiente; insertar y buscar residentes (ID, nombre, casa, socio) | B31: 2 | D31: 2
A32: Eliminar y actualizar residentes manteniendo correctamente las referencias | B32: 2 | D32: 2
A33: Recorrido de la lista en ambos sentidos y visualización de los residentes | B33: 1 | D33: 1
A34: 2.2 Lista simplemente enlazada – Vehículos | B34: =SUM(B35:B36) -> 3 | D34: =IF(SUM(D35:D36)=0,"",SUM(D35:D36)) -> 3
A35: Lista propia por residente: insertar, eliminar y recorrer vehículos (placa, marca, modelo, color, tipo, estado) | B35: 2 | D35: 2
A36: Validación de 0 a 3 vehículos: impide registrar un cuarto vehículo | B36: 1 | D36: 1
A37: 2.3 Lista doble de listas simples – Parqueo | B37: =SUM(B38:B41) -> 7 | D37: =IF(SUM(D38:D41)=0,"",SUM(D38:D41)) -> 7
A38: 150 nodos que representan espacios físicos (ID, estado, vehículo estacionado, tipo socio/general) | B38: 2 | D38: 2
A39: Enlaces arriba/abajo y enlace simple que reflejan la distribución A–C (25) y E–I (15) | B39: 2 | D39: 2
A40: Recorrido para buscar espacio libre por tipo, asignación y liberación correcta del espacio | B40: 2 | D40: 2
A41: Validación del área de socios: ningún vehículo no autorizado ocupa A–C (reglas documentadas) | B41: 1 | D41: 1
A42: 2.4 Colas FIFO – Entrada y salida | B42: =SUM(B43:B44) -> 3 | D42: =IF(SUM(D43:D44)=0,"",SUM(D43:D44)) -> 3
A43: Cola de entrada manual (FIFO) consumida por las 3 garitas de entrada | B43: 1.5 | D43: 1.5
...

Sheet 202507586
A1: UNIVERSIDAD DE SAN CARLOS DE GUATEMALA
A2: FACULTAD DE INGENIERÍA
A3: ESCUELA DE CIENCIAS Y SISTEMAS
A4: Introducción a la Programación y Computación 1, Sección E
A5: Ing. William Estuardo Escobar Argueta
A6: Aux. Fernando José Vicente Velásquez
A8: Hoja de Calificación – Proyecto 2: Parque Residencial: Sistema de Gestión de Parqueo
A10: Fecha de calificación:
A11: Nombre del estudiante: | C11: =VLOOKUP(C12, Consolidado!$B$3:$C$26, 2, 0) -> #N/A
A12: Carné: | C12: 202507586
A14: Descripción de Ponderación | B14: Valor | C14: Observación | D14: Punteo
A15: 1. HABILIDADES – CÓMO SE PROGRAMA | B15: =B16+B21+B25 -> 15 | D15: =IF(N(D16)+N(D21)+N(D25)=0,"",N(D16)+N(D21)+N(D25)) -> 15
A16: 1.1 Documentación | B16: =SUM(B17:B20) -> 6 | D16: =IF(SUM(D17:D20)=0,"",SUM(D17:D20)) -> 6
A17: Manual técnico: arquitectura, diagrama de clases, estructuras, hilos y formato de archivos | B17: 2 | D17: 2
A18: Manual de usuario con capturas reales de cada panel (residentes, vehículos, visitantes, simulación, eventos) | B18: 1.5 | D18: 1.5
A19: Informe de desarrollo: plan por etapas, avance, problemas encontrados y soluciones | B19: 1.5 | D19: 1.5
A20: Informe realizado con herramienta https://aicodedetector.org/ | B20: 1 | D20: 1
A21: 1.2 Repositorio GitHub | B21: =SUM(B22:B24) -> 4 | D21: =IF(SUM(D22:D24)=0,"",SUM(D22:D24)) -> 4
A22: Formato de nombre correcto y auxiliar agregado como colaborador | B22: 1 | D22: 1
A23: Commits incrementales y semánticos (feat:, fix:, docs:), no concentrados al final | B23: 2 | D23: 2
A24: Proyecto compilable desde el repo, .jar ejecutable y archivos .txt de ejemplo incluidos | B24: 1 | D24: 1
A25: 1.3 Buenas prácticas de código e interfaz | B25: =SUM(B26:B28) -> 5 | D25: =IF(SUM(D26:D28)=0,"",SUM(D26:D28)) -> 5
A26: Organización en paquetes (estructuras, modelo, hilos, persistencia, vista) con POO y sin sobreingeniería | B26: 2 | D26: 2
A27: Nombres de variables/métodos claros y comentarios útiles | B27: 1 | D27: 1
A28: Swing codificado manualmente y actualización de la UI desde hilos con SwingUtilities.invokeLater | B28: 2 | D28: 2
A29: 2. CONOCIMIENTO – QUÉ SE PROGRAMA | B29: =B30+B34+B37+B42+B45+B48+B53+B56+B59 -> 35 | D29: =IF(N(D30)+N(D34)+N(D37)+N(D42)+N(D45)+N(D48)+N(D53)+N(D56)+N(D59)=0,"",N(D30)+N(D34)+N(D37)+N(D42)+N(D45)+N(D48)+N(D53)+N(D56)+N(D59)) -> 33
A30: 2.1 Lista doblemente enlazada – Residentes | B30: =SUM(B31:B33) -> 5 | D30: =IF(SUM(D31:D33)=0,"",SUM(D31:D33)) -> 4
A31: Nodo propio con anterior/siguiente; insertar y buscar residentes (ID, nombre, casa, socio) | B31: 2 | D31: 2
A32: Eliminar y actualizar residentes manteniendo correctamente las referencias | B32: 2 | D32: 1
A33: Recorrido de la lista en ambos sentidos y visualización de los residentes | B33: 1 | D33: 1
A34: 2.2 Lista simplemente enlazada – Vehículos | B34: =SUM(B35:B36) -> 3 | D34: =IF(SUM(D35:D36)=0,"",SUM(D35:D36)) -> 3
A35: Lista propia por residente: insertar, eliminar y recorrer vehículos (placa, marca, modelo, color, tipo, estado) | B35: 2 | D35: 2
A36: Validación de 0 a 3 vehículos: impide registrar un cuarto vehículo | B36: 1 | D36: 1
A37: 2.3 Lista doble de listas simples – Parqueo | B37: =SUM(B38:B41) -> 7 | D37: =IF(SUM(D38:D41)=0,"",SUM(D38:D41)) -> 6
A38: 150 nodos que representan espacios físicos (ID, estado, vehículo estacionado, tipo socio/general) | B38: 2 | D38: 1
A39: Enlaces arriba/abajo y enlace simple que reflejan la distribución A–C (25) y E–I (15) | B39: 2 | D39: 2
A40: Recorrido para buscar espacio libre por tipo, asignación y liberación correcta del espacio | B40: 2 | D40: 2
A41: Validación del área de socios: ningún vehículo no autorizado ocupa A–C (reglas documentadas) | B41: 1 | D41: 1
A42: 2.4 Colas FIFO – Entrada y salida | B42: =SUM(B43:B44) -> 3 | D42: =IF(SUM(D43:D44)=0,"",SUM(D43:D44)) -> 3
A43: Cola de entrada manual (FIFO) consumida por las 3 garitas de entrada | B43: 1.5 | D43: 1.5
...

Sheet 202501625
A1: UNIVERSIDAD DE SAN CARLOS DE GUATEMALA
A2: FACULTAD DE INGENIERÍA
A3: ESCUELA DE CIENCIAS Y SISTEMAS
A4: Introducción a la Programación y Computación 1, Sección E
A5: Ing. William Estuardo Escobar Argueta
A6: Aux. Fernando José Vicente Velásquez
A8: Hoja de Calificación – Proyecto 2: Parque Residencial: Sistema de Gestión de Parqueo
A10: Fecha de calificación:
A11: Nombre del estudiante: | C11: =VLOOKUP(C12, Consolidado!$B$3:$C$26, 2, 0) -> #N/A
A12: Carné: | C12: 202501625
A14: Descripción de Ponderación | B14: Valor | C14: Observación | D14: Punteo
A15: 1. HABILIDADES – CÓMO SE PROGRAMA | B15: =B16+B21+B25 -> 15 | D15: =IF(N(D16)+N(D21)+N(D25)=0,"",N(D16)+N(D21)+N(D25)) -> 15
A16: 1.1 Documentación | B16: =SUM(B17:B20) -> 6 | D16: =IF(SUM(D17:D20)=0,"",SUM(D17:D20)) -> 6
A17: Manual técnico: arquitectura, diagrama de clases, estructuras, hilos y formato de archivos | B17: 2 | D17: 2
A18: Manual de usuario con capturas reales de cada panel (residentes, vehículos, visitantes, simulación, eventos) | B18: 1.5 | D18: 1.5
A19: Informe de desarrollo: plan por etapas, avance, problemas encontrados y soluciones | B19: 1.5 | D19: 1.5
A20: Informe realizado con herramienta https://aicodedetector.org/ | B20: 1 | D20: 1
A21: 1.2 Repositorio GitHub | B21: =SUM(B22:B24) -> 4 | D21: =IF(SUM(D22:D24)=0,"",SUM(D22:D24)) -> 4
A22: Formato de nombre correcto y auxiliar agregado como colaborador | B22: 1 | D22: 1
A23: Commits incrementales y semánticos (feat:, fix:, docs:), no concentrados al final | B23: 2 | D23: 2
A24: Proyecto compilable desde el repo, .jar ejecutable y archivos .txt de ejemplo incluidos | B24: 1 | D24: 1
A25: 1.3 Buenas prácticas de código e interfaz | B25: =SUM(B26:B28) -> 5 | D25: =IF(SUM(D26:D28)=0,"",SUM(D26:D28)) -> 5
A26: Organización en paquetes (estructuras, modelo, hilos, persistencia, vista) con POO y sin sobreingeniería | B26: 2 | D26: 2
A27: Nombres de variables/métodos claros y comentarios útiles | B27: 1 | D27: 1
A28: Swing codificado manualmente y actualización de la UI desde hilos con SwingUtilities.invokeLater | B28: 2 | D28: 2
A29: 2. CONOCIMIENTO – QUÉ SE PROGRAMA | B29: =B30+B34+B37+B42+B45+B48+B53+B56+B59 -> 35 | D29: =IF(N(D30)+N(D34)+N(D37)+N(D42)+N(D45)+N(D48)+N(D53)+N(D56)+N(D59)=0,"",N(D30)+N(D34)+N(D37)+N(D42)+N(D45)+N(D48)+N(D53)+N(D56)+N(D59)) -> 35
A30: 2.1 Lista doblemente enlazada – Residentes | B30: =SUM(B31:B33) -> 5 | D30: =IF(SUM(D31:D33)=0,"",SUM(D31:D33)) -> 5
A31: Nodo propio con anterior/siguiente; insertar y buscar residentes (ID, nombre, casa, socio) | B31: 2 | D31: 2
A32: Eliminar y actualizar residentes manteniendo correctamente las referencias | B32: 2 | D32: 2
A33: Recorrido de la lista en ambos sentidos y visualización de los residentes | B33: 1 | D33: 1
A34: 2.2 Lista simplemente enlazada – Vehículos | B34: =SUM(B35:B36) -> 3 | D34: =IF(SUM(D35:D36)=0,"",SUM(D35:D36)) -> 3
A35: Lista propia por residente: insertar, eliminar y recorrer vehículos (placa, marca, modelo, color, tipo, estado) | B35: 2 | D35: 2
A36: Validación de 0 a 3 vehículos: impide registrar un cuarto vehículo | B36: 1 | D36: 1
A37: 2.3 Lista doble de listas simples – Parqueo | B37: =SUM(B38:B41) -> 7 | D37: =IF(SUM(D38:D41)=0,"",SUM(D38:D41)) -> 7
A38: 150 nodos que representan espacios físicos (ID, estado, vehículo estacionado, tipo socio/general) | B38: 2 | D38: 2
A39: Enlaces arriba/abajo y enlace simple que reflejan la distribución A–C (25) y E–I (15) | B39: 2 | D39: 2
A40: Recorrido para buscar espacio libre por tipo, asignación y liberación correcta del espacio | B40: 2 | D40: 2
A41: Validación del área de socios: ningún vehículo no autorizado ocupa A–C (reglas documentadas) | B41: 1 | D41: 1
A42: 2.4 Colas FIFO – Entrada y salida | B42: =SUM(B43:B44) -> 3 | D42: =IF(SUM(D43:D44)=0,"",SUM(D43:D44)) -> 3
A43: Cola de entrada manual (FIFO) consumida por las 3 garitas de entrada | B43: 1.5 | D43: 1.5
...

Sheet 202505830
A1: UNIVERSIDAD DE SAN CARLOS DE GUATEMALA
A2: FACULTAD DE INGENIERÍA
A3: ESCUELA DE CIENCIAS Y SISTEMAS
A4: Introducción a la Programación y Computación 1, Sección E
A5: Ing. William Estuardo Escobar Argueta
A6: Aux. Fernando José Vicente Velásquez
A8: Hoja de Calificación – Proyecto 2: Parque Residencial: Sistema de Gestión de Parqueo
A10: Fecha de calificación:
A11: Nombre del estudiante: | C11: =VLOOKUP(C12, Consolidado!$B$3:$C$26, 2, 0) -> #N/A
A12: Carné: | C12: 202505830
A14: Descripción de Ponderación | B14: Valor | C14: Observación | D14: Punteo
A15: 1. HABILIDADES – CÓMO SE PROGRAMA | B15: =B16+B21+B25 -> 15 | D15: =IF(N(D16)+N(D21)+N(D25)=0,"",N(D16)+N(D21)+N(D25)) -> 15
A16: 1.1 Documentación | B16: =SUM(B17:B20) -> 6 | D16: =IF(SUM(D17:D20)=0,"",SUM(D17:D20)) -> 6
A17: Manual técnico: arquitectura, diagrama de clases, estructuras, hilos y formato de archivos | B17: 2 | D17: 2
A18: Manual de usuario con capturas reales de cada panel (residentes, vehículos, visitantes, simulación, eventos) | B18: 1.5 | D18: 1.5
A19: Informe de desarrollo: plan por etapas, avance, problemas encontrados y soluciones | B19: 1.5 | D19: 1.5
A20: Informe realizado con herramienta https://aicodedetector.org/ | B20: 1 | D20: 1
A21: 1.2 Repositorio GitHub | B21: =SUM(B22:B24) -> 4 | D21: =IF(SUM(D22:D24)=0,"",SUM(D22:D24)) -> 4
A22: Formato de nombre correcto y auxiliar agregado como colaborador | B22: 1 | D22: 1
A23: Commits incrementales y semánticos (feat:, fix:, docs:), no concentrados al final | B23: 2 | D23: 2
A24: Proyecto compilable desde el repo, .jar ejecutable y archivos .txt de ejemplo incluidos | B24: 1 | D24: 1
A25: 1.3 Buenas prácticas de código e interfaz | B25: =SUM(B26:B28) -> 5 | D25: =IF(SUM(D26:D28)=0,"",SUM(D26:D28)) -> 5
A26: Organización en paquetes (estructuras, modelo, hilos, persistencia, vista) con POO y sin sobreingeniería | B26: 2 | D26: 2
A27: Nombres de variables/métodos claros y comentarios útiles | B27: 1 | D27: 1
A28: Swing codificado manualmente y actualización de la UI desde hilos con SwingUtilities.invokeLater | B28: 2 | D28: 2
A29: 2. CONOCIMIENTO – QUÉ SE PROGRAMA | B29: =B30+B34+B37+B42+B45+B48+B53+B56+B59 -> 35 | D29: =IF(N(D30)+N(D34)+N(D37)+N(D42)+N(D45)+N(D48)+N(D53)+N(D56)+N(D59)=0,"",N(D30)+N(D34)+N(D37)+N(D42)+N(D45)+N(D48)+N(D53)+N(D56)+N(D59)) -> 35
A30: 2.1 Lista doblemente enlazada – Residentes | B30: =SUM(B31:B33) -> 5 | D30: =IF(SUM(D31:D33)=0,"",SUM(D31:D33)) -> 5
A31: Nodo propio con anterior/siguiente; insertar y buscar residentes (ID, nombre, casa, socio) | B31: 2 | D31: 2
A32: Eliminar y actualizar residentes manteniendo correctamente las referencias | B32: 2 | D32: 2
A33: Recorrido de la lista en ambos sentidos y visualización de los residentes | B33: 1 | D33: 1
A34: 2.2 Lista simplemente enlazada – Vehículos | B34: =SUM(B35:B36) -> 3 | D34: =IF(SUM(D35:D36)=0,"",SUM(D35:D36)) -> 3
A35: Lista propia por residente: insertar, eliminar y recorrer vehículos (placa, marca, modelo, color, tipo, estado) | B35: 2 | D35: 2
A36: Validación de 0 a 3 vehículos: impide registrar un cuarto vehículo | B36: 1 | D36: 1
A37: 2.3 Lista doble de listas simples – Parqueo | B37: =SUM(B38:B41) -> 7 | D37: =IF(SUM(D38:D41)=0,"",SUM(D38:D41)) -> 7
A38: 150 nodos que representan espacios físicos (ID, estado, vehículo estacionado, tipo socio/general) | B38: 2 | D38: 2
A39: Enlaces arriba/abajo y enlace simple que reflejan la distribución A–C (25) y E–I (15) | B39: 2 | D39: 2
A40: Recorrido para buscar espacio libre por tipo, asignación y liberación correcta del espacio | B40: 2 | D40: 2
A41: Validación del área de socios: ningún vehículo no autorizado ocupa A–C (reglas documentadas) | B41: 1 | D41: 1
A42: 2.4 Colas FIFO – Entrada y salida | B42: =SUM(B43:B44) -> 3 | D42: =IF(SUM(D43:D44)=0,"",SUM(D43:D44)) -> 3
A43: Cola de entrada manual (FIFO) consumida por las 3 garitas de entrada | B43: 1.5 | D43: 1.5
...

Sheet 202406816
A1: UNIVERSIDAD DE SAN CARLOS DE GUATEMALA
A2: FACULTAD DE INGENIERÍA
A3: ESCUELA DE CIENCIAS Y SISTEMAS
A4: Introducción a la Programación y Computación 1, Sección E
A5: Ing. William Estuardo Escobar Argueta
A6: Aux. Fernando José Vicente Velásquez
A8: Hoja de Calificación – Proyecto 2: Parque Residencial: Sistema de Gestión de Parqueo
A10: Fecha de calificación:
A11: Nombre del estudiante: | C11: =VLOOKUP(C12, Consolidado!$B$3:$C$26, 2, 0) -> #N/A
A12: Carné: | C12: 202406816
A14: Descripción de Ponderación | B14: Valor | C14: Observación | D14: Punteo
A15: 1. HABILIDADES – CÓMO SE PROGRAMA | B15: =B16+B21+B25 -> 15 | D15: =IF(N(D16)+N(D21)+N(D25)=0,"",N(D16)+N(D21)+N(D25)) -> 15
A16: 1.1 Documentación | B16: =SUM(B17:B20) -> 6 | D16: =IF(SUM(D17:D20)=0,"",SUM(D17:D20)) -> 6
A17: Manual técnico: arquitectura, diagrama de clases, estructuras, hilos y formato de archivos | B17: 2 | D17: 2
A18: Manual de usuario con capturas reales de cada panel (residentes, vehículos, visitantes, simulación, eventos) | B18: 1.5 | D18: 1.5
A19: Informe de desarrollo: plan por etapas, avance, problemas encontrados y soluciones | B19: 1.5 | D19: 1.5
A20: Informe realizado con herramienta https://aicodedetector.org/ | B20: 1 | D20: 1
A21: 1.2 Repositorio GitHub | B21: =SUM(B22:B24) -> 4 | D21: =IF(SUM(D22:D24)=0,"",SUM(D22:D24)) -> 4
A22: Formato de nombre correcto y auxiliar agregado como colaborador | B22: 1 | D22: 1
A23: Commits incrementales y semánticos (feat:, fix:, docs:), no concentrados al final | B23: 2 | D23: 2
A24: Proyecto compilable desde el repo, .jar ejecutable y archivos .txt de ejemplo incluidos | B24: 1 | D24: 1
A25: 1.3 Buenas prácticas de código e interfaz | B25: =SUM(B26:B28) -> 5 | D25: =IF(SUM(D26:D28)=0,"",SUM(D26:D28)) -> 5
A26: Organización en paquetes (estructuras, modelo, hilos, persistencia, vista) con POO y sin sobreingeniería | B26: 2 | D26: 2
A27: Nombres de variables/métodos claros y comentarios útiles | B27: 1 | D27: 1
A28: Swing codificado manualmente y actualización de la UI desde hilos con SwingUtilities.invokeLater | B28: 2 | D28: 2
A29: 2. CONOCIMIENTO – QUÉ SE PROGRAMA | B29: =B30+B34+B37+B42+B45+B48+B53+B56+B59 -> 35 | D29: =IF(N(D30)+N(D34)+N(D37)+N(D42)+N(D45)+N(D48)+N(D53)+N(D56)+N(D59)=0,"",N(D30)+N(D34)+N(D37)+N(D42)+N(D45)+N(D48)+N(D53)+N(D56)+N(D59)) -> 35
A30: 2.1 Lista doblemente enlazada – Residentes | B30: =SUM(B31:B33) -> 5 | D30: =IF(SUM(D31:D33)=0,"",SUM(D31:D33)) -> 5
A31: Nodo propio con anterior/siguiente; insertar y buscar residentes (ID, nombre, casa, socio) | B31: 2 | D31: 2
A32: Eliminar y actualizar residentes manteniendo correctamente las referencias | B32: 2 | D32: 2
A33: Recorrido de la lista en ambos sentidos y visualización de los residentes | B33: 1 | D33: 1
A34: 2.2 Lista simplemente enlazada – Vehículos | B34: =SUM(B35:B36) -> 3 | D34: =IF(SUM(D35:D36)=0,"",SUM(D35:D36)) -> 3
A35: Lista propia por residente: insertar, eliminar y recorrer vehículos (placa, marca, modelo, color, tipo, estado) | B35: 2 | D35: 2
A36: Validación de 0 a 3 vehículos: impide registrar un cuarto vehículo | B36: 1 | D36: 1
A37: 2.3 Lista doble de listas simples – Parqueo | B37: =SUM(B38:B41) -> 7 | D37: =IF(SUM(D38:D41)=0,"",SUM(D38:D41)) -> 7
A38: 150 nodos que representan espacios físicos (ID, estado, vehículo estacionado, tipo socio/general) | B38: 2 | D38: 2
A39: Enlaces arriba/abajo y enlace simple que reflejan la distribución A–C (25) y E–I (15) | B39: 2 | D39: 2
A40: Recorrido para buscar espacio libre por tipo, asignación y liberación correcta del espacio | B40: 2 | D40: 2
A41: Validación del área de socios: ningún vehículo no autorizado ocupa A–C (reglas documentadas) | B41: 1 | D41: 1
A42: 2.4 Colas FIFO – Entrada y salida | B42: =SUM(B43:B44) -> 3 | D42: =IF(SUM(D43:D44)=0,"",SUM(D43:D44)) -> 3
A43: Cola de entrada manual (FIFO) consumida por las 3 garitas de entrada | B43: 1.5 | D43: 1.5
...

Sheet 202501349
A1: UNIVERSIDAD DE SAN CARLOS DE GUATEMALA
A2: FACULTAD DE INGENIERÍA
A3: ESCUELA DE CIENCIAS Y SISTEMAS
A4: Introducción a la Programación y Computación 1, Sección E
A5: Ing. William Estuardo Escobar Argueta
A6: Aux. Fernando José Vicente Velásquez
A8: Hoja de Calificación – Proyecto 2: Parque Residencial: Sistema de Gestión de Parqueo
A10: Fecha de calificación:
A11: Nombre del estudiante: | C11: =VLOOKUP(C12, Consolidado!$B$3:$C$26, 2, 0) -> #N/A
A12: Carné: | C12: 202501349
A14: Descripción de Ponderación | B14: Valor | C14: Observación | D14: Punteo
A15: 1. HABILIDADES – CÓMO SE PROGRAMA | B15: =B16+B21+B25 -> 15 | D15: =IF(N(D16)+N(D21)+N(D25)=0,"",N(D16)+N(D21)+N(D25)) -> 15
A16: 1.1 Documentación | B16: =SUM(B17:B20) -> 6 | D16: =IF(SUM(D17:D20)=0,"",SUM(D17:D20)) -> 6
A17: Manual técnico: arquitectura, diagrama de clases, estructuras, hilos y formato de archivos | B17: 2 | D17: 2
A18: Manual de usuario con capturas reales de cada panel (residentes, vehículos, visitantes, simulación, eventos) | B18: 1.5 | D18: 1.5
A19: Informe de desarrollo: plan por etapas, avance, problemas encontrados y soluciones | B19: 1.5 | D19: 1.5
A20: Informe realizado con herramienta https://aicodedetector.org/ | B20: 1 | D20: 1
A21: 1.2 Repositorio GitHub | B21: =SUM(B22:B24) -> 4 | D21: =IF(SUM(D22:D24)=0,"",SUM(D22:D24)) -> 4
A22: Formato de nombre correcto y auxiliar agregado como colaborador | B22: 1 | D22: 1
A23: Commits incrementales y semánticos (feat:, fix:, docs:), no concentrados al final | B23: 2 | D23: 2
A24: Proyecto compilable desde el repo, .jar ejecutable y archivos .txt de ejemplo incluidos | B24: 1 | D24: 1
A25: 1.3 Buenas prácticas de código e interfaz | B25: =SUM(B26:B28) -> 5 | D25: =IF(SUM(D26:D28)=0,"",SUM(D26:D28)) -> 5
A26: Organización en paquetes (estructuras, modelo, hilos, persistencia, vista) con POO y sin sobreingeniería | B26: 2 | D26: 2
A27: Nombres de variables/métodos claros y comentarios útiles | B27: 1 | D27: 1
A28: Swing codificado manualmente y actualización de la UI desde hilos con SwingUtilities.invokeLater | B28: 2 | D28: 2
A29: 2. CONOCIMIENTO – QUÉ SE PROGRAMA | B29: =B30+B34+B37+B42+B45+B48+B53+B56+B59 -> 35 | D29: =IF(N(D30)+N(D34)+N(D37)+N(D42)+N(D45)+N(D48)+N(D53)+N(D56)+N(D59)=0,"",N(D30)+N(D34)+N(D37)+N(D42)+N(D45)+N(D48)+N(D53)+N(D56)+N(D59)) -> 35
A30: 2.1 Lista doblemente enlazada – Residentes | B30: =SUM(B31:B33) -> 5 | D30: =IF(SUM(D31:D33)=0,"",SUM(D31:D33)) -> 5
A31: Nodo propio con anterior/siguiente; insertar y buscar residentes (ID, nombre, casa, socio) | B31: 2 | D31: 2
A32: Eliminar y actualizar residentes manteniendo correctamente las referencias | B32: 2 | D32: 2
A33: Recorrido de la lista en ambos sentidos y visualización de los residentes | B33: 1 | D33: 1
A34: 2.2 Lista simplemente enlazada – Vehículos | B34: =SUM(B35:B36) -> 3 | D34: =IF(SUM(D35:D36)=0,"",SUM(D35:D36)) -> 3
A35: Lista propia por residente: insertar, eliminar y recorrer vehículos (placa, marca, modelo, color, tipo, estado) | B35: 2 | D35: 2
A36: Validación de 0 a 3 vehículos: impide registrar un cuarto vehículo | B36: 1 | D36: 1
A37: 2.3 Lista doble de listas simples – Parqueo | B37: =SUM(B38:B41) -> 7 | D37: =IF(SUM(D38:D41)=0,"",SUM(D38:D41)) -> 7
A38: 150 nodos que representan espacios físicos (ID, estado, vehículo estacionado, tipo socio/general) | B38: 2 | D38: 2
A39: Enlaces arriba/abajo y enlace simple que reflejan la distribución A–C (25) y E–I (15) | B39: 2 | D39: 2
A40: Recorrido para buscar espacio libre por tipo, asignación y liberación correcta del espacio | B40: 2 | D40: 2
A41: Validación del área de socios: ningún vehículo no autorizado ocupa A–C (reglas documentadas) | B41: 1 | D41: 1
A42: 2.4 Colas FIFO – Entrada y salida | B42: =SUM(B43:B44) -> 3 | D42: =IF(SUM(D43:D44)=0,"",SUM(D43:D44)) -> 3
A43: Cola de entrada manual (FIFO) consumida por las 3 garitas de entrada | B43: 1.5 | D43: 1.5
...

Sheet Consolidado
A1: Consolidado de calificaciones – Proyecto 2: Parque Residencial: Sistema de Gestión de Parqueo
A2: No. | B2: Carné | C2: Nombre del estudiante | D2: Habilidades (15) | E2: Conocimiento (35) | F2: Autoría (50) | G2: Subtotal | H2: Penalización | I2: Nota final | J2: Plagio | K2: Uso de IA | L2: Modificacion | M2: Repositorio
A3: 1 | B3: 201503481 | C3: MARTA GABRIELA GÓMEZ DIMAYUGA | D3: =IF($B3="","",N(IFERROR(INDIRECT("'"&$B3&"'!D15"),0))) -> 0 | E3: =IF($B3="","",N(IFERROR(INDIRECT("'"&$B3&"'!D29"),0))) -> 0 | F3: =IF($B3="","",N(IFERROR(INDIRECT("'"&$B3&"'!D64"),0))) -> 0 | G3: =IF(C3="","",SUM(D3:F3)) -> 0 | H3: =IF($B3="",0,MAX(-1,IFERROR(SUMIF(INDIRECT("'"&$B3&"'!C89:C106"),"S*",INDIRECT("'"&$B3&"'!B89:B106")),0))) -> 0 | I3: =IF(C3="","",MAX(0,ROUND(G3*(1+H3),2))) -> 0
A4: 2 | B4: 201503481 | C4: DIEGO ALFONSO CANEL FUENTES | D4: =IF($B4="","",N(IFERROR(INDIRECT("'"&$B4&"'!D15"),0))) -> 0 | E4: =IF($B4="","",N(IFERROR(INDIRECT("'"&$B4&"'!D29"),0))) -> 0 | F4: =IF($B4="","",N(IFERROR(INDIRECT("'"&$B4&"'!D64"),0))) -> 0 | G4: =IF(C4="","",SUM(D4:F4)) -> 0 | H4: =IF($B4="",0,MAX(-1,IFERROR(SUMIF(INDIRECT("'"&$B4&"'!C89:C106"),"S*",INDIRECT("'"&$B4&"'!B89:B106")),0))) -> 0 | I4: =IF(C4="","",MAX(0,ROUND(G4*(1+H4),2))) -> 0
A5: 3 | B5: 202004723 | C5: ERMI RONALDO SOTO MEJÍA | D5: =IF($B5="","",N(IFERROR(INDIRECT("'"&$B5&"'!D15"),0))) -> 0 | E5: =IF($B5="","",N(IFERROR(INDIRECT("'"&$B5&"'!D29"),0))) -> 0 | F5: =IF($B5="","",N(IFERROR(INDIRECT("'"&$B5&"'!D64"),0))) -> 0 | G5: =IF(C5="","",SUM(D5:F5)) -> 0 | H5: =IF($B5="",0,MAX(-1,IFERROR(SUMIF(INDIRECT("'"&$B5&"'!C89:C106"),"S*",INDIRECT("'"&$B5&"'!B89:B106")),0))) -> 0 | I5: =IF(C5="","",MAX(0,ROUND(G5*(1+H5),2))) -> 0
A6: 4 | B6: 202201204 | C6: BRYAN ALEXANDER MARTÍNEZ FLORES | D6: =IF($B6="","",N(IFERROR(INDIRECT("'"&$B6&"'!D15"),0))) -> 0 | E6: =IF($B6="","",N(IFERROR(INDIRECT("'"&$B6&"'!D29"),0))) -> 0 | F6: =IF($B6="","",N(IFERROR(INDIRECT("'"&$B6&"'!D64"),0))) -> 0 | G6: =IF(C6="","",SUM(D6:F6)) -> 0 | H6: =IF($B6="",0,MAX(-1,IFERROR(SUMIF(INDIRECT("'"&$B6&"'!C89:C106"),"S*",INDIRECT("'"&$B6&"'!B89:B106")),0))) -> 0 | I6: =IF(C6="","",MAX(0,ROUND(G6*(1+H6),2))) -> 0
A7: 5 | B7: 202300365 | C7: BRAYAN HOMERO SOSA GONZALEZ | D7: =IF($B7="","",N(IFERROR(INDIRECT("'"&$B7&"'!D15"),0))) -> 0 | E7: =IF($B7="","",N(IFERROR(INDIRECT("'"&$B7&"'!D29"),0))) -> 0 | F7: =IF($B7="","",N(IFERROR(INDIRECT("'"&$B7&"'!D64"),0))) -> 0 | G7: =IF(C7="","",SUM(D7:F7)) -> 0 | H7: =IF($B7="",0,MAX(-1,IFERROR(SUMIF(INDIRECT("'"&$B7&"'!C89:C106"),"S*",INDIRECT("'"&$B7&"'!B89:B106")),0))) -> 0 | I7: =IF(C7="","",MAX(0,ROUND(G7*(1+H7),2))) -> 0
A8: 6 | B8: 202303797 | C8: ROLANDO AARÓN BARRIOS BOROR | D8: =IF($B8="","",N(IFERROR(INDIRECT("'"&$B8&"'!D15"),0))) -> 0 | E8: =IF($B8="","",N(IFERROR(INDIRECT("'"&$B8&"'!D29"),0))) -> 0 | F8: =IF($B8="","",N(IFERROR(INDIRECT("'"&$B8&"'!D64"),0))) -> 0 | G8: =IF(C8="","",SUM(D8:F8)) -> 0 | H8: =IF($B8="",0,MAX(-1,IFERROR(SUMIF(INDIRECT("'"&$B8&"'!C89:C106"),"S*",INDIRECT("'"&$B8&"'!B89:B106")),0))) -> 0 | I8: =IF(C8="","",MAX(0,ROUND(G8*(1+H8),2))) -> 0
A9: 7 | B9: 202306260 | C9: WILLIAM SAMUEL CABRERA GÓMEZ | D9: =IF($B9="","",N(IFERROR(INDIRECT("'"&$B9&"'!D15"),0))) -> 0 | E9: =IF($B9="","",N(IFERROR(INDIRECT("'"&$B9&"'!D29"),0))) -> 0 | F9: =IF($B9="","",N(IFERROR(INDIRECT("'"&$B9&"'!D64"),0))) -> 0 | G9: =IF(C9="","",SUM(D9:F9)) -> 0 | H9: =IF($B9="",0,MAX(-1,IFERROR(SUMIF(INDIRECT("'"&$B9&"'!C89:C106"),"S*",INDIRECT("'"&$B9&"'!B89:B106")),0))) -> 0 | I9: =IF(C9="","",MAX(0,ROUND(G9*(1+H9),2))) -> 0
A10: 8 | B10: 202308203 | C10: HANS CRISTIAN MEYER DIAZ | D10: =IF($B10="","",N(IFERROR(INDIRECT("'"&$B10&"'!D15"),0))) -> 0 | E10: =IF($B10="","",N(IFERROR(INDIRECT("'"&$B10&"'!D29"),0))) -> 0 | F10: =IF($B10="","",N(IFERROR(INDIRECT("'"&$B10&"'!D64"),0))) -> 0 | G10: =IF(C10="","",SUM(D10:F10)) -> 0 | H10: =IF($B10="",0,MAX(-1,IFERROR(SUMIF(INDIRECT("'"&$B10&"'!C89:C106"),"S*",INDIRECT("'"&$B10&"'!B89:B106")),0))) -> 0 | I10: =IF(C10="","",MAX(0,ROUND(G10*(1+H10),2))) -> 0
A11: 9 | B11: 202308528 | C11: ASTRID MARIA SUSETH MORALES RODAS | D11: =IF($B11="","",N(IFERROR(INDIRECT("'"&$B11&"'!D15"),0))) -> 0 | E11: =IF($B11="","",N(IFERROR(INDIRECT("'"&$B11&"'!D29"),0))) -> 0 | F11: =IF($B11="","",N(IFERROR(INDIRECT("'"&$B11&"'!D64"),0))) -> 0 | G11: =IF(C11="","",SUM(D11:F11)) -> 0 | H11: =IF($B11="",0,MAX(-1,IFERROR(SUMIF(INDIRECT("'"&$B11&"'!C89:C106"),"S*",INDIRECT("'"&$B11&"'!B89:B106")),0))) -> 0 | I11: =IF(C11="","",MAX(0,ROUND(G11*(1+H11),2))) -> 0
A12: 10 | B12: 202400066 | C12: DIEGO SEBASTIAN ALVARADO MORATAYA | D12: =IF($B12="","",N(IFERROR(INDIRECT("'"&$B12&"'!D15"),0))) -> 7.5 | E12: =IF($B12="","",N(IFERROR(INDIRECT("'"&$B12&"'!D29"),0))) -> 35 | F12: =IF($B12="","",N(IFERROR(INDIRECT("'"&$B12&"'!D64"),0))) -> 11 | G12: =IF(C12="","",SUM(D12:F12)) -> 53.5 | H12: =IF($B12="",0,MAX(-1,IFERROR(SUMIF(INDIRECT("'"&$B12&"'!C89:C106"),"S*",INDIRECT("'"&$B12&"'!B89:B106")),0))) -> 0 | I12: =IF(C12="","",MAX(0,ROUND(G12*(1+H12),2))) -> 53.5
A13: 11 | B13: 202400155 | C13: ESVIN FERNANDO ORTEGA GONZÁLEZ | D13: =IF($B13="","",N(IFERROR(INDIRECT("'"&$B13&"'!D15"),0))) -> 15 | E13: =IF($B13="","",N(IFERROR(INDIRECT("'"&$B13&"'!D29"),0))) -> 35 | F13: =IF($B13="","",N(IFERROR(INDIRECT("'"&$B13&"'!D64"),0))) -> 0 | G13: =IF(C13="","",SUM(D13:F13)) -> 50 | H13: =IF($B13="",0,MAX(-1,IFERROR(SUMIF(INDIRECT("'"&$B13&"'!C89:C106"),"S*",INDIRECT("'"&$B13&"'!B89:B106")),0))) -> 0 | I13: =IF(C13="","",MAX(0,ROUND(G13*(1+H13),2))) -> 50
A14: 12 | B14: 202400482 | C14: ADRIAN EDUARDO ALVAREZ ZAMBRANO | D14: =IF($B14="","",N(IFERROR(INDIRECT("'"&$B14&"'!D15"),0))) -> 0 | E14: =IF($B14="","",N(IFERROR(INDIRECT("'"&$B14&"'!D29"),0))) -> 0 | F14: =IF($B14="","",N(IFERROR(INDIRECT("'"&$B14&"'!D64"),0))) -> 0 | G14: =IF(C14="","",SUM(D14:F14)) -> 0 | H14: =IF($B14="",0,MAX(-1,IFERROR(SUMIF(INDIRECT("'"&$B14&"'!C89:C106"),"S*",INDIRECT("'"&$B14&"'!B89:B106")),0))) -> 0 | I14: =IF(C14="","",MAX(0,ROUND(G14*(1+H14),2))) -> 0
A15: 13 | B15: 202403338 | C15: ANDY RAÍ TELÓN GABRIEL | D15: =IF($B15="","",N(IFERROR(INDIRECT("'"&$B15&"'!D15"),0))) -> 15 | E15: =IF($B15="","",N(IFERROR(INDIRECT("'"&$B15&"'!D29"),0))) -> 35 | F15: =IF($B15="","",N(IFERROR(INDIRECT("'"&$B15&"'!D64"),0))) -> 7 | G15: =IF(C15="","",SUM(D15:F15)) -> 57 | H15: =IF($B15="",0,MAX(-1,IFERROR(SUMIF(INDIRECT("'"&$B15&"'!C89:C106"),"S*",INDIRECT("'"&$B15&"'!B89:B106")),0))) -> 0 | I15: =IF(C15="","",MAX(0,ROUND(G15*(1+H15),2))) -> 57
... A26: 24 | B26: 202507586 | C26: KEVYN JOSUÉ APÉN OTZOY | D26: =IF($B26="","",N(IFERROR(INDIRECT("'"&$B26&"'!D15"),0))) -> 15 | E26: =IF($B26="","",N(IFERROR(INDIRECT("'"&$B26&"'!D29"),0))) -> 33 | F26: =IF($B26="","",N(IFERROR(INDIRECT("'"&$B26&"'!D64"),0))) -> 26 | G26: =IF(C26="","",SUM(D26:F26)) -> 74 | H26: =IF($B26="",0,MAX(-1,IFERROR(SUMIF(INDIRECT("'"&$B26&"'!C89:C106"),"S*",INDIRECT("'"&$B26&"'!B89:B106")),0))) -> 0 | I26: =IF(C26="","",MAX(0,ROUND(G26*(1+H26),2))) -> 74
C28: Estudiantes calificados | D28: =COUNT(I3:I26) -> 24
C29: Nota promedio | D29: =IFERROR(AVERAGE(I3:I26),0) -> 28.541667
C30: Nota más alta | D30: =IFERROR(MAX(I3:I26),0) -> 100
C31: Nota más baja | D31: =IFERROR(MIN(I3:I26),0) -> 0
C32: Aprobados (61 pts o más) | D32: =COUNTIF(I3:I26,">=61") -> 7
C33: Reprobados (menos de 61 pts) | D33: =COUNT(I3:I26)-COUNTIF(I3:I26,">=61") -> 17
