Workbook

Sheet Plantilla
A1: UNIVERSIDAD DE SAN CARLOS DE GUATEMALA
A2: FACULTAD DE INGENIERÍA
A3: ESCUELA DE CIENCIAS Y SISTEMAS
A4: Introducción a la Programación y Computación 1, Sección B
A5: Ing. William Estuardo Escobar Argueta
A6: Aux. Fernando José Vicente Velásquez
A8: Hoja de Calificación – Practica 2: Quetzal Space Defender - Side Scroller
A10: Fecha de calificación:
A11: Nombre del estudiante: | C11: =VLOOKUP(C12, Consolidado!$B$3:$C$26, 2, 0) -> #N/A
A12: Carné:
A14: Descripción de Ponderación | B14: Valor | C14: Observación | D14: Punteo
A15: 1. HABILIDADES – CÓMO SE PROGRAMA | B15: =B16+B21+B25 -> 25 | D15: =IF(D16+D21+D25=0,"",D16+D21+D25) -> #VALUE!
A16: 1.1 Documentación | B16: =SUM(B17:B20) -> 10 | D16: =IF(SUM(D17:D20)=0,"",SUM(D17:D20))
A17: Manual técnico detallado completo y coherente con el código | B17: 3
A18: Manual de usuario con capturas reales y guia para el usuario | B18: 3
A19: Diagramas (flujo, módulos, matriz de ubicaciones) | B19: 2
A20: Informe realizado con herramienta https://aicodedetector.org/ | B20: 2
A21: 1.2 Repositorio GitHub | B21: =SUM(B22:B24) -> 7 | D21: =IF(SUM(D22:D24)=0,"",SUM(D22:D24))
A22: Formato de nombre correcto y auxiliar agregado como colaborador | B22: 2
A23: Commits progresivos, no concentrados al final | B23: 3
A24: Estructura de carpetas ordenada y proyecto compilable desde el repo | B24: 2
A25: 1.3 Buenas prácticas de código y reportes HTML | B25: =SUM(B26:B28) -> 8 | D25: =IF(SUM(D26:D28)=0,"",SUM(D26:D28))
A26: Arquitectura ordenada con POO (clases por entidad: Nave, Enemigo, Proyectil, Piloto, etc.) | B26: 3
A27: Nombres de variables/métodos claros y comentarios útiles | B27: 2
A28: Uso exclusivo de vectores y ciclos para pilotos e historial (sin colecciones dinámicas) | B28: 3
A29: 2. CONOCIMIENTO – QUÉ SE PROGRAMA | B29: =B30+B33+B38+B46+B50+B54+B58 -> 40 | D29: =IF(D30+D33+D38+D46+D50+D54+D58=0,"",D30+D33+D38+D46+D50+D54+D58) -> #VALUE!
A30: 2.1 Menú principal | B30: =SUM(B31:B32) -> 3 | D30: =IF(SUM(D31:D32)=0,"",SUM(D31:D32))
A31: Opciones Jugar, Crear Piloto, Top de Puntajes y Salir funcionan sin errores ni cuelgues | B31: 2
A32: Navegación correcta entre ventanas y regreso al menú al finalizar la partida | B32: 1
A33: 2.2 Gestión de pilotos y naves | B33: =SUM(B34:B37) -> 7 | D33: =IF(SUM(D34:D37)=0,"",SUM(D34:D37))
A34: Creación de piloto con validaciones (campos vacíos, nombres duplicados) | B34: 2
A35: Selección de piloto existente para jugar | B35: 1
A36: Selección de nave (Explorador / Caza Estelar / Acorazado) | B36: 1
A37: Tiempos de sleep() de movimiento y disparo según la nave (2 s / 1 s / 0.3 s) | B37: 3
A38: 2.3 Simulación de combate e hilos | B38: =SUM(B39:B45) -> 12 | D38: =IF(SUM(D39:D45)=0,"",SUM(D39:D45))
A39: Movimiento de la nave del jugador con teclado dentro de los límites de pantalla | B39: 1
A40: Enemigos y asteroides se generan en X máximo y se desplazan hacia X mínimo | B40: 2
A41: Cada proyectil del jugador es un hilo independiente que actualiza su posición (x, y) | B41: 3
A42: Cada enemigo/asteroide en pantalla es un hilo independiente | B42: 3
A43: Detección correcta de colisiones proyectil–enemigo (sin colisiones fantasma) | B43: 2
...

Sheet 202406816
A1: UNIVERSIDAD DE SAN CARLOS DE GUATEMALA
A2: FACULTAD DE INGENIERÍA
A3: ESCUELA DE CIENCIAS Y SISTEMAS
A4: Introducción a la Programación y Computación 1, Sección B
A5: Ing. William Estuardo Escobar Argueta
A6: Aux. Fernando José Vicente Velásquez
A8: Hoja de Calificación – Practica 2: Quetzal Space Defender - Side Scroller
A10: Fecha de calificación:
A11: Nombre del estudiante: | C11: =VLOOKUP(C12, Consolidado!$B$3:$C$26, 2, 0) -> #N/A
A12: Carné: | C12: 202406816 | E12: Evelyn Cardona
A14: Descripción de Ponderación | B14: Valor | C14: Observación | D14: Punteo
A15: 1. HABILIDADES – CÓMO SE PROGRAMA | B15: =B16+B21+B25 -> 25 | D15: =IF(D16+D21+D25=0,"",D16+D21+D25) -> 25
A16: 1.1 Documentación | B16: =SUM(B17:B20) -> 10 | D16: =IF(SUM(D17:D20)=0,"",SUM(D17:D20)) -> 10
A17: Manual técnico detallado completo y coherente con el código | B17: 3 | D17: 3
A18: Manual de usuario con capturas reales y guia para el usuario | B18: 3 | D18: 3
A19: Diagramas (flujo, módulos, matriz de ubicaciones) | B19: 2 | D19: 2
A20: Informe realizado con herramienta https://aicodedetector.org/ | B20: 2 | D20: 2
A21: 1.2 Repositorio GitHub | B21: =SUM(B22:B24) -> 7 | D21: =IF(SUM(D22:D24)=0,"",SUM(D22:D24)) -> 7
A22: Formato de nombre correcto y auxiliar agregado como colaborador | B22: 2 | D22: 2
A23: Commits progresivos, no concentrados al final | B23: 3 | D23: 3
A24: Estructura de carpetas ordenada y proyecto compilable desde el repo | B24: 2 | D24: 2
A25: 1.3 Buenas prácticas de código y reportes HTML | B25: =SUM(B26:B28) -> 8 | D25: =IF(SUM(D26:D28)=0,"",SUM(D26:D28)) -> 8
A26: Arquitectura ordenada con POO (clases por entidad: Nave, Enemigo, Proyectil, Piloto, etc.) | B26: 3 | D26: 3
A27: Nombres de variables/métodos claros y comentarios útiles | B27: 2 | D27: 2
A28: Uso exclusivo de vectores y ciclos para pilotos e historial (sin colecciones dinámicas) | B28: 3 | D28: 3
A29: 2. CONOCIMIENTO – QUÉ SE PROGRAMA | B29: =B30+B33+B38+B46+B50+B54+B58 -> 40 | D29: =IF(D30+D33+D38+D46+D50+D54+D58=0,"",D30+D33+D38+D46+D50+D54+D58) -> 38
A30: 2.1 Menú principal | B30: =SUM(B31:B32) -> 3 | D30: =IF(SUM(D31:D32)=0,"",SUM(D31:D32)) -> 3
A31: Opciones Jugar, Crear Piloto, Top de Puntajes y Salir funcionan sin errores ni cuelgues | B31: 2 | D31: 2
A32: Navegación correcta entre ventanas y regreso al menú al finalizar la partida | B32: 1 | D32: 1
A33: 2.2 Gestión de pilotos y naves | B33: =SUM(B34:B37) -> 7 | D33: =IF(SUM(D34:D37)=0,"",SUM(D34:D37)) -> 7
A34: Creación de piloto con validaciones (campos vacíos, nombres duplicados) | B34: 2 | D34: 2
A35: Selección de piloto existente para jugar | B35: 1 | D35: 1
A36: Selección de nave (Explorador / Caza Estelar / Acorazado) | B36: 1 | D36: 1
A37: Tiempos de sleep() de movimiento y disparo según la nave (2 s / 1 s / 0.3 s) | B37: 3 | D37: 3
A38: 2.3 Simulación de combate e hilos | B38: =SUM(B39:B45) -> 12 | D38: =IF(SUM(D39:D45)=0,"",SUM(D39:D45)) -> 12
A39: Movimiento de la nave del jugador con teclado dentro de los límites de pantalla | B39: 1 | D39: 1
A40: Enemigos y asteroides se generan en X máximo y se desplazan hacia X mínimo | B40: 2 | D40: 2
A41: Cada proyectil del jugador es un hilo independiente que actualiza su posición (x, y) | B41: 3 | D41: 3
A42: Cada enemigo/asteroide en pantalla es un hilo independiente | B42: 3 | D42: 3
A43: Detección correcta de colisiones proyectil–enemigo (sin colisiones fantasma) | B43: 2 | D43: 2
...

Sheet 202405048
A1: UNIVERSIDAD DE SAN CARLOS DE GUATEMALA
A2: FACULTAD DE INGENIERÍA
A3: ESCUELA DE CIENCIAS Y SISTEMAS
A4: Introducción a la Programación y Computación 1, Sección B
A5: Ing. William Estuardo Escobar Argueta
A6: Aux. Fernando José Vicente Velásquez
A8: Hoja de Calificación – Practica 2: Quetzal Space Defender - Side Scroller
A10: Fecha de calificación:
A11: Nombre del estudiante: | C11: =VLOOKUP(C12, Consolidado!$B$3:$C$26, 2, 0) -> #N/A | E11: Monika Cruz
A12: Carné: | C12: 202405048
A14: Descripción de Ponderación | B14: Valor | C14: Observación | D14: Punteo
A15: 1. HABILIDADES – CÓMO SE PROGRAMA | B15: =B16+B21+B25 -> 25 | D15: =IF(D16+D21+D25=0,"",D16+D21+D25) -> 23
A16: 1.1 Documentación | B16: =SUM(B17:B20) -> 10 | D16: =IF(SUM(D17:D20)=0,"",SUM(D17:D20)) -> 8
A17: Manual técnico detallado completo y coherente con el código | B17: 3 | D17: 3
A18: Manual de usuario con capturas reales y guia para el usuario | B18: 3 | D18: 3
A19: Diagramas (flujo, módulos, matriz de ubicaciones) | B19: 2 | D19: 2
A20: Informe realizado con herramienta https://aicodedetector.org/ | B20: 2 | D20: 0
A21: 1.2 Repositorio GitHub | B21: =SUM(B22:B24) -> 7 | D21: =IF(SUM(D22:D24)=0,"",SUM(D22:D24)) -> 7
A22: Formato de nombre correcto y auxiliar agregado como colaborador | B22: 2 | D22: 2
A23: Commits progresivos, no concentrados al final | B23: 3 | D23: 3
A24: Estructura de carpetas ordenada y proyecto compilable desde el repo | B24: 2 | D24: 2
A25: 1.3 Buenas prácticas de código y reportes HTML | B25: =SUM(B26:B28) -> 8 | D25: =IF(SUM(D26:D28)=0,"",SUM(D26:D28)) -> 8
A26: Arquitectura ordenada con POO (clases por entidad: Nave, Enemigo, Proyectil, Piloto, etc.) | B26: 3 | D26: 3
A27: Nombres de variables/métodos claros y comentarios útiles | B27: 2 | D27: 2
A28: Uso exclusivo de vectores y ciclos para pilotos e historial (sin colecciones dinámicas) | B28: 3 | D28: 3
A29: 2. CONOCIMIENTO – QUÉ SE PROGRAMA | B29: =B30+B33+B38+B46+B50+B54+B58 -> 40 | D29: =IF(D30+D33+D38+D46+D50+D54+D58=0,"",D30+D33+D38+D46+D50+D54+D58) -> 40
A30: 2.1 Menú principal | B30: =SUM(B31:B32) -> 3 | D30: =IF(SUM(D31:D32)=0,"",SUM(D31:D32)) -> 3
A31: Opciones Jugar, Crear Piloto, Top de Puntajes y Salir funcionan sin errores ni cuelgues | B31: 2 | D31: 2
A32: Navegación correcta entre ventanas y regreso al menú al finalizar la partida | B32: 1 | D32: 1
A33: 2.2 Gestión de pilotos y naves | B33: =SUM(B34:B37) -> 7 | D33: =IF(SUM(D34:D37)=0,"",SUM(D34:D37)) -> 7
A34: Creación de piloto con validaciones (campos vacíos, nombres duplicados) | B34: 2 | D34: 2
A35: Selección de piloto existente para jugar | B35: 1 | D35: 1
A36: Selección de nave (Explorador / Caza Estelar / Acorazado) | B36: 1 | D36: 1
A37: Tiempos de sleep() de movimiento y disparo según la nave (2 s / 1 s / 0.3 s) | B37: 3 | D37: 3
A38: 2.3 Simulación de combate e hilos | B38: =SUM(B39:B45) -> 12 | D38: =IF(SUM(D39:D45)=0,"",SUM(D39:D45)) -> 12
A39: Movimiento de la nave del jugador con teclado dentro de los límites de pantalla | B39: 1 | D39: 1
A40: Enemigos y asteroides se generan en X máximo y se desplazan hacia X mínimo | B40: 2 | D40: 2
A41: Cada proyectil del jugador es un hilo independiente que actualiza su posición (x, y) | B41: 3 | D41: 3
A42: Cada enemigo/asteroide en pantalla es un hilo independiente | B42: 3 | D42: 3
A43: Detección correcta de colisiones proyectil–enemigo (sin colisiones fantasma) | B43: 2 | D43: 2
...

Sheet 202404528
A1: UNIVERSIDAD DE SAN CARLOS DE GUATEMALA
A2: FACULTAD DE INGENIERÍA
A3: ESCUELA DE CIENCIAS Y SISTEMAS
A4: Introducción a la Programación y Computación 1, Sección B
A5: Ing. William Estuardo Escobar Argueta
A6: Aux. Fernando José Vicente Velásquez
A8: Hoja de Calificación – Practica 2: Quetzal Space Defender - Side Scroller
A10: Fecha de calificación:
A11: Nombre del estudiante: | C11: =VLOOKUP(C12, Consolidado!$B$3:$C$26, 2, 0) -> #N/A | E11: Melissa Pérez
A12: Carné: | C12: 202404528
A14: Descripción de Ponderación | B14: Valor | C14: Observación | D14: Punteo
A15: 1. HABILIDADES – CÓMO SE PROGRAMA | B15: =B16+B21+B25 -> 25 | D15: =IF(D16+D21+D25=0,"",D16+D21+D25) -> 21
A16: 1.1 Documentación | B16: =SUM(B17:B20) -> 10 | D16: =IF(SUM(D17:D20)=0,"",SUM(D17:D20)) -> 6
A17: Manual técnico detallado completo y coherente con el código | B17: 3 | D17: 3
A18: Manual de usuario con capturas reales y guia para el usuario | B18: 3 | D18: 1
A19: Diagramas (flujo, módulos, matriz de ubicaciones) | B19: 2 | D19: 2
A20: Informe realizado con herramienta https://aicodedetector.org/ | B20: 2 | D20: 0
A21: 1.2 Repositorio GitHub | B21: =SUM(B22:B24) -> 7 | D21: =IF(SUM(D22:D24)=0,"",SUM(D22:D24)) -> 7
A22: Formato de nombre correcto y auxiliar agregado como colaborador | B22: 2 | D22: 2
A23: Commits progresivos, no concentrados al final | B23: 3 | D23: 3
A24: Estructura de carpetas ordenada y proyecto compilable desde el repo | B24: 2 | D24: 2
A25: 1.3 Buenas prácticas de código y reportes HTML | B25: =SUM(B26:B28) -> 8 | D25: =IF(SUM(D26:D28)=0,"",SUM(D26:D28)) -> 8
A26: Arquitectura ordenada con POO (clases por entidad: Nave, Enemigo, Proyectil, Piloto, etc.) | B26: 3 | D26: 3
A27: Nombres de variables/métodos claros y comentarios útiles | B27: 2 | D27: 2
A28: Uso exclusivo de vectores y ciclos para pilotos e historial (sin colecciones dinámicas) | B28: 3 | D28: 3
A29: 2. CONOCIMIENTO – QUÉ SE PROGRAMA | B29: =B30+B33+B38+B46+B50+B54+B58 -> 40 | D29: =IF(D30+D33+D38+D46+D50+D54+D58=0,"",D30+D33+D38+D46+D50+D54+D58) -> 40
A30: 2.1 Menú principal | B30: =SUM(B31:B32) -> 3 | D30: =IF(SUM(D31:D32)=0,"",SUM(D31:D32)) -> 3
A31: Opciones Jugar, Crear Piloto, Top de Puntajes y Salir funcionan sin errores ni cuelgues | B31: 2 | D31: 2
A32: Navegación correcta entre ventanas y regreso al menú al finalizar la partida | B32: 1 | D32: 1
A33: 2.2 Gestión de pilotos y naves | B33: =SUM(B34:B37) -> 7 | D33: =IF(SUM(D34:D37)=0,"",SUM(D34:D37)) -> 7
A34: Creación de piloto con validaciones (campos vacíos, nombres duplicados) | B34: 2 | D34: 2
A35: Selección de piloto existente para jugar | B35: 1 | D35: 1
A36: Selección de nave (Explorador / Caza Estelar / Acorazado) | B36: 1 | D36: 1
A37: Tiempos de sleep() de movimiento y disparo según la nave (2 s / 1 s / 0.3 s) | B37: 3 | D37: 3
A38: 2.3 Simulación de combate e hilos | B38: =SUM(B39:B45) -> 12 | D38: =IF(SUM(D39:D45)=0,"",SUM(D39:D45)) -> 12
A39: Movimiento de la nave del jugador con teclado dentro de los límites de pantalla | B39: 1 | D39: 1
A40: Enemigos y asteroides se generan en X máximo y se desplazan hacia X mínimo | B40: 2 | D40: 2
A41: Cada proyectil del jugador es un hilo independiente que actualiza su posición (x, y) | B41: 3 | D41: 3
A42: Cada enemigo/asteroide en pantalla es un hilo independiente | B42: 3 | D42: 3
A43: Detección correcta de colisiones proyectil–enemigo (sin colisiones fantasma) | B43: 2 | D43: 2
...

Sheet 202505830
A1: UNIVERSIDAD DE SAN CARLOS DE GUATEMALA
A2: FACULTAD DE INGENIERÍA
A3: ESCUELA DE CIENCIAS Y SISTEMAS
A4: Introducción a la Programación y Computación 1, Sección B
A5: Ing. William Estuardo Escobar Argueta
A6: Aux. Fernando José Vicente Velásquez
A8: Hoja de Calificación – Practica 2: Quetzal Space Defender - Side Scroller
A10: Fecha de calificación:
A11: Nombre del estudiante: | C11: =VLOOKUP(C12, Consolidado!$B$3:$C$26, 2, 0) -> #N/A | E11: Naomi Axpuac
A12: Carné: | C12: 202505830
A14: Descripción de Ponderación | B14: Valor | C14: Observación | D14: Punteo
A15: 1. HABILIDADES – CÓMO SE PROGRAMA | B15: =B16+B21+B25 -> 25 | D15: =IF(D16+D21+D25=0,"",D16+D21+D25) -> 21
A16: 1.1 Documentación | B16: =SUM(B17:B20) -> 10 | D16: =IF(SUM(D17:D20)=0,"",SUM(D17:D20)) -> 6
A17: Manual técnico detallado completo y coherente con el código | B17: 3 | D17: 3
A18: Manual de usuario con capturas reales y guia para el usuario | B18: 3 | D18: 3
A19: Diagramas (flujo, módulos, matriz de ubicaciones) | B19: 2 | D19: 0
A20: Informe realizado con herramienta https://aicodedetector.org/ | B20: 2 | D20: 0
A21: 1.2 Repositorio GitHub | B21: =SUM(B22:B24) -> 7 | D21: =IF(SUM(D22:D24)=0,"",SUM(D22:D24)) -> 7
A22: Formato de nombre correcto y auxiliar agregado como colaborador | B22: 2 | D22: 2
A23: Commits progresivos, no concentrados al final | B23: 3 | D23: 3
A24: Estructura de carpetas ordenada y proyecto compilable desde el repo | B24: 2 | D24: 2
A25: 1.3 Buenas prácticas de código y reportes HTML | B25: =SUM(B26:B28) -> 8 | D25: =IF(SUM(D26:D28)=0,"",SUM(D26:D28)) -> 8
A26: Arquitectura ordenada con POO (clases por entidad: Nave, Enemigo, Proyectil, Piloto, etc.) | B26: 3 | D26: 3
A27: Nombres de variables/métodos claros y comentarios útiles | B27: 2 | D27: 2
A28: Uso exclusivo de vectores y ciclos para pilotos e historial (sin colecciones dinámicas) | B28: 3 | D28: 3
A29: 2. CONOCIMIENTO – QUÉ SE PROGRAMA | B29: =B30+B33+B38+B46+B50+B54+B58 -> 40 | D29: =IF(D30+D33+D38+D46+D50+D54+D58=0,"",D30+D33+D38+D46+D50+D54+D58) -> 40
A30: 2.1 Menú principal | B30: =SUM(B31:B32) -> 3 | D30: =IF(SUM(D31:D32)=0,"",SUM(D31:D32)) -> 3
A31: Opciones Jugar, Crear Piloto, Top de Puntajes y Salir funcionan sin errores ni cuelgues | B31: 2 | D31: 2
A32: Navegación correcta entre ventanas y regreso al menú al finalizar la partida | B32: 1 | D32: 1
A33: 2.2 Gestión de pilotos y naves | B33: =SUM(B34:B37) -> 7 | D33: =IF(SUM(D34:D37)=0,"",SUM(D34:D37)) -> 7
A34: Creación de piloto con validaciones (campos vacíos, nombres duplicados) | B34: 2 | D34: 2
A35: Selección de piloto existente para jugar | B35: 1 | D35: 1
A36: Selección de nave (Explorador / Caza Estelar / Acorazado) | B36: 1 | D36: 1
A37: Tiempos de sleep() de movimiento y disparo según la nave (2 s / 1 s / 0.3 s) | B37: 3 | D37: 3
A38: 2.3 Simulación de combate e hilos | B38: =SUM(B39:B45) -> 12 | D38: =IF(SUM(D39:D45)=0,"",SUM(D39:D45)) -> 12
A39: Movimiento de la nave del jugador con teclado dentro de los límites de pantalla | B39: 1 | D39: 1
A40: Enemigos y asteroides se generan en X máximo y se desplazan hacia X mínimo | B40: 2 | D40: 2
A41: Cada proyectil del jugador es un hilo independiente que actualiza su posición (x, y) | B41: 3 | D41: 3
A42: Cada enemigo/asteroide en pantalla es un hilo independiente | B42: 3 | D42: 3
A43: Detección correcta de colisiones proyectil–enemigo (sin colisiones fantasma) | B43: 2 | D43: 2
...

Sheet 202501625
A1: UNIVERSIDAD DE SAN CARLOS DE GUATEMALA
A2: FACULTAD DE INGENIERÍA
A3: ESCUELA DE CIENCIAS Y SISTEMAS
A4: Introducción a la Programación y Computación 1, Sección B
A5: Ing. William Estuardo Escobar Argueta
A6: Aux. Fernando José Vicente Velásquez
A8: Hoja de Calificación – Practica 2: Quetzal Space Defender - Side Scroller
A10: Fecha de calificación:
A11: Nombre del estudiante: | C11: =VLOOKUP(C12, Consolidado!$B$3:$C$26, 2, 0) -> #N/A | E11: Chung Kim
A12: Carné: | C12: 202501625
A14: Descripción de Ponderación | B14: Valor | C14: Observación | D14: Punteo
A15: 1. HABILIDADES – CÓMO SE PROGRAMA | B15: =B16+B21+B25 -> 25 | D15: =IF(D16+D21+D25=0,"",D16+D21+D25) -> 21
A16: 1.1 Documentación | B16: =SUM(B17:B20) -> 10 | D16: =IF(SUM(D17:D20)=0,"",SUM(D17:D20)) -> 6
A17: Manual técnico detallado completo y coherente con el código | B17: 3 | D17: 3
A18: Manual de usuario con capturas reales y guia para el usuario | B18: 3 | D18: 3
A19: Diagramas (flujo, módulos, matriz de ubicaciones) | B19: 2 | D19: 0
A20: Informe realizado con herramienta https://aicodedetector.org/ | B20: 2 | D20: 0
A21: 1.2 Repositorio GitHub | B21: =SUM(B22:B24) -> 7 | D21: =IF(SUM(D22:D24)=0,"",SUM(D22:D24)) -> 7
A22: Formato de nombre correcto y auxiliar agregado como colaborador | B22: 2 | D22: 2
A23: Commits progresivos, no concentrados al final | B23: 3 | D23: 3
A24: Estructura de carpetas ordenada y proyecto compilable desde el repo | B24: 2 | D24: 2
A25: 1.3 Buenas prácticas de código y reportes HTML | B25: =SUM(B26:B28) -> 8 | D25: =IF(SUM(D26:D28)=0,"",SUM(D26:D28)) -> 8
A26: Arquitectura ordenada con POO (clases por entidad: Nave, Enemigo, Proyectil, Piloto, etc.) | B26: 3 | D26: 3
A27: Nombres de variables/métodos claros y comentarios útiles | B27: 2 | D27: 2
A28: Uso exclusivo de vectores y ciclos para pilotos e historial (sin colecciones dinámicas) | B28: 3 | D28: 3
A29: 2. CONOCIMIENTO – QUÉ SE PROGRAMA | B29: =B30+B33+B38+B46+B50+B54+B58 -> 40 | D29: =IF(D30+D33+D38+D46+D50+D54+D58=0,"",D30+D33+D38+D46+D50+D54+D58) -> 40
A30: 2.1 Menú principal | B30: =SUM(B31:B32) -> 3 | D30: =IF(SUM(D31:D32)=0,"",SUM(D31:D32)) -> 3
A31: Opciones Jugar, Crear Piloto, Top de Puntajes y Salir funcionan sin errores ni cuelgues | B31: 2 | D31: 2
A32: Navegación correcta entre ventanas y regreso al menú al finalizar la partida | B32: 1 | D32: 1
A33: 2.2 Gestión de pilotos y naves | B33: =SUM(B34:B37) -> 7 | D33: =IF(SUM(D34:D37)=0,"",SUM(D34:D37)) -> 7
A34: Creación de piloto con validaciones (campos vacíos, nombres duplicados) | B34: 2 | D34: 2
A35: Selección de piloto existente para jugar | B35: 1 | D35: 1
A36: Selección de nave (Explorador / Caza Estelar / Acorazado) | B36: 1 | D36: 1
A37: Tiempos de sleep() de movimiento y disparo según la nave (2 s / 1 s / 0.3 s) | B37: 3 | D37: 3
A38: 2.3 Simulación de combate e hilos | B38: =SUM(B39:B45) -> 12 | D38: =IF(SUM(D39:D45)=0,"",SUM(D39:D45)) -> 12
A39: Movimiento de la nave del jugador con teclado dentro de los límites de pantalla | B39: 1 | D39: 1
A40: Enemigos y asteroides se generan en X máximo y se desplazan hacia X mínimo | B40: 2 | D40: 2
A41: Cada proyectil del jugador es un hilo independiente que actualiza su posición (x, y) | B41: 3 | D41: 3
A42: Cada enemigo/asteroide en pantalla es un hilo independiente | B42: 3 | D42: 3
A43: Detección correcta de colisiones proyectil–enemigo (sin colisiones fantasma) | B43: 2 | D43: 2
...

Sheet 202201204
A1: UNIVERSIDAD DE SAN CARLOS DE GUATEMALA
A2: FACULTAD DE INGENIERÍA
A3: ESCUELA DE CIENCIAS Y SISTEMAS
A4: Introducción a la Programación y Computación 1, Sección B
A5: Ing. William Estuardo Escobar Argueta
A6: Aux. Fernando José Vicente Velásquez
A8: Hoja de Calificación – Practica 2: Quetzal Space Defender - Side Scroller
A10: Fecha de calificación:
A11: Nombre del estudiante: | C11: =VLOOKUP(C12, Consolidado!$B$3:$C$26, 2, 0) -> #N/A | E11: Brayan Martinez
A12: Carné: | C12: 202201204
A14: Descripción de Ponderación | B14: Valor | C14: Observación | D14: Punteo
A15: 1. HABILIDADES – CÓMO SE PROGRAMA | B15: =B16+B21+B25 -> 25 | D15: =IF(D16+D21+D25=0,"",D16+D21+D25) -> 23
A16: 1.1 Documentación | B16: =SUM(B17:B20) -> 10 | D16: =IF(SUM(D17:D20)=0,"",SUM(D17:D20)) -> 9
A17: Manual técnico detallado completo y coherente con el código | B17: 3 | D17: 3
A18: Manual de usuario con capturas reales y guia para el usuario | B18: 3 | D18: 2
A19: Diagramas (flujo, módulos, matriz de ubicaciones) | B19: 2 | D19: 2
A20: Informe realizado con herramienta https://aicodedetector.org/ | B20: 2 | D20: 2
A21: 1.2 Repositorio GitHub | B21: =SUM(B22:B24) -> 7 | D21: =IF(SUM(D22:D24)=0,"",SUM(D22:D24)) -> 7
A22: Formato de nombre correcto y auxiliar agregado como colaborador | B22: 2 | D22: 2
A23: Commits progresivos, no concentrados al final | B23: 3 | D23: 3
A24: Estructura de carpetas ordenada y proyecto compilable desde el repo | B24: 2 | D24: 2
A25: 1.3 Buenas prácticas de código y reportes HTML | B25: =SUM(B26:B28) -> 8 | D25: =IF(SUM(D26:D28)=0,"",SUM(D26:D28)) -> 7
A26: Arquitectura ordenada con POO (clases por entidad: Nave, Enemigo, Proyectil, Piloto, etc.) | B26: 3 | D26: 3
A27: Nombres de variables/métodos claros y comentarios útiles | B27: 2 | D27: 2
A28: Uso exclusivo de vectores y ciclos para pilotos e historial (sin colecciones dinámicas) | B28: 3 | D28: 2
A29: 2. CONOCIMIENTO – QUÉ SE PROGRAMA | B29: =B30+B33+B38+B46+B50+B54+B58 -> 40 | D29: =IF(D30+D33+D38+D46+D50+D54+D58=0,"",D30+D33+D38+D46+D50+D54+D58) -> 34
A30: 2.1 Menú principal | B30: =SUM(B31:B32) -> 3 | D30: =IF(SUM(D31:D32)=0,"",SUM(D31:D32)) -> 3
A31: Opciones Jugar, Crear Piloto, Top de Puntajes y Salir funcionan sin errores ni cuelgues | B31: 2 | D31: 2
A32: Navegación correcta entre ventanas y regreso al menú al finalizar la partida | B32: 1 | D32: 1
A33: 2.2 Gestión de pilotos y naves | B33: =SUM(B34:B37) -> 7 | D33: =IF(SUM(D34:D37)=0,"",SUM(D34:D37)) -> 7
A34: Creación de piloto con validaciones (campos vacíos, nombres duplicados) | B34: 2 | D34: 2
A35: Selección de piloto existente para jugar | B35: 1 | D35: 1
A36: Selección de nave (Explorador / Caza Estelar / Acorazado) | B36: 1 | D36: 1
A37: Tiempos de sleep() de movimiento y disparo según la nave (2 s / 1 s / 0.3 s) | B37: 3 | D37: 3
A38: 2.3 Simulación de combate e hilos | B38: =SUM(B39:B45) -> 12 | D38: =IF(SUM(D39:D45)=0,"",SUM(D39:D45)) -> 12
A39: Movimiento de la nave del jugador con teclado dentro de los límites de pantalla | B39: 1 | D39: 1
A40: Enemigos y asteroides se generan en X máximo y se desplazan hacia X mínimo | B40: 2 | D40: 2
A41: Cada proyectil del jugador es un hilo independiente que actualiza su posición (x, y) | B41: 3 | D41: 3
A42: Cada enemigo/asteroide en pantalla es un hilo independiente | B42: 3 | D42: 3
A43: Detección correcta de colisiones proyectil–enemigo (sin colisiones fantasma) | B43: 2 | D43: 2
...

Sheet 202507586
A1: UNIVERSIDAD DE SAN CARLOS DE GUATEMALA
A2: FACULTAD DE INGENIERÍA
A3: ESCUELA DE CIENCIAS Y SISTEMAS
A4: Introducción a la Programación y Computación 1, Sección B
A5: Ing. William Estuardo Escobar Argueta
A6: Aux. Fernando José Vicente Velásquez
A8: Hoja de Calificación – Practica 2: Quetzal Space Defender - Side Scroller
A10: Fecha de calificación:
A11: Nombre del estudiante: | C11: =VLOOKUP(C12, Consolidado!$B$3:$C$26, 2, 0) -> #N/A | E11: Kevin Apén
A12: Carné: | C12: 202507586
A14: Descripción de Ponderación | B14: Valor | C14: Observación | D14: Punteo
A15: 1. HABILIDADES – CÓMO SE PROGRAMA | B15: =B16+B21+B25 -> 25 | D15: =IF(D16+D21+D25=0,"",D16+D21+D25) -> 23
A16: 1.1 Documentación | B16: =SUM(B17:B20) -> 10 | D16: =IF(SUM(D17:D20)=0,"",SUM(D17:D20)) -> 8
A17: Manual técnico detallado completo y coherente con el código | B17: 3 | D17: 3
A18: Manual de usuario con capturas reales y guia para el usuario | B18: 3 | D18: 3
A19: Diagramas (flujo, módulos, matriz de ubicaciones) | B19: 2 | D19: 2
A20: Informe realizado con herramienta https://aicodedetector.org/ | B20: 2 | D20: 0
A21: 1.2 Repositorio GitHub | B21: =SUM(B22:B24) -> 7 | D21: =IF(SUM(D22:D24)=0,"",SUM(D22:D24)) -> 7
A22: Formato de nombre correcto y auxiliar agregado como colaborador | B22: 2 | D22: 2
A23: Commits progresivos, no concentrados al final | B23: 3 | D23: 3
A24: Estructura de carpetas ordenada y proyecto compilable desde el repo | B24: 2 | D24: 2
A25: 1.3 Buenas prácticas de código y reportes HTML | B25: =SUM(B26:B28) -> 8 | D25: =IF(SUM(D26:D28)=0,"",SUM(D26:D28)) -> 8
A26: Arquitectura ordenada con POO (clases por entidad: Nave, Enemigo, Proyectil, Piloto, etc.) | B26: 3 | D26: 3
A27: Nombres de variables/métodos claros y comentarios útiles | B27: 2 | D27: 2
A28: Uso exclusivo de vectores y ciclos para pilotos e historial (sin colecciones dinámicas) | B28: 3 | D28: 3
A29: 2. CONOCIMIENTO – QUÉ SE PROGRAMA | B29: =B30+B33+B38+B46+B50+B54+B58 -> 40 | D29: =IF(D30+D33+D38+D46+D50+D54+D58=0,"",D30+D33+D38+D46+D50+D54+D58) -> #VALUE!
A30: 2.1 Menú principal | B30: =SUM(B31:B32) -> 3 | D30: =IF(SUM(D31:D32)=0,"",SUM(D31:D32)) -> 3
A31: Opciones Jugar, Crear Piloto, Top de Puntajes y Salir funcionan sin errores ni cuelgues | B31: 2 | D31: 2
A32: Navegación correcta entre ventanas y regreso al menú al finalizar la partida | B32: 1 | D32: 1
A33: 2.2 Gestión de pilotos y naves | B33: =SUM(B34:B37) -> 7 | D33: =IF(SUM(D34:D37)=0,"",SUM(D34:D37)) -> 7
A34: Creación de piloto con validaciones (campos vacíos, nombres duplicados) | B34: 2 | D34: 2
A35: Selección de piloto existente para jugar | B35: 1 | D35: 1
A36: Selección de nave (Explorador / Caza Estelar / Acorazado) | B36: 1 | D36: 1
A37: Tiempos de sleep() de movimiento y disparo según la nave (2 s / 1 s / 0.3 s) | B37: 3 | D37: 3
A38: 2.3 Simulación de combate e hilos | B38: =SUM(B39:B45) -> 12 | D38: =IF(SUM(D39:D45)=0,"",SUM(D39:D45)) -> 12
A39: Movimiento de la nave del jugador con teclado dentro de los límites de pantalla | B39: 1 | D39: 1
A40: Enemigos y asteroides se generan en X máximo y se desplazan hacia X mínimo | B40: 2 | D40: 2
A41: Cada proyectil del jugador es un hilo independiente que actualiza su posición (x, y) | B41: 3 | D41: 3
A42: Cada enemigo/asteroide en pantalla es un hilo independiente | B42: 3 | D42: 3
A43: Detección correcta de colisiones proyectil–enemigo (sin colisiones fantasma) | B43: 2 | D43: 2
...

Sheet 202501349
A1: UNIVERSIDAD DE SAN CARLOS DE GUATEMALA
A2: FACULTAD DE INGENIERÍA
A3: ESCUELA DE CIENCIAS Y SISTEMAS
A4: Introducción a la Programación y Computación 1, Sección B
A5: Ing. William Estuardo Escobar Argueta
A6: Aux. Fernando José Vicente Velásquez
A8: Hoja de Calificación – Practica 2: Quetzal Space Defender - Side Scroller
A10: Fecha de calificación:
A11: Nombre del estudiante: | C11: =VLOOKUP(C12, Consolidado!$B$3:$C$26, 2, 0) -> #N/A | E11: Diego Gómez
A12: Carné: | E12: 202501349
A14: Descripción de Ponderación | B14: Valor | C14: Observación | D14: Punteo
A15: 1. HABILIDADES – CÓMO SE PROGRAMA | B15: =B16+B21+B25 -> 25 | D15: =IF(D16+D21+D25=0,"",D16+D21+D25) -> 23
A16: 1.1 Documentación | B16: =SUM(B17:B20) -> 10 | D16: =IF(SUM(D17:D20)=0,"",SUM(D17:D20)) -> 8
A17: Manual técnico detallado completo y coherente con el código | B17: 3 | D17: 3
A18: Manual de usuario con capturas reales y guia para el usuario | B18: 3 | D18: 3
A19: Diagramas (flujo, módulos, matriz de ubicaciones) | B19: 2 | D19: 2
A20: Informe realizado con herramienta https://aicodedetector.org/ | B20: 2 | D20: 0
A21: 1.2 Repositorio GitHub | B21: =SUM(B22:B24) -> 7 | D21: =IF(SUM(D22:D24)=0,"",SUM(D22:D24)) -> 7
A22: Formato de nombre correcto y auxiliar agregado como colaborador | B22: 2 | D22: 2
A23: Commits progresivos, no concentrados al final | B23: 3 | D23: 3
A24: Estructura de carpetas ordenada y proyecto compilable desde el repo | B24: 2 | D24: 2
A25: 1.3 Buenas prácticas de código y reportes HTML | B25: =SUM(B26:B28) -> 8 | D25: =IF(SUM(D26:D28)=0,"",SUM(D26:D28)) -> 8
A26: Arquitectura ordenada con POO (clases por entidad: Nave, Enemigo, Proyectil, Piloto, etc.) | B26: 3 | D26: 3
A27: Nombres de variables/métodos claros y comentarios útiles | B27: 2 | D27: 2
A28: Uso exclusivo de vectores y ciclos para pilotos e historial (sin colecciones dinámicas) | B28: 3 | D28: 3
A29: 2. CONOCIMIENTO – QUÉ SE PROGRAMA | B29: =B30+B33+B38+B46+B50+B54+B58 -> 40 | D29: =IF(D30+D33+D38+D46+D50+D54+D58=0,"",D30+D33+D38+D46+D50+D54+D58) -> 40
A30: 2.1 Menú principal | B30: =SUM(B31:B32) -> 3 | D30: =IF(SUM(D31:D32)=0,"",SUM(D31:D32)) -> 3
A31: Opciones Jugar, Crear Piloto, Top de Puntajes y Salir funcionan sin errores ni cuelgues | B31: 2 | D31: 2
A32: Navegación correcta entre ventanas y regreso al menú al finalizar la partida | B32: 1 | D32: 1
A33: 2.2 Gestión de pilotos y naves | B33: =SUM(B34:B37) -> 7 | D33: =IF(SUM(D34:D37)=0,"",SUM(D34:D37)) -> 7
A34: Creación de piloto con validaciones (campos vacíos, nombres duplicados) | B34: 2 | D34: 2
A35: Selección de piloto existente para jugar | B35: 1 | D35: 1
A36: Selección de nave (Explorador / Caza Estelar / Acorazado) | B36: 1 | D36: 1
A37: Tiempos de sleep() de movimiento y disparo según la nave (2 s / 1 s / 0.3 s) | B37: 3 | D37: 3
A38: 2.3 Simulación de combate e hilos | B38: =SUM(B39:B45) -> 12 | D38: =IF(SUM(D39:D45)=0,"",SUM(D39:D45)) -> 12
A39: Movimiento de la nave del jugador con teclado dentro de los límites de pantalla | B39: 1 | D39: 1
A40: Enemigos y asteroides se generan en X máximo y se desplazan hacia X mínimo | B40: 2 | D40: 2
A41: Cada proyectil del jugador es un hilo independiente que actualiza su posición (x, y) | B41: 3 | D41: 3
A42: Cada enemigo/asteroide en pantalla es un hilo independiente | B42: 3 | D42: 3
A43: Detección correcta de colisiones proyectil–enemigo (sin colisiones fantasma) | B43: 2 | D43: 2
...

Sheet 202407699
A1: UNIVERSIDAD DE SAN CARLOS DE GUATEMALA
A2: FACULTAD DE INGENIERÍA
A3: ESCUELA DE CIENCIAS Y SISTEMAS
A4: Introducción a la Programación y Computación 1, Sección B
A5: Ing. William Estuardo Escobar Argueta
A6: Aux. Fernando José Vicente Velásquez
A8: Hoja de Calificación – Practica 2: Quetzal Space Defender - Side Scroller
A10: Fecha de calificación:
A11: Nombre del estudiante: | C11: =VLOOKUP(C12, Consolidado!$B$3:$C$26, 2, 0) -> #N/A | E11: Kevin Mendoza
A12: Carné: | C12: 202407699
A14: Descripción de Ponderación | B14: Valor | C14: Observación | D14: Punteo
A15: 1. HABILIDADES – CÓMO SE PROGRAMA | B15: =B16+B21+B25 -> 25 | D15: =IF(D16+D21+D25=0,"",D16+D21+D25) -> 18
A16: 1.1 Documentación | B16: =SUM(B17:B20) -> 10 | D16: =IF(SUM(D17:D20)=0,"",SUM(D17:D20)) -> 3
A17: Manual técnico detallado completo y coherente con el código | B17: 3 | D17: 1
A18: Manual de usuario con capturas reales y guia para el usuario | B18: 3 | D18: 2
A19: Diagramas (flujo, módulos, matriz de ubicaciones) | B19: 2 | D19: 0
A20: Informe realizado con herramienta https://aicodedetector.org/ | B20: 2 | D20: 0
A21: 1.2 Repositorio GitHub | B21: =SUM(B22:B24) -> 7 | D21: =IF(SUM(D22:D24)=0,"",SUM(D22:D24)) -> 7
A22: Formato de nombre correcto y auxiliar agregado como colaborador | B22: 2 | D22: 2
A23: Commits progresivos, no concentrados al final | B23: 3 | D23: 3
A24: Estructura de carpetas ordenada y proyecto compilable desde el repo | B24: 2 | D24: 2
A25: 1.3 Buenas prácticas de código y reportes HTML | B25: =SUM(B26:B28) -> 8 | D25: =IF(SUM(D26:D28)=0,"",SUM(D26:D28)) -> 8
A26: Arquitectura ordenada con POO (clases por entidad: Nave, Enemigo, Proyectil, Piloto, etc.) | B26: 3 | D26: 3
A27: Nombres de variables/métodos claros y comentarios útiles | B27: 2 | D27: 2
A28: Uso exclusivo de vectores y ciclos para pilotos e historial (sin colecciones dinámicas) | B28: 3 | D28: 3
A29: 2. CONOCIMIENTO – QUÉ SE PROGRAMA | B29: =B30+B33+B38+B46+B50+B54+B58 -> 40 | D29: =IF(D30+D33+D38+D46+D50+D54+D58=0,"",D30+D33+D38+D46+D50+D54+D58) -> 40
A30: 2.1 Menú principal | B30: =SUM(B31:B32) -> 3 | D30: =IF(SUM(D31:D32)=0,"",SUM(D31:D32)) -> 3
A31: Opciones Jugar, Crear Piloto, Top de Puntajes y Salir funcionan sin errores ni cuelgues | B31: 2 | D31: 2
A32: Navegación correcta entre ventanas y regreso al menú al finalizar la partida | B32: 1 | D32: 1
A33: 2.2 Gestión de pilotos y naves | B33: =SUM(B34:B37) -> 7 | D33: =IF(SUM(D34:D37)=0,"",SUM(D34:D37)) -> 7
A34: Creación de piloto con validaciones (campos vacíos, nombres duplicados) | B34: 2 | D34: 2
A35: Selección de piloto existente para jugar | B35: 1 | D35: 1
A36: Selección de nave (Explorador / Caza Estelar / Acorazado) | B36: 1 | D36: 1
A37: Tiempos de sleep() de movimiento y disparo según la nave (2 s / 1 s / 0.3 s) | B37: 3 | D37: 3
A38: 2.3 Simulación de combate e hilos | B38: =SUM(B39:B45) -> 12 | D38: =IF(SUM(D39:D45)=0,"",SUM(D39:D45)) -> 12
A39: Movimiento de la nave del jugador con teclado dentro de los límites de pantalla | B39: 1 | D39: 1
A40: Enemigos y asteroides se generan en X máximo y se desplazan hacia X mínimo | B40: 2 | D40: 2
A41: Cada proyectil del jugador es un hilo independiente que actualiza su posición (x, y) | B41: 3 | D41: 3
A42: Cada enemigo/asteroide en pantalla es un hilo independiente | B42: 3 | D42: 3
A43: Detección correcta de colisiones proyectil–enemigo (sin colisiones fantasma) | B43: 2 | D43: 2
...

Sheet 202403338
A1: UNIVERSIDAD DE SAN CARLOS DE GUATEMALA
A2: FACULTAD DE INGENIERÍA
A3: ESCUELA DE CIENCIAS Y SISTEMAS
A4: Introducción a la Programación y Computación 1, Sección B
A5: Ing. William Estuardo Escobar Argueta
A6: Aux. Fernando José Vicente Velásquez
A8: Hoja de Calificación – Practica 2: Quetzal Space Defender - Side Scroller
A10: Fecha de calificación:
A11: Nombre del estudiante: | C11: =VLOOKUP(C12, Consolidado!$B$3:$C$26, 2, 0) -> #N/A | E11: Andy Raí
A12: Carné: | C12: 202403338
A14: Descripción de Ponderación | B14: Valor | C14: Observación | D14: Punteo
A15: 1. HABILIDADES – CÓMO SE PROGRAMA | B15: =B16+B21+B25 -> 25 | D15: =IF(D16+D21+D25=0,"",D16+D21+D25) -> 23
A16: 1.1 Documentación | B16: =SUM(B17:B20) -> 10 | D16: =IF(SUM(D17:D20)=0,"",SUM(D17:D20)) -> 8
A17: Manual técnico detallado completo y coherente con el código | B17: 3 | D17: 3
A18: Manual de usuario con capturas reales y guia para el usuario | B18: 3 | D18: 3
A19: Diagramas (flujo, módulos, matriz de ubicaciones) | B19: 2 | D19: 2
A20: Informe realizado con herramienta https://aicodedetector.org/ | B20: 2 | D20: 0
A21: 1.2 Repositorio GitHub | B21: =SUM(B22:B24) -> 7 | D21: =IF(SUM(D22:D24)=0,"",SUM(D22:D24)) -> 7
A22: Formato de nombre correcto y auxiliar agregado como colaborador | B22: 2 | D22: 2
A23: Commits progresivos, no concentrados al final | B23: 3 | D23: 3
A24: Estructura de carpetas ordenada y proyecto compilable desde el repo | B24: 2 | D24: 2
A25: 1.3 Buenas prácticas de código y reportes HTML | B25: =SUM(B26:B28) -> 8 | D25: =IF(SUM(D26:D28)=0,"",SUM(D26:D28)) -> 8
A26: Arquitectura ordenada con POO (clases por entidad: Nave, Enemigo, Proyectil, Piloto, etc.) | B26: 3 | D26: 3
A27: Nombres de variables/métodos claros y comentarios útiles | B27: 2 | D27: 2
A28: Uso exclusivo de vectores y ciclos para pilotos e historial (sin colecciones dinámicas) | B28: 3 | D28: 3
A29: 2. CONOCIMIENTO – QUÉ SE PROGRAMA | B29: =B30+B33+B38+B46+B50+B54+B58 -> 40 | D29: =IF(D30+D33+D38+D46+D50+D54+D58=0,"",D30+D33+D38+D46+D50+D54+D58) -> 38.5
A30: 2.1 Menú principal | B30: =SUM(B31:B32) -> 3 | D30: =IF(SUM(D31:D32)=0,"",SUM(D31:D32)) -> 3
A31: Opciones Jugar, Crear Piloto, Top de Puntajes y Salir funcionan sin errores ni cuelgues | B31: 2 | D31: 2
A32: Navegación correcta entre ventanas y regreso al menú al finalizar la partida | B32: 1 | D32: 1
A33: 2.2 Gestión de pilotos y naves | B33: =SUM(B34:B37) -> 7 | D33: =IF(SUM(D34:D37)=0,"",SUM(D34:D37)) -> 7
A34: Creación de piloto con validaciones (campos vacíos, nombres duplicados) | B34: 2 | D34: 2
A35: Selección de piloto existente para jugar | B35: 1 | D35: 1
A36: Selección de nave (Explorador / Caza Estelar / Acorazado) | B36: 1 | D36: 1
A37: Tiempos de sleep() de movimiento y disparo según la nave (2 s / 1 s / 0.3 s) | B37: 3 | D37: 3
A38: 2.3 Simulación de combate e hilos | B38: =SUM(B39:B45) -> 12 | D38: =IF(SUM(D39:D45)=0,"",SUM(D39:D45)) -> 12
A39: Movimiento de la nave del jugador con teclado dentro de los límites de pantalla | B39: 1 | D39: 1
A40: Enemigos y asteroides se generan en X máximo y se desplazan hacia X mínimo | B40: 2 | D40: 2
A41: Cada proyectil del jugador es un hilo independiente que actualiza su posición (x, y) | B41: 3 | D41: 3
A42: Cada enemigo/asteroide en pantalla es un hilo independiente | B42: 3 | D42: 3
A43: Detección correcta de colisiones proyectil–enemigo (sin colisiones fantasma) | B43: 2 | D43: 2
...

Sheet 202400066
A1: UNIVERSIDAD DE SAN CARLOS DE GUATEMALA
A2: FACULTAD DE INGENIERÍA
A3: ESCUELA DE CIENCIAS Y SISTEMAS
A4: Introducción a la Programación y Computación 1, Sección B
A5: Ing. William Estuardo Escobar Argueta
A6: Aux. Fernando José Vicente Velásquez
A8: Hoja de Calificación – Practica 2: Quetzal Space Defender - Side Scroller
A10: Fecha de calificación:
A11: Nombre del estudiante: | C11: =VLOOKUP(C12, Consolidado!$B$3:$C$26, 2, 0) -> #N/A | E11: Diego Alvarado
A12: Carné: | C12: 202400066
A14: Descripción de Ponderación | B14: Valor | C14: Observación | D14: Punteo
A15: 1. HABILIDADES – CÓMO SE PROGRAMA | B15: =B16+B21+B25 -> 25 | D15: =IF(D16+D21+D25=0,"",D16+D21+D25) -> 25
A16: 1.1 Documentación | B16: =SUM(B17:B20) -> 10 | D16: =IF(SUM(D17:D20)=0,"",SUM(D17:D20)) -> 10
A17: Manual técnico detallado completo y coherente con el código | B17: 3 | D17: 3
A18: Manual de usuario con capturas reales y guia para el usuario | B18: 3 | D18: 3
A19: Diagramas (flujo, módulos, matriz de ubicaciones) | B19: 2 | D19: 2
A20: Informe realizado con herramienta https://aicodedetector.org/ | B20: 2 | D20: 2
A21: 1.2 Repositorio GitHub | B21: =SUM(B22:B24) -> 7 | D21: =IF(SUM(D22:D24)=0,"",SUM(D22:D24)) -> 7
A22: Formato de nombre correcto y auxiliar agregado como colaborador | B22: 2 | D22: 2
A23: Commits progresivos, no concentrados al final | B23: 3 | D23: 3
A24: Estructura de carpetas ordenada y proyecto compilable desde el repo | B24: 2 | D24: 2
A25: 1.3 Buenas prácticas de código y reportes HTML | B25: =SUM(B26:B28) -> 8 | D25: =IF(SUM(D26:D28)=0,"",SUM(D26:D28)) -> 8
A26: Arquitectura ordenada con POO (clases por entidad: Nave, Enemigo, Proyectil, Piloto, etc.) | B26: 3 | D26: 3
A27: Nombres de variables/métodos claros y comentarios útiles | B27: 2 | D27: 2
A28: Uso exclusivo de vectores y ciclos para pilotos e historial (sin colecciones dinámicas) | B28: 3 | D28: 3
A29: 2. CONOCIMIENTO – QUÉ SE PROGRAMA | B29: =B30+B33+B38+B46+B50+B54+B58 -> 40 | D29: =IF(D30+D33+D38+D46+D50+D54+D58=0,"",D30+D33+D38+D46+D50+D54+D58) -> 40
A30: 2.1 Menú principal | B30: =SUM(B31:B32) -> 3 | D30: =IF(SUM(D31:D32)=0,"",SUM(D31:D32)) -> 3
A31: Opciones Jugar, Crear Piloto, Top de Puntajes y Salir funcionan sin errores ni cuelgues | B31: 2 | D31: 2
A32: Navegación correcta entre ventanas y regreso al menú al finalizar la partida | B32: 1 | D32: 1
A33: 2.2 Gestión de pilotos y naves | B33: =SUM(B34:B37) -> 7 | D33: =IF(SUM(D34:D37)=0,"",SUM(D34:D37)) -> 7
A34: Creación de piloto con validaciones (campos vacíos, nombres duplicados) | B34: 2 | D34: 2
A35: Selección de piloto existente para jugar | B35: 1 | D35: 1
A36: Selección de nave (Explorador / Caza Estelar / Acorazado) | B36: 1 | D36: 1
A37: Tiempos de sleep() de movimiento y disparo según la nave (2 s / 1 s / 0.3 s) | B37: 3 | D37: 3
A38: 2.3 Simulación de combate e hilos | B38: =SUM(B39:B45) -> 12 | D38: =IF(SUM(D39:D45)=0,"",SUM(D39:D45)) -> 12
A39: Movimiento de la nave del jugador con teclado dentro de los límites de pantalla | B39: 1 | D39: 1
A40: Enemigos y asteroides se generan en X máximo y se desplazan hacia X mínimo | B40: 2 | D40: 2
A41: Cada proyectil del jugador es un hilo independiente que actualiza su posición (x, y) | B41: 3 | D41: 3
A42: Cada enemigo/asteroide en pantalla es un hilo independiente | B42: 3 | D42: 3
A43: Detección correcta de colisiones proyectil–enemigo (sin colisiones fantasma) | B43: 2 | D43: 2
...

Sheet 202400155
A1: UNIVERSIDAD DE SAN CARLOS DE GUATEMALA
A2: FACULTAD DE INGENIERÍA
A3: ESCUELA DE CIENCIAS Y SISTEMAS
A4: Introducción a la Programación y Computación 1, Sección B
A5: Ing. William Estuardo Escobar Argueta
A6: Aux. Fernando José Vicente Velásquez
A8: Hoja de Calificación – Practica 2: Quetzal Space Defender - Side Scroller
A10: Fecha de calificación:
A11: Nombre del estudiante: | C11: =VLOOKUP(C12, Consolidado!$B$3:$C$26, 2, 0) -> #N/A | E11: Esvin Ortega
A12: Carné: | C12: 202400155
A14: Descripción de Ponderación | B14: Valor | C14: Observación | D14: Punteo
A15: 1. HABILIDADES – CÓMO SE PROGRAMA | B15: =B16+B21+B25 -> 25 | D15: =IF(D16+D21+D25=0,"",D16+D21+D25) -> 25
A16: 1.1 Documentación | B16: =SUM(B17:B20) -> 10 | D16: =IF(SUM(D17:D20)=0,"",SUM(D17:D20)) -> 10
A17: Manual técnico detallado completo y coherente con el código | B17: 3 | D17: 3
A18: Manual de usuario con capturas reales y guia para el usuario | B18: 3 | D18: 3
A19: Diagramas (flujo, módulos, matriz de ubicaciones) | B19: 2 | D19: 2
A20: Informe realizado con herramienta https://aicodedetector.org/ | B20: 2 | D20: 2
A21: 1.2 Repositorio GitHub | B21: =SUM(B22:B24) -> 7 | D21: =IF(SUM(D22:D24)=0,"",SUM(D22:D24)) -> 7
A22: Formato de nombre correcto y auxiliar agregado como colaborador | B22: 2 | D22: 2
A23: Commits progresivos, no concentrados al final | B23: 3 | D23: 3
A24: Estructura de carpetas ordenada y proyecto compilable desde el repo | B24: 2 | D24: 2
A25: 1.3 Buenas prácticas de código y reportes HTML | B25: =SUM(B26:B28) -> 8 | D25: =IF(SUM(D26:D28)=0,"",SUM(D26:D28)) -> 8
A26: Arquitectura ordenada con POO (clases por entidad: Nave, Enemigo, Proyectil, Piloto, etc.) | B26: 3 | D26: 3
A27: Nombres de variables/métodos claros y comentarios útiles | B27: 2 | D27: 2
A28: Uso exclusivo de vectores y ciclos para pilotos e historial (sin colecciones dinámicas) | B28: 3 | D28: 3
A29: 2. CONOCIMIENTO – QUÉ SE PROGRAMA | B29: =B30+B33+B38+B46+B50+B54+B58 -> 40 | D29: =IF(D30+D33+D38+D46+D50+D54+D58=0,"",D30+D33+D38+D46+D50+D54+D58) -> 36
A30: 2.1 Menú principal | B30: =SUM(B31:B32) -> 3 | D30: =IF(SUM(D31:D32)=0,"",SUM(D31:D32)) -> 3
A31: Opciones Jugar, Crear Piloto, Top de Puntajes y Salir funcionan sin errores ni cuelgues | B31: 2 | D31: 2
A32: Navegación correcta entre ventanas y regreso al menú al finalizar la partida | B32: 1 | D32: 1
A33: 2.2 Gestión de pilotos y naves | B33: =SUM(B34:B37) -> 7 | D33: =IF(SUM(D34:D37)=0,"",SUM(D34:D37)) -> 7
A34: Creación de piloto con validaciones (campos vacíos, nombres duplicados) | B34: 2 | D34: 2
A35: Selección de piloto existente para jugar | B35: 1 | D35: 1
A36: Selección de nave (Explorador / Caza Estelar / Acorazado) | B36: 1 | D36: 1
A37: Tiempos de sleep() de movimiento y disparo según la nave (2 s / 1 s / 0.3 s) | B37: 3 | D37: 3
A38: 2.3 Simulación de combate e hilos | B38: =SUM(B39:B45) -> 12 | D38: =IF(SUM(D39:D45)=0,"",SUM(D39:D45)) -> 12
A39: Movimiento de la nave del jugador con teclado dentro de los límites de pantalla | B39: 1 | D39: 1
A40: Enemigos y asteroides se generan en X máximo y se desplazan hacia X mínimo | B40: 2 | D40: 2
A41: Cada proyectil del jugador es un hilo independiente que actualiza su posición (x, y) | B41: 3 | D41: 3
A42: Cada enemigo/asteroide en pantalla es un hilo independiente | B42: 3 | D42: 3
A43: Detección correcta de colisiones proyectil–enemigo (sin colisiones fantasma) | B43: 2 | D43: 2
...

Sheet Consolidado
A1: Consolidado de calificaciones – Practica 2: Quetzal Space Defender - Side Scroller
A2: No. | B2: Carné | C2: Nombre del estudiante | D2: Habilidades (20) | E2: Conocimiento (55) | F2: Autoría (25) | G2: Subtotal | H2: Penalización | I2: Nota final | J2: Plagio | K2: Uso de IA | L2: Modificacion | M2: Repositorio
A3: 1 | B3: 201024808 | C3: MARTA GABRIELA GÓMEZ DIMAYUGA | D3: =IFERROR(INDIRECT(B3 & "!D15"), "0") -> #REF! | E3: =IFERROR(INDIRECT(B3 & "!D29"), "0") -> #REF! | F3: =IFERROR(INDIRECT(B3 & "!D66"), "0") -> #REF! | G3: =IF(C3="","",SUM(D3:F3)) -> #REF! | H3: =IFERROR(__xludf.dummyfunction("IFERROR(MIN(FILTER(INDIRECT(B3 & ""!B90:B106""), LEFT(INDIRECT(B3 & ""!C90:C106""),1)=""S"")), ""0%"")"),"0%") -> 0% | I3: =IF(C3="","",MAX(0,ROUND(G3*(1+H3),2))) -> #REF!
A4: 2 | B4: 201503481 | C4: DIEGO ALFONSO CANEL FUENTES | D4: =IFERROR(INDIRECT(B4 & "!D15"), "0") -> #REF! | E4: =IFERROR(INDIRECT(B4 & "!D29"), "0") -> #REF! | F4: =IFERROR(INDIRECT(B4 & "!D66"), "0") -> #REF! | G4: =IF(C4="","",SUM(D4:F4)) -> #REF! | H4: =IFERROR(__xludf.dummyfunction("IFERROR(MIN(FILTER(INDIRECT(B4 & ""!B90:B106""), LEFT(INDIRECT(B4 & ""!C90:C106""),1)=""S"")), ""0%"")"),"0%") -> 0% | I4: =IF(C4="","",MAX(0,ROUND(G4*(1+H4),2))) -> #REF!
A5: 3 | B5: 202004723 | C5: ERMI RONALDO SOTO MEJÍA | D5: =IFERROR(INDIRECT(B5 & "!D15"), "0") -> #REF! | E5: =IFERROR(INDIRECT(B5 & "!D29"), "0") -> #REF! | F5: =IFERROR(INDIRECT(B5 & "!D66"), "0") -> #REF! | G5: =IF(C5="","",SUM(D5:F5)) -> #REF! | H5: =IFERROR(__xludf.dummyfunction("IFERROR(MIN(FILTER(INDIRECT(B5 & ""!B90:B106""), LEFT(INDIRECT(B5 & ""!C90:C106""),1)=""S"")), ""0%"")"),"0%") -> 0% | I5: =IF(C5="","",MAX(0,ROUND(G5*(1+H5),2))) -> #REF!
A6: 4 | B6: 202201204 | C6: BRYAN ALEXANDER MARTÍNEZ FLORES | D6: =IFERROR(INDIRECT(B6 & "!D15"), "0") -> 23 | E6: =IFERROR(INDIRECT(B6 & "!D29"), "0") -> 34 | F6: =IFERROR(INDIRECT(B6 & "!D66"), "0") -> 3 | G6: =IF(C6="","",SUM(D6:F6)) -> 60 | H6: =IFERROR(__xludf.dummyfunction("IFERROR(MIN(FILTER(INDIRECT(B6 & ""!B90:B106""), LEFT(INDIRECT(B6 & ""!C90:C106""),1)=""S"")), ""0%"")"),"0%") -> 0% | I6: =IF(C6="","",MAX(0,ROUND(G6*(1+H6),2))) -> 60
A7: 5 | B7: 202300365 | C7: BRAYAN HOMERO SOSA GONZALEZ | D7: =IFERROR(INDIRECT(B7 & "!D15"), "0") -> #REF! | E7: =IFERROR(INDIRECT(B7 & "!D29"), "0") -> #REF! | F7: =IFERROR(INDIRECT(B7 & "!D66"), "0") -> #REF! | G7: =IF(C7="","",SUM(D7:F7)) -> #REF! | H7: =IFERROR(__xludf.dummyfunction("IFERROR(MIN(FILTER(INDIRECT(B7 & ""!B90:B106""), LEFT(INDIRECT(B7 & ""!C90:C106""),1)=""S"")), ""0%"")"),"0%") -> 0% | I7: =IF(C7="","",MAX(0,ROUND(G7*(1+H7),2))) -> #REF!
A8: 6 | B8: 202303797 | C8: ROLANDO AARÓN BARRIOS BOROR | D8: =IFERROR(INDIRECT(B8 & "!D15"), "0") -> #REF! | E8: =IFERROR(INDIRECT(B8 & "!D29"), "0") -> #REF! | F8: =IFERROR(INDIRECT(B8 & "!D66"), "0") -> #REF! | G8: =IF(C8="","",SUM(D8:F8)) -> #REF! | H8: =IFERROR(__xludf.dummyfunction("IFERROR(MIN(FILTER(INDIRECT(B8 & ""!B90:B106""), LEFT(INDIRECT(B8 & ""!C90:C106""),1)=""S"")), ""0%"")"),"0%") -> 0% | I8: =IF(C8="","",MAX(0,ROUND(G8*(1+H8),2))) -> #REF!
A9: 7 | B9: 202306260 | C9: WILLIAM SAMUEL CABRERA GÓMEZ | D9: =IFERROR(INDIRECT(B9 & "!D15"), "0") -> #REF! | E9: =IFERROR(INDIRECT(B9 & "!D29"), "0") -> #REF! | F9: =IFERROR(INDIRECT(B9 & "!D66"), "0") -> #REF! | G9: =IF(C9="","",SUM(D9:F9)) -> #REF! | H9: =IFERROR(__xludf.dummyfunction("IFERROR(MIN(FILTER(INDIRECT(B9 & ""!B90:B106""), LEFT(INDIRECT(B9 & ""!C90:C106""),1)=""S"")), ""0%"")"),"0%") -> 0% | I9: =IF(C9="","",MAX(0,ROUND(G9*(1+H9),2))) -> #REF!
A10: 8 | B10: 202308203 | C10: HANS CRISTIAN MEYER DIAZ | D10: =IFERROR(INDIRECT(B10 & "!D15"), "0") -> #REF! | E10: =IFERROR(INDIRECT(B10 & "!D29"), "0") -> #REF! | F10: =IFERROR(INDIRECT(B10 & "!D66"), "0") -> #REF! | G10: =IF(C10="","",SUM(D10:F10)) -> #REF! | H10: =IFERROR(__xludf.dummyfunction("IFERROR(MIN(FILTER(INDIRECT(B10 & ""!B90:B106""), LEFT(INDIRECT(B10 & ""!C90:C106""),1)=""S"")), ""0%"")"),"0%") -> 0% | I10: =IF(C10="","",MAX(0,ROUND(G10*(1+H10),2))) -> #REF!
A11: 9 | B11: 202308528 | C11: ASTRID MARIA SUSETH MORALES RODAS | D11: =IFERROR(INDIRECT(B11 & "!D15"), "0") -> #REF! | E11: =IFERROR(INDIRECT(B11 & "!D29"), "0") -> #REF! | F11: =IFERROR(INDIRECT(B11 & "!D66"), "0") -> #REF! | G11: =IF(C11="","",SUM(D11:F11)) -> #REF! | H11: =IFERROR(__xludf.dummyfunction("IFERROR(MIN(FILTER(INDIRECT(B11 & ""!B90:B106""), LEFT(INDIRECT(B11 & ""!C90:C106""),1)=""S"")), ""0%"")"),"0%") -> 0% | I11: =IF(C11="","",MAX(0,ROUND(G11*(1+H11),2))) -> #REF!
A12: 10 | B12: 202400066 | C12: DIEGO SEBASTIAN ALVARADO MORATAYA | D12: =IFERROR(INDIRECT(B12 & "!D15"), "0") -> 25 | E12: =IFERROR(INDIRECT(B12 & "!D29"), "0") -> 40 | F12: =IFERROR(INDIRECT(B12 & "!D66"), "0") -> 3 | G12: =IF(C12="","",SUM(D12:F12)) -> 68 | H12: =IFERROR(__xludf.dummyfunction("IFERROR(MIN(FILTER(INDIRECT(B12 & ""!B90:B106""), LEFT(INDIRECT(B12 & ""!C90:C106""),1)=""S"")), ""0%"")"),"0%") -> 0% | I12: =IF(C12="","",MAX(0,ROUND(G12*(1+H12),2))) -> 68
A13: 11 | B13: 202400155 | C13: ESVIN FERNANDO ORTEGA GONZÁLEZ | D13: =IFERROR(INDIRECT(B13 & "!D15"), "0") -> 25 | E13: =IFERROR(INDIRECT(B13 & "!D29"), "0") -> 36 | F13: =IFERROR(INDIRECT(B13 & "!D66"), "0") -> 0 | G13: =IF(C13="","",SUM(D13:F13)) -> 61 | H13: =IFERROR(__xludf.dummyfunction("IFERROR(MIN(FILTER(INDIRECT(B13 & ""!B90:B106""), LEFT(INDIRECT(B13 & ""!C90:C106""),1)=""S"")), ""0%"")"),"0%") -> 0% | I13: =IF(C13="","",MAX(0,ROUND(G13*(1+H13),2))) -> 61
A14: 12 | B14: 202400482 | C14: ADRIAN EDUARDO ALVAREZ ZAMBRANO | D14: 0 | E14: 0 | F14: 0 | G14: =IF(C14="","",SUM(D14:F14)) -> 0 | H14: =IFERROR(__xludf.dummyfunction("IFERROR(MIN(FILTER(INDIRECT(B14 & ""!B90:B106""), LEFT(INDIRECT(B14 & ""!C90:C106""),1)=""S"")), ""0%"")"),"0%") -> 0% | I14: =IF(C14="","",MAX(0,ROUND(G14*(1+H14),2))) -> 0
A15: 13 | B15: 202403338 | C15: ANDY RAÍ TELÓN GABRIEL | D15: =IFERROR(INDIRECT(B15 & "!D15"), "0") -> 23 | E15: =IFERROR(INDIRECT(B15 & "!D29"), "0") -> 38.5 | F15: =IFERROR(INDIRECT(B15 & "!D66"), "0") -> 1 | G15: =IF(C15="","",SUM(D15:F15)) -> 62.5 | H15: =IFERROR(__xludf.dummyfunction("IFERROR(MIN(FILTER(INDIRECT(B15 & ""!B90:B106""), LEFT(INDIRECT(B15 & ""!C90:C106""),1)=""S"")), ""0%"")"),"0%") -> 0% | I15: =IF(C15="","",MAX(0,ROUND(G15*(1+H15),2))) -> 62.5
A16: 14 | B16: 202404528 | C16: MELISSA GRISSEL PEREZ RIVAS | D16: =IFERROR(INDIRECT(B16 & "!D15"), "0") -> 21 | E16: =IFERROR(INDIRECT(B16 & "!D29"), "0") -> 40 | F16: =IFERROR(INDIRECT(B16 & "!D66"), "0") -> 3 | G16: =IF(C16="","",SUM(D16:F16)) -> 64 | H16: =IFERROR(__xludf.dummyfunction("IFERROR(MIN(FILTER(INDIRECT(B16 & ""!B90:B106""), LEFT(INDIRECT(B16 & ""!C90:C106""),1)=""S"")), ""0%"")"),"0%") -> 0% | I16: =IF(C16="","",MAX(0,ROUND(G16*(1+H16),2))) -> 64
A17: 15 | B17: 202405048 | C17: MONIKA ESTEFANIA CRUZ PALACIOS | D17: =IFERROR(INDIRECT(B17 & "!D15"), "0") -> 23 | E17: =IFERROR(INDIRECT(B17 & "!D29"), "0") -> 40 | F17: =IFERROR(INDIRECT(B17 & "!D66"), "0") -> 0 | G17: =IF(C17="","",SUM(D17:F17)) -> 63 | H17: =IFERROR(__xludf.dummyfunction("IFERROR(MIN(FILTER(INDIRECT(B17 & ""!B90:B106""), LEFT(INDIRECT(B17 & ""!C90:C106""),1)=""S"")), ""0%"")"),"0%") -> 0% | I17: =IF(C17="","",MAX(0,ROUND(G17*(1+H17),2))) -> 63
A18: 16 | B18: 202405842 | C18: GABRIEL LEVI ZAPETA MAZARIEGOS | D18: =IFERROR(INDIRECT(B18 & "!D15"), "0") -> #REF! | E18: =IFERROR(INDIRECT(B18 & "!D29"), "0") -> #REF! | F18: =IFERROR(INDIRECT(B18 & "!D66"), "0") -> #REF! | G18: =IF(C18="","",SUM(D18:F18)) -> #REF! | H18: =IFERROR(__xludf.dummyfunction("IFERROR(MIN(FILTER(INDIRECT(B18 & ""!B90:B106""), LEFT(INDIRECT(B18 & ""!C90:C106""),1)=""S"")), ""0%"")"),"0%") -> 0% | I18: =IF(C18="","",MAX(0,ROUND(G18*(1+H18),2))) -> #REF!
A19: 17 | B19: 202406816 | C19: EVELYN ARACELY CARDONA AGUILON | D19: =IFERROR(INDIRECT(B19 & "!D15"), "0") -> 25 | E19: =IFERROR(INDIRECT(B19 & "!D29"), "0") -> 38 | F19: =IFERROR(INDIRECT(B19 & "!D66"), "0") -> 3 | G19: =IF(C19="","",SUM(D19:F19)) -> 66 | H19: =IFERROR(__xludf.dummyfunction("IFERROR(MIN(FILTER(INDIRECT(B19 & ""!B90:B106""), LEFT(INDIRECT(B19 & ""!C90:C106""),1)=""S"")), ""0%"")"),"0%") -> 0% | I19: =IF(C19="","",MAX(0,ROUND(G19*(1+H19),2))) -> 66
A20: 18 | B20: 202407699 | C20: KEVIN ANDRE MENDOZA VILLEDA | D20: =IFERROR(INDIRECT(B20 & "!D15"), "0") -> 18 | E20: =IFERROR(INDIRECT(B20 & "!D29"), "0") -> 40 | F20: =IFERROR(INDIRECT(B20 & "!D66"), "0") -> 0 | G20: =IF(C20="","",SUM(D20:F20)) -> 58 | H20: =IFERROR(__xludf.dummyfunction("IFERROR(MIN(FILTER(INDIRECT(B20 & ""!B90:B106""), LEFT(INDIRECT(B20 & ""!C90:C106""),1)=""S"")), ""0%"")"),"0%") -> 0% | I20: =IF(C20="","",MAX(0,ROUND(G20*(1+H20),2))) -> 58
A21: 19 | B21: 202501349 | C21: DIEGO JOSÉ GÓMEZ LÓPEZ | D21: 0 | E21: 0 | F21: 0 | G21: =IF(C21="","",SUM(D21:F21)) -> 0 | H21: =IFERROR(__xludf.dummyfunction("IFERROR(MIN(FILTER(INDIRECT(B21 & ""!B90:B106""), LEFT(INDIRECT(B21 & ""!C90:C106""),1)=""S"")), ""0%"")"),"0%") -> 0% | I21: =IF(C21="","",MAX(0,ROUND(G21*(1+H21),2))) -> 0
A22: 20 | B22: 202501470 | C22: CARLOS ANDRÉS HERNÁNDEZ VÁSQUEZ | D22: =IFERROR(INDIRECT(B22 & "!D15"), "0") -> #REF! | E22: =IFERROR(INDIRECT(B22 & "!D29"), "0") -> #REF! | F22: =IFERROR(INDIRECT(B22 & "!D66"), "0") -> #REF! | G22: =IF(C22="","",SUM(D22:F22)) -> #REF! | H22: =IFERROR(__xludf.dummyfunction("IFERROR(MIN(FILTER(INDIRECT(B22 & ""!B90:B106""), LEFT(INDIRECT(B22 & ""!C90:C106""),1)=""S"")), ""0%"")"),"0%") -> 0% | I22: =IF(C22="","",MAX(0,ROUND(G22*(1+H22),2))) -> #REF!
A23: 21 | B23: 202501625 | C23: CHUNG MIN KIM CHEN | D23: =IFERROR(INDIRECT(B23 & "!D15"), "0") -> 21 | E23: =IFERROR(INDIRECT(B23 & "!D29"), "0") -> 40 | F23: =IFERROR(INDIRECT(B23 & "!D66"), "0") -> 3 | G23: =IF(C23="","",SUM(D23:F23)) -> 64 | H23: =IFERROR(__xludf.dummyfunction("IFERROR(MIN(FILTER(INDIRECT(B23 & ""!B90:B106""), LEFT(INDIRECT(B23 & ""!C90:C106""),1)=""S"")), ""0%"")"),"0%") -> 0% | I23: =IF(C23="","",MAX(0,ROUND(G23*(1+H23),2))) -> 64
A24: 22 | B24: 202502481 | C24: FRANCISCO JAVIER CHIVICHÓN FERNÁNDEZ | D24: =IFERROR(INDIRECT(B24 & "!D15"), "0") -> #REF! | E24: =IFERROR(INDIRECT(B24 & "!D29"), "0") -> #REF! | F24: =IFERROR(INDIRECT(B24 & "!D66"), "0") -> #REF! | G24: =IF(C24="","",SUM(D24:F24)) -> #REF! | H24: =IFERROR(__xludf.dummyfunction("IFERROR(MIN(FILTER(INDIRECT(B24 & ""!B90:B106""), LEFT(INDIRECT(B24 & ""!C90:C106""),1)=""S"")), ""0%"")"),"0%") -> 0% | I24: =IF(C24="","",MAX(0,ROUND(G24*(1+H24),2))) -> #REF!
A25: 23 | B25: 202505830 | C25: NAOMI ROCIO AXPUAC VELASQUEZ | D25: 0 | E25: 0 | F25: 0 | G25: =IF(C25="","",SUM(D25:F25)) -> 0 | H25: =IFERROR(__xludf.dummyfunction("IFERROR(MIN(FILTER(INDIRECT(B25 & ""!B90:B106""), LEFT(INDIRECT(B25 & ""!C90:C106""),1)=""S"")), ""0%"")"),"0%") -> 0% | I25: =IF(C25="","",MAX(0,ROUND(G25*(1+H25),2))) -> 0 | N25: This invitation has expired.
A26: 24 | B26: 202507586 | C26: KEVYN JOSUÉ APÉN OTZOY | D26: {=IFERROR(INDIRECT(B26 & "!D15"), "0")} -> 23 | E26: {=IFERROR(INDIRECT(B26 & "!D29"), "0")} -> 0 | F26: {=IFERROR(INDIRECT(B26 & "!D66"), "0")} -> 3 | G26: =IF(C26="","",SUM(D26:F26)) -> 26 | H26: =IFERROR(__xludf.dummyfunction("IFERROR(MIN(FILTER(INDIRECT(B26 & ""!B90:B106""), LEFT(INDIRECT(B26 & ""!C90:C106""),1)=""S"")), ""0%"")"),"0%") -> 0% | I26: =IF(C26="","",MAX(0,ROUND(G26*(1+H26),2))) -> 26
C28: Estudiantes calificados | D28: =COUNT(I3:I26) -> 13
C29: Nota promedio | D29: =IFERROR(AVERAGE(I3:I26),0) -> 0
C30: Nota más alta | D30: =IFERROR(MAX(I3:I26),0) -> 0
C31: Nota más baja | D31: =IFERROR(MIN(I3:I26),0) -> 0
C32: Aprobados (61 pts o más) | D32: =COUNTIF(I3:I26,">=61") -> 7
C33: Reprobados (menos de 61 pts) | D33: =COUNT(I3:I26)-COUNTIF(I3:I26,">=61") -> 6

Sheet Hoja15
A1: Carnet | B1: Nota
A2: 202406816 | B2: 98
A3: 202405048 | B3: 68
A4: 202404528 | B4: 81
A5: 202505830 | B5: 80
A6: 202501625 | B6: 87
A7: 202201204 | B7: 92
A8: 202507586 | B8: 90
A9: 202501349 | B9: 98
A10: 202407699 | B10: 70
A11: 202403338 | B11: 75.5
A12: 202400066 | B12: 82
A13: 202400155 | B13: 66.5
