Workbook

Sheet Refentes
B1: Identificación de referentes internacionales
B3: Nombre del Curso | C3: 770 - Introducción a ala programación y computación 1
B4: Semestre que aplica | C4: Primer Semestre 2027
B6: 1. Universidad Refente
B7: Analiza cursos similares en universidades internacionales reconocidas (como MIT, Stanford o ETH Zurich) para comparar temas, herramientas y competencias. Esto permite identificar buenas prácticas y alinear el laboratorio con tendencias globales en educación tecnológica.
B9: Nombre de la Universidad | C9: Stanford University
B10: Pais | C10: Estados Unidos
B11: Nombre del Curso | C11: CS106A - Programming Methodology
B12: Fuente de Información | C12: Curso introductorio de programación de Stanford, orientado a principios de ingeniería de software: diseño de programas, descomposición, encapsulamiento, abstracción y pruebas. Actualización importante: el curso migró de Java a Python 3 (entorno PyCharm) y conserva Karel the Robot como introducción. Contenido tomado de la edición Summer Quarter 2026. Fuentes: https://web.stanford.edu/class/archive/cs/cs106a/cs106a.1268/ | https://online.stanford.edu/courses/cs106a-programming-methodology
B14: No. | C14: Contenido de la Universidad Referente
B15: 1 | C15: Resolución de problemas y descomposición con Karel the Robot (control de flujo inicial)
B16: 2 | C16: Fundamentos de Python: variables, tipos de datos, expresiones y entrada/salida
B17: 3 | C17: Funciones: parámetros, valores de retorno y alcance de variables
B18: 4 | C18: Estructuras de control: condicionales y ciclos
B19: 5 | C19: Cadenas de texto (Strings) y listas
B20: 6 | C20: Gráficos, imágenes y listas bidimensionales (grids)
B21: 7 | C21: Lectura de archivos y diccionarios (incluye diccionarios anidados)
B22: 8 | C22: Clases y objetos: introducción a la programación orientada a objetos
B23: 9 | C23: Tuplas, ordenamiento y búsqueda (aplicación: motores de búsqueda)
B24: 10 | C24: Ética en la computación e introducción a Internet
B27: 2. Estandar Internacional
B28: Se identifican estándares internacionales relevantes (como ABET, CDIO o IEEE/ACM) para verificar si el laboratorio cumple con criterios de calidad educativa, competencias clave y buenas prácticas recomendadas a nivel global.
B30: Nombre del Estandar | C30: ACM/IEEE-CS/AAAI CS2023 - Computer Science Curricula 2023
B31: Sección , Capitulo , etc, | C31: Knowledge Area: Software Development Fundamentals (SDF)
B32: Funte de Información | C32: Área de conocimiento que agrupa los conceptos y habilidades del proceso de desarrollo de software que deben dominarse al inicio de la carrera (típicamente el primer año): construcciones fundamentales de programación, estructuras de datos básicas, algoritmos fundamentales, prácticas de desarrollo y aspectos de sociedad y ética. Unidades: SDF-Fundamentals, SDF-ADT, SDF-Algorithms, SDF-Practices y SDF-SEP. Fuente: https://csed.acm.org/final-report/ | https://csed.acm.org/software-development-fundamentals/
B34: No. | C34: Contenido del Estandar
B35: 1 | C35: Conceptos fundamentales: algoritmo, variables, tipos, expresiones y asignación
B36: 2 | C36: Estructuras de control (condicionales e iterativas) y funciones con paso de parámetros
B37: 3 | C37: Recursividad y pila de llamadas (call stack)
B38: 4 | C38: Entrada/salida simple y persistencia de datos mediante archivos
B39: 5 | C39: Modularidad y POO básica: descomposición, clases, objetos y encapsulamiento
B40: 6 | C40: Tipos de datos estructurados: strings, arreglos, listas, diccionarios y conjuntos
B41: 7 | C41: Algoritmos fundamentales: búsqueda, ordenamiento y noción de eficiencia
B42: 8 | C42: Prácticas de desarrollo: pruebas, depuración, estilo, documentación y herramientas (IDE, control de versiones)
B43: 9 | C43: Manejo de errores y excepciones para programas robustos
B44: 10 | C44: Sociedad, ética y profesión: responsabilidad social y propiedad intelectual
B47: 3. Tecnologias y/o herramientas en Tendencia
B48: *Investiga las tecnologias y/o herramientas que estan en tendencia actualmente a nivel internacional, como por ejemplo en cuadrante de gartner
B49: No. | C49: Nombre | H49: Link de referencia
B50: 1 | C50: GitHub Copilot | H50: https://github.com/features/copilot
...

Sheet Analisis de Contenido
B1: Comparación con referentes internacionales
A2: =#REF!&" - "&C3 -> #REF!
B3: Nombre del Curso | C3: =Refentes!C3 -> 770 - Introducción a ala programación y computación 1
B4: Semestre que aplica | C4: =Refentes!C4 -> Primer Semestre 2027
B5: * Si el tema del curso no esta en el referente dejala la casilla en blanco
B6: **Este ejercicio de analisis de servira para mejorar el laboratorio para el siguiente semestre.
F8: Universidad: Stanford University (CS106A) | G8: Estándar: ACM/IEEE CS2023 (SDF)
B9: Laboratorio Actual ( Aqui van los temas impartidos en el presente semestre) | F9: =Refentes!C9 -> Stanford University | G9: =Refentes!C30 -> ACM/IEEE-CS/AAAI CS2023 - Computer Science Curricula 2023
B10: Competencia | C10: Unidad | D10: Tema | E10: SubTema | F10: Contenido | G10: Contenido
B11: Analiza Estructuras de datos complejas y algoritmos de ordenamiento Utilizando técnicas de análisis de complejidad temporal y Para optimizar el rendimiento y eficiencia de aplicaciones | C11: 1. Introducción a la Programación | D11: Introducción a los fundamentos de Programación | E11: Algoritmos | F11: Resolución de problemas y descomposición con Karel the Robot (control de flujo inicial) | G11: Conceptos fundamentales: algoritmo, variables, tipos, expresiones y asignación
B12: Analiza Estructuras de datos complejas y algoritmos de ordenamiento Utilizando técnicas de análisis de complejidad temporal y Para optimizar el rendimiento y eficiencia de aplicaciones | C12: 1. Introducción a la Programación | D12: Introducción a los fundamentos de Programación | E12: Diagramas de Flujo | F12: Resolución de problemas y descomposición con Karel the Robot (control de flujo inicial) | G12: Conceptos fundamentales: algoritmo, variables, tipos, expresiones y asignación
B13: Analiza Estructuras de datos complejas y algoritmos de ordenamiento Utilizando técnicas de análisis de complejidad temporal y Para optimizar el rendimiento y eficiencia de aplicaciones | C13: 1. Introducción a la Programación | D13: Introducción a los fundamentos de Programación | E13: Pseudocódigo | F13: Resolución de problemas y descomposición con Karel the Robot (control de flujo inicial) | G13: Conceptos fundamentales: algoritmo, variables, tipos, expresiones y asignación
B14: Colabora En equipos multidiciplinarios de desarrollo de software Aplicando metodologías ágiles, herramientas de gestión y comunicación efectiva Adaptando el nivel de detalle según el contexto y audiencia objetivo | C14: 2. Introducción al versionamiento | D14: Introducción al manejo de control de versiones | E14: Introducción a versionamiento | G14: Prácticas de desarrollo: pruebas, depuración, estilo, documentación y herramientas (IDE, control de versiones)
B15: Colabora En equipos multidiciplinarios de desarrollo de software Aplicando metodologías ágiles, herramientas de gestión y comunicación efectiva Adaptando el nivel de detalle según el contexto y audiencia objetivo | C15: 2. Introducción al versionamiento | D15: Introducción al manejo de control de versiones | E15: Herramientas de control de versiones | G15: Prácticas de desarrollo: pruebas, depuración, estilo, documentación y herramientas (IDE, control de versiones)
B16: Colabora En equipos multidiciplinarios de desarrollo de software Aplicando metodologías ágiles, herramientas de gestión y comunicación efectiva Adaptando el nivel de detalle según el contexto y audiencia objetivo | C16: 2. Introducción al versionamiento | D16: Introducción al manejo de control de versiones | E16: Tareas básicas de Git | G16: Prácticas de desarrollo: pruebas, depuración, estilo, documentación y herramientas (IDE, control de versiones)
B17: Colabora En equipos multidiciplinarios de desarrollo de software Aplicando metodologías ágiles, herramientas de gestión y comunicación efectiva Adaptando el nivel de detalle según el contexto y audiencia objetivo | C17: 2. Introducción al versionamiento | D17: Introducción al manejo de control de versiones | E17: Colaboración en repositorios remotos | G17: Prácticas de desarrollo: pruebas, depuración, estilo, documentación y herramientas (IDE, control de versiones)
B18: Comunica Soluciones técnicas complejas a audiencias diversas Utilizando documentación técnica, presentaciones y demostraciones interactivas Adaptando el nivel de detalle según el contexto y audiencia objetivo | C18: 3. Introducción a Java | D18: Introducción a Java - Parte 1 | E18: ¿Qué es Java? | F18: Fundamentos de Python: variables, tipos de datos, expresiones y entrada/salida | G18: Conceptos fundamentales: algoritmo, variables, tipos, expresiones y asignación
B19: Comunica Soluciones técnicas complejas a audiencias diversas Utilizando documentación técnica, presentaciones y demostraciones interactivas Adaptando el nivel de detalle según el contexto y audiencia objetivo | C19: 3. Introducción a Java | D19: Introducción a Java - Parte 2 | E19: Versiones y ambientes de java (JDK, JRE, JVM) | G19: Prácticas de desarrollo: pruebas, depuración, estilo, documentación y herramientas (IDE, control de versiones)
B20: Analiza Estructuras de datos complejas y algoritmos de ordenamiento Utilizando técnicas de análisis de complejidad temporal y Para optimizar el rendimiento y eficiencia de aplicaciones | C20: 3. Introducción a Java | D20: Introducción a Java - Parte 2 | E20: Operadores aritméticos, relacionales y lógicos | F20: Fundamentos de Python: variables, tipos de datos, expresiones y entrada/salida | G20: Conceptos fundamentales: algoritmo, variables, tipos, expresiones y asignación
B21: Comunica Soluciones técnicas complejas a audiencias diversas Utilizando documentación técnica, presentaciones y demostraciones interactivas Adaptando el nivel de detalle según el contexto y audiencia objetivo | C21: 3. Introducción a Java | D21: Introducción a Java - Parte 3 | E21: Características de Java | F21: Fundamentos de Python: variables, tipos de datos, expresiones y entrada/salida
B22: Analiza Estructuras de datos complejas y algoritmos de ordenamiento Utilizando técnicas de análisis de complejidad temporal y Para optimizar el rendimiento y eficiencia de aplicaciones | C22: 3. Introducción a Java | D22: Introducción a Java - Parte 3 | E22: Input y output | F22: Fundamentos de Python: variables, tipos de datos, expresiones y entrada/salida | G22: Entrada/salida simple y persistencia de datos mediante archivos
B23: Comunica Soluciones técnicas complejas a audiencias diversas Utilizando documentación técnica, presentaciones y demostraciones interactivas Adaptando el nivel de detalle según el contexto y audiencia objetivo | C23: 3. Introducción a Java | D23: Introducción a Java - Parte 4 | E23: Comentarios de una línea y multilínea | G23: Prácticas de desarrollo: pruebas, depuración, estilo, documentación y herramientas (IDE, control de versiones)
B24: Analiza Estructuras de datos complejas y algoritmos de ordenamiento Utilizando técnicas de análisis de complejidad temporal y Para optimizar el rendimiento y eficiencia de aplicaciones | C24: 3. Introducción a Java | D24: Introducción a Java - Parte 4 | E24: Estructuras de control (if, else if, else y switch) | F24: Estructuras de control: condicionales y ciclos | G24: Estructuras de control (condicionales e iterativas) y funciones con paso de parámetros
B25: Analiza Estructuras de datos complejas y algoritmos de ordenamiento Utilizando técnicas de análisis de complejidad temporal y Para optimizar el rendimiento y eficiencia de aplicaciones | C25: 3. Introducción a Java | D25: Introducción a Java - Parte 5 | E25: Variables | F25: Fundamentos de Python: variables, tipos de datos, expresiones y entrada/salida | G25: Conceptos fundamentales: algoritmo, variables, tipos, expresiones y asignación
B26: Analiza Estructuras de datos complejas y algoritmos de ordenamiento Utilizando técnicas de análisis de complejidad temporal y Para optimizar el rendimiento y eficiencia de aplicaciones | C26: 3. Introducción a Java | D26: Introducción a Java - Parte 5 | E26: Ciclos (for, while, do-while) | F26: Estructuras de control: condicionales y ciclos | G26: Estructuras de control (condicionales e iterativas) y funciones con paso de parámetros
B27: Analiza Estructuras de datos complejas y algoritmos de ordenamiento Utilizando técnicas de análisis de complejidad temporal y Para optimizar el rendimiento y eficiencia de aplicaciones | C27: 3. Introducción a Java | D27: Introducción a Java - Parte 6 | E27: Tipos primitivos y no primitivos | F27: Fundamentos de Python: variables, tipos de datos, expresiones y entrada/salida | G27: Conceptos fundamentales: algoritmo, variables, tipos, expresiones y asignación
B28: Evalua Arquitecturas de software y calidad de código Empleando métricas de software, patrones de diseño y técnicas de testing Para garantizar mantenibilidad, escalabilidad y robustez del sistema | C28: 3. Introducción a Java | D28: Introducción a Java - Parte 6 | E28: Try-catch-finally | G28: Manejo de errores y excepciones para programas robustos
B29: Analiza Estructuras de datos complejas y algoritmos de ordenamiento Utilizando técnicas de análisis de complejidad temporal y Para optimizar el rendimiento y eficiencia de aplicaciones | C29: 3. Introducción a Java | D29: Introducción a Java - Parte 7 | E29: Casteos implícitos y explícitos | F29: Fundamentos de Python: variables, tipos de datos, expresiones y entrada/salida | G29: Conceptos fundamentales: algoritmo, variables, tipos, expresiones y asignación
B30: Analiza Estructuras de datos complejas y algoritmos de ordenamiento Utilizando técnicas de análisis de complejidad temporal y Para optimizar el rendimiento y eficiencia de aplicaciones | C30: 3. Introducción a Java | D30: Introducción a Java - Parte 7 | E30: Procedimientos y funciones | F30: Funciones: parámetros, valores de retorno y alcance de variables | G30: Estructuras de control (condicionales e iterativas) y funciones con paso de parámetros
B31: Evalua Arquitecturas de software y calidad de código Empleando métricas de software, patrones de diseño y técnicas de testing Para garantizar mantenibilidad, escalabilidad y robustez del sistema | C31: 3. Introducción a Java | D31: Introducción a Java - Parte 8 | E31: Debugging (Breakpoint [Inline, function], start, pause, continue, stop) | G31: Prácticas de desarrollo: pruebas, depuración, estilo, documentación y herramientas (IDE, control de versiones)
B32: Analiza Estructuras de datos complejas y algoritmos de ordenamiento Utilizando técnicas de análisis de complejidad temporal y Para optimizar el rendimiento y eficiencia de aplicaciones | C32: 4. Manejo de Memoria | D32: Manejo de memoria | E32: Arreglos y Matrices | F32: Gráficos, imágenes y listas bidimensionales (grids) | G32: Tipos de datos estructurados: strings, arreglos, listas, diccionarios y conjuntos
B33: Analiza Estructuras de datos complejas y algoritmos de ordenamiento Utilizando técnicas de análisis de complejidad temporal y Para optimizar el rendimiento y eficiencia de aplicaciones | C33: 4. Manejo de Memoria | D33: Manejo de memoria | E33: Listas Dinámicas | F33: Cadenas de texto (Strings) y listas | G33: Tipos de datos estructurados: strings, arreglos, listas, diccionarios y conjuntos
B34: Analiza Estructuras de datos complejas y algoritmos de ordenamiento Utilizando técnicas de análisis de complejidad temporal y Para optimizar el rendimiento y eficiencia de aplicaciones | C34: 4. Manejo de Memoria | D34: Manejo de memoria | E34: Métodos de Ordenamiento | F34: Tuplas, ordenamiento y búsqueda (aplicación: motores de búsqueda) | G34: Algoritmos fundamentales: búsqueda, ordenamiento y noción de eficiencia
B35: Analiza Estructuras de datos complejas y algoritmos de ordenamiento Utilizando técnicas de análisis de complejidad temporal y Para optimizar el rendimiento y eficiencia de aplicaciones | C35: 5. Recursividad y Archivos | D35: Recursividad y Archivos de texto plano | E35: Pila de ejecución (Call Stack) | F35: Funciones: parámetros, valores de retorno y alcance de variables | G35: Recursividad y pila de llamadas (call stack)
B36: Analiza Estructuras de datos complejas y algoritmos de ordenamiento Utilizando técnicas de análisis de complejidad temporal y Para optimizar el rendimiento y eficiencia de aplicaciones | C36: 5. Recursividad y Archivos | D36: Recursividad y Archivos de texto plano | E36: Recursividad | G36: Recursividad y pila de llamadas (call stack)
B37: Implementa Sistemas de software con persistencia de datos Utilizando bases de datos relacionales, archivos estructurados y APIs Conforme a especificaciones de integridad, consistencia y seguridad | C37: 5. Recursividad y Archivos | D37: Recursividad y Archivos de texto plano | E37: Manejo de archivos de texto plano | F37: Lectura de archivos y diccionarios (incluye diccionarios anidados) | G37: Entrada/salida simple y persistencia de datos mediante archivos
B38: Evalua Arquitecturas de software y calidad de código Empleando métricas de software, patrones de diseño y técnicas de testing Para garantizar mantenibilidad, escalabilidad y robustez del sistema | C38: 6. Introducción a POO | D38: Conceptos y Pilares de POO | E38: Concepto de abstracción y clasificación | F38: Clases y objetos: introducción a la programación orientada a objetos | G38: Modularidad y POO básica: descomposición, clases, objetos y encapsulamiento
B39: Evalua Arquitecturas de software y calidad de código Empleando métricas de software, patrones de diseño y técnicas de testing Para garantizar mantenibilidad, escalabilidad y robustez del sistema | C39: 6. Introducción a POO | D39: Conceptos y Pilares de POO | E39: Clases y objetos | F39: Clases y objetos: introducción a la programación orientada a objetos | G39: Modularidad y POO básica: descomposición, clases, objetos y encapsulamiento
B40: Evalua Arquitecturas de software y calidad de código Empleando métricas de software, patrones de diseño y técnicas de testing Para garantizar mantenibilidad, escalabilidad y robustez del sistema | C40: 6. Introducción a POO | D40: Conceptos y Pilares de POO | E40: Mensajes y métodos | F40: Clases y objetos: introducción a la programación orientada a objetos | G40: Modularidad y POO básica: descomposición, clases, objetos y encapsulamiento
B41: Evalua Arquitecturas de software y calidad de código Empleando métricas de software, patrones de diseño y técnicas de testing Para garantizar mantenibilidad, escalabilidad y robustez del sistema | C41: 6. Introducción a POO | D41: Conceptos y Pilares de POO | E41: Pilares de POO: Abstracción, Encapsulamiento, Polimorfismo, Herencia | F41: Clases y objetos: introducción a la programación orientada a objetos | G41: Modularidad y POO básica: descomposición, clases, objetos y encapsulamiento
...

Sheet Metadata
A1: Codigo-Nombre | E1: 2S2026 | F1: =IFERROR(__xludf.DUMMYFUNCTION("{IMPORTRANGE(E2,""Listado Cursos!i:i""),IMPORTRANGE(E2,""Listado Cursos!J:J"")}"),"#REF!") -> #REF! | G1: ="COMPUTED_VALUE" -> COMPUTED_VALUE
A2: 17 - Área Social Humanística 1 | E2: =IFERROR(__xludf.DUMMYFUNCTION("VLOOKUP(E1,IMPORTRANGE(""14SVpSRgMldrNgug8WsLJFt7WyBUBxCrt0v9QzSB_xyA"",""DataBase!A:B""),2,FALSE)"),"#REF!") -> #REF! | F2: ="COMPUTED_VALUE" -> COMPUTED_VALUE
A3: 101 - Área Matemática Básica 1 | F3: ="COMPUTED_VALUE" -> COMPUTED_VALUE
A4: 5 - Técnicas de Estudio e Investigación | F4: ="COMPUTED_VALUE" -> COMPUTED_VALUE
A5: 39 - Deportes 1 | F5: ="COMPUTED_VALUE" -> COMPUTED_VALUE
A6: 6 - Idioma Tecnico 1 | F6: ="COMPUTED_VALUE" -> COMPUTED_VALUE
A7: 19 - Área Social Humanística 2 | F7: ="COMPUTED_VALUE" -> COMPUTED_VALUE
A8: 103 - Área Matemática Básica 2 | F8: ="COMPUTED_VALUE" -> COMPUTED_VALUE
A9: 960 - Matemática Para Computación 1 | F9: ="COMPUTED_VALUE" -> COMPUTED_VALUE
A10: 147 - Física Básica | F10: ="COMPUTED_VALUE" -> COMPUTED_VALUE
A11: 40 - Deportes 2 | F11: ="COMPUTED_VALUE" -> COMPUTED_VALUE
A12: 8 - Idioma Técnico 2 | F12: ="COMPUTED_VALUE" -> COMPUTED_VALUE
A13: 795 - Logica de Sitemas | F13: ="COMPUTED_VALUE" -> COMPUTED_VALUE
A14: 962 - Matemática Para Computación 2 | F14: ="COMPUTED_VALUE" -> COMPUTED_VALUE
... A24: 152 - Física 2 | F24: ="COMPUTED_VALUE" -> COMPUTED_VALUE
A25: 10 - Lógica | F25: ="COMPUTED_VALUE" -> COMPUTED_VALUE | G25: ="COMPUTED_VALUE" -> COMPUTED_VALUE
A26: 11 - Idioma Técnico 4 | F26: ="COMPUTED_VALUE" -> COMPUTED_VALUE | G26: ="COMPUTED_VALUE" -> COMPUTED_VALUE
A27: 2025 - Prácticas Iniciales | F27: ="COMPUTED_VALUE" -> COMPUTED_VALUE | G27: ="COMPUTED_VALUE" -> COMPUTED_VALUE
A28: 732 - Estadística 1 | F28: ="COMPUTED_VALUE" -> COMPUTED_VALUE
A29: 777 - Organización de Lenguajes y Compiladores 1 | F29: ="COMPUTED_VALUE" -> COMPUTED_VALUE | G29: ="COMPUTED_VALUE" -> COMPUTED_VALUE
A30: 964 - Organización Computacional | F30: ="COMPUTED_VALUE" -> COMPUTED_VALUE | G30: ="COMPUTED_VALUE" -> COMPUTED_VALUE
A31: 772 - Estructuras de Datos | F31: ="COMPUTED_VALUE" -> COMPUTED_VALUE | G31: ="COMPUTED_VALUE" -> COMPUTED_VALUE
A32: 116 - Matemática Aplicada 3 | F32: ="COMPUTED_VALUE" -> COMPUTED_VALUE | G32: ="COMPUTED_VALUE" -> COMPUTED_VALUE
A33: 118 - Matemática Aplicada 1 | F33: ="COMPUTED_VALUE" -> COMPUTED_VALUE | G33: ="COMPUTED_VALUE" -> COMPUTED_VALUE
A34: 18 - Filosofía de la Ciencia | F34: ="COMPUTED_VALUE" -> COMPUTED_VALUE | G34: ="COMPUTED_VALUE" -> COMPUTED_VALUE
A35: 722 - Teoría de Sistemas 1 | F35: ="COMPUTED_VALUE" -> COMPUTED_VALUE
A36: 601 - Investigación de Operaciones 1 | F36: ="COMPUTED_VALUE" -> COMPUTED_VALUE
A37: 14 - Economía | F37: ="COMPUTED_VALUE" -> COMPUTED_VALUE | G37: ="COMPUTED_VALUE" -> COMPUTED_VALUE
A38: 781 - Organización de Lenguajes y Compiladores 2 | F38: ="COMPUTED_VALUE" -> COMPUTED_VALUE | G38: ="COMPUTED_VALUE" -> COMPUTED_VALUE
A39: 778 - Arquitectura de Computadoras y Ensambladores 1 | F39: ="COMPUTED_VALUE" -> COMPUTED_VALUE | G39: ="COMPUTED_VALUE" -> COMPUTED_VALUE
A40: 773 - Manejo e Implementación de Archivos | F40: ="COMPUTED_VALUE" -> COMPUTED_VALUE | G40: ="COMPUTED_VALUE" -> COMPUTED_VALUE
A41: 122 - Matemática Aplicada 4 | F41: ="COMPUTED_VALUE" -> COMPUTED_VALUE | G41: ="COMPUTED_VALUE" -> COMPUTED_VALUE
A42: 120 - Matemática Aplicada 2 | F42: ="COMPUTED_VALUE" -> COMPUTED_VALUE | G42: ="COMPUTED_VALUE" -> COMPUTED_VALUE
A43: 200 - Ingeniería Eléctrica 1 | F43: ="COMPUTED_VALUE" -> COMPUTED_VALUE | G43: ="COMPUTED_VALUE" -> COMPUTED_VALUE
A44: 724 - Teoría de Sistemas 2 | F44: ="COMPUTED_VALUE" -> COMPUTED_VALUE | G44: ="COMPUTED_VALUE" -> COMPUTED_VALUE
A45: 603 - Investigación de Operaciones 2 | F45: ="COMPUTED_VALUE" -> COMPUTED_VALUE | G45: ="COMPUTED_VALUE" -> COMPUTED_VALUE
A46: 734 - Estadística 2 | F46: ="COMPUTED_VALUE" -> COMPUTED_VALUE | G46: ="COMPUTED_VALUE" -> COMPUTED_VALUE
A47: 281 - Sistemas Operativos 1 | F47: ="COMPUTED_VALUE" -> COMPUTED_VALUE
A48: 779 - Arquitectura de Computadoras y Ensambladores 2 | F48: ="COMPUTED_VALUE" -> COMPUTED_VALUE
A49: 970 - Redes de Computadoras 1 | F49: ="COMPUTED_VALUE" -> COMPUTED_VALUE | G49: ="COMPUTED_VALUE" -> COMPUTED_VALUE
...

Sheet Analisis Tecnologico
B1: Comparación con referentes internacionales
B3: Nombre del Curso | C3: =Refentes!C3 -> 770 - Introducción a ala programación y computación 1
B4: Semestre que aplica | C4: =Refentes!C4 -> Primer Semestre 2027
B5: **Este ejercicio de analisis de servira para mejorar el laboratorio para el siguiente semestre.
B7: Tecnologias y/o Herramientas actuales en el laboratorio | E7: Tecnologias y/o herramientas en Tendencia
B8: Java (JDK) como lenguaje del laboratorio | E8: Java 25 (LTS)
B9: Interfaces gráficas con Swing y AWT | E9: JavaFX (OpenJFX)
B10: Git y GitHub para versionamiento y entrega de proyectos | E10: GitHub Codespaces
B11: IDE de escritorio para Java | E11: IntelliJ IDEA
B12: Depuración con breakpoints y pruebas manuales | E12: JUnit
B13: Proyectos compilados desde el IDE sin gestor de dependencias | E13: Gradle / Maven
B14: Cloud computing visto de forma teórica (SaaS, PaaS, IaaS) | E14: Docker
B15: Uso de IA no integrado formalmente en el laboratorio | E15: GitHub Copilot
B18: Consulta con el catedratico de los hallazgos y si debes hacer algun cambio en tecnologias y/o herramientas para el proximo semestre
