Workbook

Sheet Resumen
B2: Resumen de Ponderacion y Horas para realizar las actividades
B4: Curso | C4: 770 - Introducción a la Programación y Computación 1
B5: Periodo al que aplica | C5: 2S 2026
B6: Total de Puntos del Laboratorio
B8: Tipo de Actividad | C8: Ponderacion | D8: Horas utilizadas | E8: Aspectos clave que debe abordar | H8: Valor Maximo Recomendado
B9: Actividades durante el periodo de laboratorio | C9: ='S. 2'!C7+'S. 3'!C7+'S. 4'!C7+'S. 5'!C7+'S. 6'!C7+'S. 7'!C7+'S. 8'!C7+'S. 9'!C7+'S. 10'!C7+'S. 11'!C7 -> 20 | D9: ='S. 2'!$I$1+'S. 3'!$I$1+'S. 4'!$I$1+'S. 5'!$I$1+'S. 6'!$I$1+'S. 7'!$I$1+'S. 8'!$I$1+'S. 9'!$I$1+'S. 10'!$I$1+'S. 11'!$I$1 -> 200 | E9: CORTO 1 Y 2 (5 pts c/u) y FINAL (10 pts) | H9: 10
B10: Proyectos | C10: =Proyectos!C6 -> 50 | D10: =Proyectos!C5 -> 90 | E10: proyecto 1 20 pts. proyecto 2 30 pts. | H10: 60
B11: Prácticas | C11: =Practicas!C6 -> 25 | D11: =Practicas!C5 -> 40 | E11: práctica 1 10 pts. práctica 2 15 pts. | H11: 20
B12: Tareas | C12: =Tareas!C6 -> 5 | D12: =Tareas!C5 -> 9 | E12: 5 tareas (1 ptc. c/u) | H12: 10
B13: Total | C13: =SUM(C9:C12) -> 100 | D13: =SUM(D9:D12) -> 339 | E13: Validacion | F13: =IF(AND(SUM(C9:C12)=100, COUNTIF(C9:C12,"<0")=0, C9<=H9, C10<=H10, C11<=H11, C12<=H12),"✅ Distribución válida","❌ Revisar: " & IF(SUM(C9:C12)<>100,"Total ≠ 100 (actual " & SUM(C9:C12) & ") | ","") & IF(COUNTIF(C9:C12,"<0")>0,"Hay negativos | ","") & IF(OR(C9>H9,C10>H10,C11>H11,C12>H12),"Exceden: " & IF(C9>H9,B9 & " (" & C9 & ">" & H9 & ") ","") & IF(C10>H10,B10 & " (" & C10 & ">" & H10 & ") ","") & IF(C11>H11,B11 & " (" & C11 & ">" & H11 & ") ","") & IF(C12>H12,B12 & " (" & C12 & ">" & H12 & ") ",""),"")) -> ❌ Revisar: Exceden: Actividades durante el periodo de laboratorio (20>10) Prácticas (25>20)

Sheet Competencias_2S_2026
Q1: Aplica los conocimientos de su disciplina en la elaboración, fundamentación y defensa de argumentos para prevenir y resolver problemas complejos en su campo profesional, identificando y aplicando innovaciones. | R1: Aplica principios básicos de ingeniería, ciencias de computación y sistemas de información y comunicación, en la formulación y resolución adecuada de problemas complejos.
B2: Competencias que se formaran en el Segundo Semestre 2026 | Q2: Identifica oportunidades y riesgos para la innovación y adaptación de conocimientos y tecnologías para resolver problemas. | R2: Aplica estándares de calidad, eficiencia y seguridad en la implementación adecuada de soluciones de software, hardware y TIC en general.
Q3: Demuestra pensamiento crítico, actitud investigativa y rigor analítico en el planteamiento y la resolución de problemas complejos. | R3: Aplica conocimientos tecnológicos con ética profesional y respetando y cuidando los recursos naturales, humanos y financieros.
B4: Curso | C4: 770 - Introducción a la Programación y Computación 1 | Q4: Toma decisiones profesionales con base en fundamentos teóricos, datos e información pertinente, válida y confiable. | R4: Maneja e Interpreta adecuadamente datos masivos, sean estos estructurados o no estructurados, facilitando su visualización e interpretación de forma eficaz en apoyo a la toma de decisiones.
B5: Periodo al que aplica | C5: Segundo Semestre 2026 | Q5: Demuestra destreza y habilidad en la selección, uso y adaptación de herramientas metodológicas, tecnológicas, equipos especializados y en la lectura e interpretación de datos, pertinentes al contexto de su ejercicio profesional. | R5: Domina diversos recursos de comunicación con el objetivo de presentar adecuadamente sus propuestas a variados tipos de audiencias, en idioma español, inglés e idealmente en un tercer idioma acorde a las necesidades globales.
Q6: Identifica sus necesidades de actualización, capacitación y formación, durante su proceso formativo y en el ejercicio profesional, y busca los medios para cubrirlas por medios formales e informales, nacionales e internacionales, presenciales y en línea. | R6: Construye soluciones integrales trabajando en forma colaborativa y propositiva en equipos interdisciplinarios, en forma presencial o utilizando plataformas virtuales.
B7: Competencias relacionadas al perfil del egresado (Especifica) | F7: Competencias relacionadas al perfil del egresado (General) | Q7: Comunica a diversos públicos, información de su campo profesional, en varios lenguajes y formatos de manera asertiva, clara, rigurosa y precisa, con el uso apropiado de recursos tecnológicos. | R7: Actualiza permanente sus conocimientos relacionados con TIC en general, apoyándose en las estrategias de aprendizaje apropiadas.
B8: 1 | C8: Identifica oportunidades y riesgos para la innovación y adaptación de conocimientos y tecnologías para resolver problemas. | F8: 1 | G8: Actualiza permanente sus conocimientos relacionados con TIC en general, apoyándose en las estrategias de aprendizaje apropiadas. | Q8: Se comunica correctamente en su lengua oficial y utiliza una lengua extranjera con el dominio requerido para el ejercicio de su profesión.
B9: 2 | C9: Demuestra pensamiento crítico, actitud investigativa y rigor analítico en el planteamiento y la resolución de problemas complejos. | F9: 2 | G9: Construye soluciones integrales trabajando en forma colaborativa y propositiva en equipos interdisciplinarios, en forma presencial o utilizando plataformas virtuales. | Q9: Lidera y colabora proactivamente en equipos de trabajo y en comunidades profesionales para el logro de objetivos y mejoramiento de la calidad de vida.
B10: 3 | C10: Demuestra destreza y habilidad en la selección, uso y adaptación de herramientas metodológicas, tecnológicas, equipos especializados y en la lectura e interpretación de datos, pertinentes al contexto de su ejercicio profesional. | F10: 3 | G10: Maneja e Interpreta adecuadamente datos masivos, sean estos estructurados o no estructurados, facilitando su visualización e interpretación de forma eficaz en apoyo a la toma de decisiones.
B12: No | C12: Tipo | D12: Verbo en Presente | E12: Objeto de la acción | F12: [Palabras conectoreas] Herramientas o metodología | G12: [Palabras conectoreas] Condiciones específicas | H12: Nivel
B13: 1 | D13: Analiza | E13: Estructuras de datos y algoritmos | F13: Análisis de complejidad temporal | G13: Optimizar rendimiento y eficiencia | P13: =IF(TRIM(C14)="", "", C14) -> Analiza Estructuras de datos y algoritmos Análisis de complejidad temporal Optimizar rendimiento y eficiencia
C14: =D13 & " " & E13 & " " & F13 & " " & G13 -> Analiza Estructuras de datos y algoritmos Análisis de complejidad temporal Optimizar rendimiento y eficiencia
B15: 2 | D15: Implementa | E15: Sistemas de software | F15: Java, archivos y APIs | G15: Integridad y seguridad de datos | P15: =IF(TRIM(C16)="", "", C16) -> Implementa Sistemas de software Java, archivos y APIs Integridad y seguridad de datos
C16: =D15 & " " & E15 & " " & F15 & " " & G15 -> Implementa Sistemas de software Java, archivos y APIs Integridad y seguridad de datos
B17: 3 | D17: Evalúa | E17: Arquitecturas de software | F17: Patrones de diseño y testing | G17: Mantenibilidad y robustez | P17: =IF(TRIM(C18)="", "", C18) -> Evalúa Arquitecturas de software Patrones de diseño y testing Mantenibilidad y robustez
C18: =D17 & " " & E17 & " " & F17 & " " & G17 -> Evalúa Arquitecturas de software Patrones de diseño y testing Mantenibilidad y robustez
B19: 4 | D19: Diseña | E19: Interfaces gráficas (GUI) | F19: Frameworks GUI y principios UX/UI | G19: Usabilidad y accesibilidad | P19: =IF(TRIM(C20)="", "", C20) -> Diseña Interfaces gráficas (GUI) Frameworks GUI y principios UX/UI Usabilidad y accesibilidad
C20: =D19 & " " & E19 & " " & F19 & " " & G19 -> Diseña Interfaces gráficas (GUI) Frameworks GUI y principios UX/UI Usabilidad y accesibilidad
B21: 5 | D21: Colabora | E21: Proyectos de desarrollo | F21: Git y metodologías ágiles | G21: Comunicación efectiva en equipo | P21: =IF(TRIM(C22)="", "", C22) -> Colabora Proyectos de desarrollo Git y metodologías ágiles Comunicación efectiva en equipo
C22: =D21 & " " & E21 & " " & F21 & " " & G21 -> Colabora Proyectos de desarrollo Git y metodologías ágiles Comunicación efectiva en equipo
B23: 6 | P23: =IF(TRIM(C24)="", "", C24)
C24: =D23 & " " & E23 & " " & F23 & " " & G23
B25: 7 | P25: =IF(TRIM(C26)="", "", C26)
C26: =D25 & " " & E25 & " " & F25 & " " & G25
B27: 8 | P27: =IF(TRIM(C28)="", "", C28)
C28: =D27 & " " & E27 & " " & F27 & " " & G27
B31: Si las competencias son las misma que el semetre anterior compartenos tu opinion de porque no se cambiaron
B34: https://drive.google.com/drive/folders/1szLcpzkwozPD6nD4uuaiZQ3mmDRuVKVy

Sheet Contenido Curricular
B1: Contenido Curricular Introducción a la Programación y Computación 1 2S 2026
B3: Unidad | C3: Tema | D3: Subtema | E3: Mes | F3: Semana | G3: Competencia
B4: 1. Fundamentos | C4: Lógica Algorítmica | D4: Algoritmos y Diagramas | E4: Julio | F4: 2 | G4: Analiza Estructuras de datos y algoritmos Análisis de complejidad temporal Optimizar rendimiento y eficiencia
B5: 1. Fundamentos | C5: Versionamiento | D5: Herramientas de versionamiento | E5: Agosto | F5: 3 | G5: Colabora Proyectos de desarrollo Git y metodologías ágiles Comunicación efectiva en equipo
B6: 2. Java Básico | C6: Sintaxis Inicial | D6: JDK, JVM y Operadores | E6: Agosto | F6: 4 | G6: Analiza Estructuras de datos y algoritmos Análisis de complejidad temporal Optimizar rendimiento y eficiencia
B7: 2. Java Básico | C7: Estructuras | D7: Ciclos y Arreglos | E7: Agosto | F7: 5 | G7: Analiza Estructuras de datos y algoritmos Análisis de complejidad temporal Optimizar rendimiento y eficiencia
B8: 3. Avanzado | C8: Recursividad | D8: Pila de ejecución y Archivos | E8: Septiembre | F8: 6 | G8: Analiza Estructuras de datos y algoritmos Análisis de complejidad temporal Optimizar rendimiento y eficiencia
B9: 4. POO | C9: Fundamentos | D9: Clases, Objetos y Pilares | E9: Septiembre | F9: 7 | G9: Analiza Estructuras de datos y algoritmos Análisis de complejidad temporal Optimizar rendimiento y eficiencia
B10: 5. GUI y MVC | C10: Arquitectura | D10: Swing y Modelo-Vista-Controlador | E10: Septiembre | F10: 8 | G10: Evalúa Arquitecturas de software Patrones de diseño y testing Mantenibilidad y robustez
B11: 4. POO | C11: Avanzado | D11: Serialización e Hilos | E11: Octubre | F11: 9 | G11: Implementa Sistemas de software Java, archivos y APIs Integridad y seguridad de datos
B12: 5. GUI | C12: Interactividad | D12: Eventos y Layout Managers | E12: Octubre | F12: 10 | G12: Diseña Interfaces gráficas (GUI) Frameworks GUI y principios UX/UI Usabilidad y accesibilidad
B13: 6. Especializado | C13: Diseño y Nube | D13: UML y Cloud Computing | E13: Noviembre | F13: 11 | G13: Colabora Proyectos de desarrollo Git y metodologías ágiles Comunicación efectiva en equipo

Sheet Semana Diagnostico
B2: Diseño de Contenido Curricular
B4: Curso | C4: 770 - Introducción a la Programación y Computación 1
B5: Semana | C5: 1
B6: Tiempo | C6: =SUM(F8:F48) -> 95
A8: 1. Bienvenida y Presentación | E8: Tiempo Aproximado | F8: 10
E9: No puedes excederte mas de 15 minutos
A10: Nombre y Formacion Academica | B10: Experiencia laboral/docente | F10: ⬅️ | G10: Estos puntos son recomendaciones de los puntos a tratar durante tu presentacion, si no usaras estos eres libre de agregar mas filas para indicar que haras. En los recuadros de la derecha colocar breve resumen de lo que planeas decir. No debes ser muy especifico seran pequeñas anotaciones que te ayudaran a recordar lo que planeaste
A11: Experiencia docente y profesional
A12: Rol del auxiliar dentro del curso (funciones, actividades y apoyo a los estudiantes). | B12: Apoyar a los estudiantes lo más que se pueda
A13: Expectativas sobre la dinámica del curso | B13: Lo más interactiva posible
A14: Tiempo que emplearas | B14: Al menos 1 día más al designado por clase
A16: 2. Evaluación de Conocimientos Previos | E16: Tiempo Aproximado | F16: 20
E17: No puedes excederte mas de 45 minutos
A18: Redactaras de 15 a 20 preguntas con sus respectivas respuestas, por lo que debes escoger los temas que evaluaras | B18: ¿Qué característica esencial debe cumplir todo algoritmo para garantizar que no se ejecutará indefinidamente y siempre entregará un resultado? Debe ser finito (tener un inicio y un final definido). En el control de versiones con Git, ¿qué comando se utiliza para subir las confirmaciones (commits) locales hacia un repositorio remoto en la nube? El comando git push. ¿Cuál es el propósito principal de utilizar pseudocódigo antes de empezar a programar? Representar la lógica de resolución de un problema en un lenguaje estructurado pero cercano al humano, independiente de la sintaxis de un lenguaje de programación específico. ¿Qué componente de la arquitectura de Java es el encargado de interpretar el "bytecode" y traducirlo a instrucciones que el sistema operativo local pueda ejecutar, logrando así la independencia de plataforma? La Máquina Virtual de Java (JVM - Java Virtual Machine). ¿Qué estructura de control repetitiva en Java evalúa su condición al final de la iteración, garantizando que el bloque de código interno se ejecute como mínimo una vez? El ciclo do-while. En el diseño de funciones recursivas, ¿cómo se le llama a la condición obligatoria que detiene las llamadas a sí misma y previene que la memoria colapse? Caso base. ¿Qué estructura de datos dinámica (que funciona bajo el principio de "último en entrar, primero en salir" o LIFO) utiliza el sistema para llevar el registro y contexto de las funciones que se van llamando durante la ejecución? La Pila de ejecución (Call Stack). ¿Qué pilar de la Programación Orientada a Objetos se encarga de restringir el acceso directo a los atributos de una clase, obligando a interactuar con ellos mediante métodos específicos (como getters y setters)? El Encapsulamiento. ¿Cuál es la diferencia principal entre una Clase y un Objeto en la POO? Una Clase es el molde o plantilla abstracta que define atributos y comportamientos, mientras que un Objeto es una instancia concreta creada a partir de esa clase. ¿Cuál es el propósito de realizar el proceso de "Serialización" de un objeto en Java? Convertir el estado del objeto que está en la memoria a un flujo de bytes (byte stream) para poder guardarlo en un archivo o transmitirlo a través de una red. ¿Qué interfaz estándar de Java se debe implementar frecuentemente en una clase para definir la tarea que se ejecutará de forma asíncrona dentro de un nuevo Hilo (Thread)? La interfaz Runnable (mediante la implementación de su método run()). Dentro del patrón de arquitectura de software Modelo-Vista-Controlador (MVC), ¿cuál de sus componentes tiene la responsabilidad exclusiva de gestionar la lógica de negocio y el acceso a los datos? El Modelo. En el desarrollo de interfaces gráficas con Java Swing, ¿qué tipo de interfaz se utiliza para "escuchar" y reaccionar a las acciones del usuario, como hacer clic en un botón? Los Listeners (como ActionListener). ¿Para qué sirven los "Layout Managers" (Administradores de diseño) al construir ventanas en Java Swing? Sirven para organizar de forma automática y dinámica la distribución, tamaño y posición de los componentes (botones, cuadros de texto) dentro de un panel, adaptándose al tamaño de la ventana. ¿Qué tipo de diagrama UML se emplea específicamente para visualizar la estructura estática del código, mostrando las entidades del sistema, sus atributos, métodos y cómo se relacionan o heredan entre sí? El Diagrama de Clases. | F18: ⬅️ | G18: En los recuadros de la derecha deberas colocar las preguntas que planeas realizar con sus respectivas respuestas. En el segundo recuadro deberas colocar un breve resumen de lo que tienes planificado para la parte practica del curso previo al que estas impartiendo.
A19: Redactaras una parte practica | B19: Lógica booleana, aritmética básica, algoritmos en lenguaje natural.
A20: Tiempo que emplearas
A22: 3. Presentación de los Estudiantes | E22: Tiempo Aproximado | F22: 20
E23: No puedes excederte mas de 30 minutos
A24: Selección al Azar de 5 Estudiantes | B24: Método de selección aleatoria | F24: ⬅️ | G24: En el primer recuadro colocaras la metodollogia que adoptaras para la eleccion de los estudiantes. En el segundo recuadro colocaras la redaccion de las preguntas que comprendan los siguientes puntos respecto al estudiante: Nombre. Intereses y expectativas sobre el curso. Experiencia previa relacionada con el curso (si aplica). Un dato curioso sobre sí mismo. Consideras que la prueba de conocimientos previos esta acorde al conocimiento que se te brindo en su momento. Que tan comodo se sintio con la prueba anterior.
A25: Preguntas que responderan los estudiantes afortunados | B25: Qué esperan del curso, por qué están estudiando programación, y qué tanto saben sobre esta
A26: Tiempo que emplearas
A28: 4. Censo de Horarios de Calificación | E28: Tiempo Aproximado | F28: 5
E29: No puedes excederte mas de 5 minutos Esta actividad quedara abierta hasta el fin de la clase. pero emplearas 5 min especificos para la actividad
A30: Deberas estar recordando que deben contestar el formulario asi mismo dejar el link fijado en la llamada
A31: Link de google forms donde este el cuestionario | F31: ⬅️ | G31: Esta actividad te ayudara a realizar un censo de posibles horarios de calificacion y que tus estudiantes esten enterados y puedan preveer los dias de calificacion y asi mismo el horario. Deberas colocar en los recuadros de la derecha link de Google form libre para correos institucionales, esto para garantizar una sola respuesta por estudiante. Tambien deberas colocar los posibles horarios y dias que tentativamente tendrias disponibles para colocarlos en el google form.
A32: Dias y posibles Horarios de calificacion | B32: Mayormente sábados o lunes
A33: Tiempo que emplearas
A35: 5. Mostrar Programa del Curso | E35: Tiempo Aproximado | F35: 30
E36: No puedes excederte mas de 30 minutos
A37: Tiempo que emplearas
A39: 6. Evaluación de Conocimientos del Curso Actual | E39: Tiempo Aproximado | F39: 10
E40: No puedes excederte mas de 15 minutos
A41: Redactaras 20 preguntas con sus respectivas respuestas | B41: 1. ¿Qué significa JDK? 2. ¿Java es compilado o interpretado? 3. ¿Qué es un IDE? 4. Diferencia entre clase y objeto.
A42: Tiempo que emplearas
A44: 7. Tarea de fortalecimiento académico
A45: Identificar y atender brechas formativas mediante el fortalecimiento de competencias previas necesarias para el correcto desarrollo del curso.
A46: Redacta una breve idea de deberia abarcar la tarea | B46: Investigación sobre el ecosistema Java (LTS 17, 21 y 25) y configuración del entorno de desarrollo con Visual Studio Code y Docker.

Sheet S. 2
I1: =B51+IF(ISNUMBER(B62),B62,0) -> 20
B2: Diseño de la Sesión de Laboratorio
B4: Curso | C4: 770 - Introducción a la Programación y Computación 1
B5: Semana | C5: 2
B6: Tiempo | C6: =H10+H21+H45+H70 -> 113
B7: Ponderación | C7: =B50+B61 -> 0
B8: Validación de Tiempo | C8: =IF(B51<=0, "❌ ERROR: La Actividad 1 debe tener un tiempo mayor a 0.", IF(H21>60, "❌ ERROR: El 'Área de Conocimiento' no puede exceder los 60 min.", IF((H10+H21+H45)<100, "❌ ERROR: El tiempo total debe ser de al menos 100 min.", "✅ VALIDACIÓN CORRECTA"))) -> ✅ VALIDACIÓN CORRECTA
A10: 1. Área Actitudinal (Saber Ser) | G10: Tiempo | H10: 3
G11: Tiene que estar en un rango de 3 a 5 minutos
A12: Nombre del Valor | B12: Puntualidad
A13: Tiempo Aproximado | B13: 5
A14: Descripcion
A15: respeto al tiempo propio y ajeno mediante el cumplimiento de los plazos y horarios establecidos.
A17: Como se relaciona con los conocimientos de la sesion y se aplicaria
A18: La puntualidad se relaciona estrechamente con este tema porque, al igual que un algoritmo falla si sus instrucciones no se ejecutan en el momento exacto, el cumplimiento estricto de los tiempos al diseñar y entregar estos diagramas garantiza que el flujo de trabajo no se interrumpa.
A21: 2. Área Conocimiento (Saber) | G21: Tiempo | H21: 50
G22: No puede exceder los 60 minutos
A23: Competencia a desarrollar | B23: Analiza Estructuras de datos y algoritmos Análisis de complejidad temporal Optimizar rendimiento y eficiencia
A24: Competencia a desarrollar | B24: Evalúa Arquitecturas de software Patrones de diseño y testing Mantenibilidad y robustez
A26: 2.1 Contenido
A27: No. | B27: Unidad | D27: Tema | F27: Sub Tema
A28: 1 | B28: =IFERROR(__xludf.DUMMYFUNCTION("IFERROR(INDEX(FILTER('Contenido Curricular'!$B$4:$B$100, 'Contenido Curricular'!$F$4:$F$100=2), 1), """")"),"1. Fundamentos") -> 1. Fundamentos | D28: =IFERROR(__xludf.DUMMYFUNCTION("IFERROR(INDEX(FILTER('Contenido Curricular'!$C$4:$C$100, 'Contenido Curricular'!$F$4:$F$100=2), 1), """")"),"Lógica Algorítmica") -> Lógica Algorítmica | F28: =IFERROR(__xludf.DUMMYFUNCTION("IFERROR(INDEX(FILTER('Contenido Curricular'!$D$4:$D$100, 'Contenido Curricular'!$F$4:$F$100=2), 1), """")"),"Algoritmos y Diagramas") -> Algoritmos y Diagramas
A29: 2 | B29: =IFERROR(__xludf.DUMMYFUNCTION("IFERROR(INDEX(FILTER('Contenido Curricular'!$B$4:$B$100, 'Contenido Curricular'!$F$4:$F$100=2), 2), """")"),"") | D29: =IFERROR(__xludf.DUMMYFUNCTION("IFERROR(INDEX(FILTER('Contenido Curricular'!$C$4:$C$100, 'Contenido Curricular'!$F$4:$F$100=2), 2), """")"),"") | F29: =IFERROR(__xludf.DUMMYFUNCTION("IFERROR(INDEX(FILTER('Contenido Curricular'!$D$4:$D$100, 'Contenido Curricular'!$F$4:$F$100=2), 2), """")"),"")
A30: 3 | B30: =IFERROR(__xludf.DUMMYFUNCTION("IFERROR(INDEX(FILTER('Contenido Curricular'!$B$4:$B$100, 'Contenido Curricular'!$F$4:$F$100=2), 3), """")"),"") | D30: =IFERROR(__xludf.DUMMYFUNCTION("IFERROR(INDEX(FILTER('Contenido Curricular'!$C$4:$C$100, 'Contenido Curricular'!$F$4:$F$100=2), 3), """")"),"") | F30: =IFERROR(__xludf.DUMMYFUNCTION("IFERROR(INDEX(FILTER('Contenido Curricular'!$D$4:$D$100, 'Contenido Curricular'!$F$4:$F$100=2), 3), """")"),"")
A31: 4 | B31: =IFERROR(__xludf.DUMMYFUNCTION("IFERROR(INDEX(FILTER('Contenido Curricular'!$B$4:$B$100, 'Contenido Curricular'!$F$4:$F$100=2), 4), """")"),"") | D31: =IFERROR(__xludf.DUMMYFUNCTION("IFERROR(INDEX(FILTER('Contenido Curricular'!$C$4:$C$100, 'Contenido Curricular'!$F$4:$F$100=2), 4), """")"),"") | F31: =IFERROR(__xludf.DUMMYFUNCTION("IFERROR(INDEX(FILTER('Contenido Curricular'!$D$4:$D$100, 'Contenido Curricular'!$F$4:$F$100=2), 4), """")"),"")
A32: 5 | B32: =IFERROR(__xludf.DUMMYFUNCTION("IFERROR(INDEX(FILTER('Contenido Curricular'!$B$4:$B$100, 'Contenido Curricular'!$F$4:$F$100=2), 5), """")"),"") | D32: =IFERROR(__xludf.DUMMYFUNCTION("IFERROR(INDEX(FILTER('Contenido Curricular'!$C$4:$C$100, 'Contenido Curricular'!$F$4:$F$100=2), 5), """")"),"") | F32: =IFERROR(__xludf.DUMMYFUNCTION("IFERROR(INDEX(FILTER('Contenido Curricular'!$D$4:$D$100, 'Contenido Curricular'!$F$4:$F$100=2), 5), """")"),"")
A33: 6 | B33: =IFERROR(__xludf.DUMMYFUNCTION("IFERROR(INDEX(FILTER('Contenido Curricular'!$B$4:$B$100, 'Contenido Curricular'!$F$4:$F$100=2), 6), """")"),"") | D33: =IFERROR(__xludf.DUMMYFUNCTION("IFERROR(INDEX(FILTER('Contenido Curricular'!$C$4:$C$100, 'Contenido Curricular'!$F$4:$F$100=2), 6), """")"),"") | F33: =IFERROR(__xludf.DUMMYFUNCTION("IFERROR(INDEX(FILTER('Contenido Curricular'!$D$4:$D$100, 'Contenido Curricular'!$F$4:$F$100=2), 6), """")"),"")
A34: 7 | B34: =IFERROR(__xludf.DUMMYFUNCTION("IFERROR(INDEX(FILTER('Contenido Curricular'!$B$4:$B$100, 'Contenido Curricular'!$F$4:$F$100=2), 7), """")"),"") | D34: =IFERROR(__xludf.DUMMYFUNCTION("IFERROR(INDEX(FILTER('Contenido Curricular'!$C$4:$C$100, 'Contenido Curricular'!$F$4:$F$100=2), 7), """")"),"") | F34: =IFERROR(__xludf.DUMMYFUNCTION("IFERROR(INDEX(FILTER('Contenido Curricular'!$D$4:$D$100, 'Contenido Curricular'!$F$4:$F$100=2), 7), """")"),"")
A35: 8 | B35: =IFERROR(__xludf.DUMMYFUNCTION("IFERROR(INDEX(FILTER('Contenido Curricular'!$B$4:$B$100, 'Contenido Curricular'!$F$4:$F$100=2), 8), """")"),"") | D35: =IFERROR(__xludf.DUMMYFUNCTION("IFERROR(INDEX(FILTER('Contenido Curricular'!$C$4:$C$100, 'Contenido Curricular'!$F$4:$F$100=2), 8), """")"),"") | F35: =IFERROR(__xludf.DUMMYFUNCTION("IFERROR(INDEX(FILTER('Contenido Curricular'!$D$4:$D$100, 'Contenido Curricular'!$F$4:$F$100=2), 8), """")"),"")
A36: 9 | B36: =IFERROR(__xludf.DUMMYFUNCTION("IFERROR(INDEX(FILTER('Contenido Curricular'!$B$4:$B$100, 'Contenido Curricular'!$F$4:$F$100=2), 9), """")"),"") | D36: =IFERROR(__xludf.DUMMYFUNCTION("IFERROR(INDEX(FILTER('Contenido Curricular'!$C$4:$C$100, 'Contenido Curricular'!$F$4:$F$100=2), 9), """")"),"") | F36: =IFERROR(__xludf.DUMMYFUNCTION("IFERROR(INDEX(FILTER('Contenido Curricular'!$D$4:$D$100, 'Contenido Curricular'!$F$4:$F$100=2), 9), """")"),"")
A37: 10 | B37: =IFERROR(__xludf.DUMMYFUNCTION("IFERROR(INDEX(FILTER('Contenido Curricular'!$B$4:$B$100, 'Contenido Curricular'!$F$4:$F$100=2), 10), """")"),"") | D37: =IFERROR(__xludf.DUMMYFUNCTION("IFERROR(INDEX(FILTER('Contenido Curricular'!$C$4:$C$100, 'Contenido Curricular'!$F$4:$F$100=2), 10), """")"),"") | F37: =IFERROR(__xludf.DUMMYFUNCTION("IFERROR(INDEX(FILTER('Contenido Curricular'!$D$4:$D$100, 'Contenido Curricular'!$F$4:$F$100=2), 10), """")"),"")
A38: 2.2 Recursos Educativos
A39: Tipo de Recurso a utilizar | C39: Tipo | E39: Rango Aproximando | G39: Tiempo Aproximado
A40: Presentacion | C40: Obligatorio | E40: 15-25 minutos | G40: 15
A41: Video | C41: Obligatorio | E41: 3 a 6 minutos | G41: 4
A42: Lectura | C42: Optativo | E42: 3-5 minutos | G42: 4
A43: Ejercicio Demostrativo | C43: Obligatorio | E43: 20-25 minutos | G43: 20
A45: 3. Área de Habilidades (Saber Hacer) | G45: Tiempo | H45: 50
G46: Tiene que estar en un rango de 30 a 50 minutos
A47: Actividad 1 (Obligatoria)
...

Sheet S. 3
I1: =B51+IF(ISNUMBER(B62),B62,0) -> 20
B2: Diseño de la Sesión de Laboratorio
B4: Curso | C4: 770 - Introducción a la Programación y Computación 1
B5: Semana | C5: 3
B6: Tiempo | C6: =H10+H21+H45+H70 -> 113
B7: Ponderación | C7: =B50+B61 -> 0
B8: Validación de Tiempo | C8: =IF(B51<=0, "❌ ERROR: La Actividad 1 debe tener un tiempo mayor a 0.", IF(H21>60, "❌ ERROR: El 'Área de Conocimiento' no puede exceder los 60 min.", IF((H10+H21+H45)<100, "❌ ERROR: El tiempo total debe ser de al menos 100 min.", "✅ VALIDACIÓN CORRECTA"))) -> ✅ VALIDACIÓN CORRECTA
A10: 1. Área Actitudinal (Saber Ser) | G10: Tiempo | H10: 3
G11: Tiene que estar en un rango de 3 a 5 minutos
A12: Nombre del Valor | B12: Responsabilidad
A13: Tiempo Aproximado
A14: Descripcion
A15: La sesión aborda los fundamentos del control de versiones colaborativo utilizando Git, la estructuración de la lógica mediante pseudocódigo y las bases para trabajar en equipo integrando metodologías ágiles y arquitecturas de software robustas.
A17: Como se relaciona con los conocimientos de la sesion y se aplicaria
A18: El valor de la responsabilidad se relaciona directamente con estos temas porque, al interactuar en un repositorio de código compartido, cada desarrollador tiene el deber de asegurar que sus aportes no afecten el trabajo de los demás; esto se aplica en la práctica revisando y probando minuciosamente el código antes de realizar un "commit", documentando los cambios con claridad y asumiendo el compromiso de mantener la calidad e integridad del proyecto de todo el equipo.
A21: 2. Área Conocimiento (Saber) | G21: Tiempo | H21: 50
G22: No puede exceder los 60 minutos
A23: Competencia a desarrollar | B23: Colabora Proyectos de desarrollo Git y metodologías ágiles Comunicación efectiva en equipo
A24: Competencia a desarrollar | B24: Evalúa Arquitecturas de software Patrones de diseño y testing Mantenibilidad y robustez
A26: 2.1 Contenido
A27: No. | B27: Unidad | D27: Tema | F27: Sub Tema
A28: 1 | B28: =IFERROR(__xludf.DUMMYFUNCTION("IFERROR(INDEX(FILTER('Contenido Curricular'!$B$4:$B$100, 'Contenido Curricular'!$F$4:$F$100=3), 1), """")"),"1. Fundamentos") -> 1. Fundamentos | D28: =IFERROR(__xludf.DUMMYFUNCTION("IFERROR(INDEX(FILTER('Contenido Curricular'!$C$4:$C$100, 'Contenido Curricular'!$F$4:$F$100=3), 1), """")"),"Versionamiento") -> Versionamiento | F28: =IFERROR(__xludf.DUMMYFUNCTION("IFERROR(INDEX(FILTER('Contenido Curricular'!$D$4:$D$100, 'Contenido Curricular'!$F$4:$F$100=3), 1), """")"),"Herramientas de versionamiento") -> Herramientas de versionamiento
A29: 2 | D29: =IFERROR(__xludf.DUMMYFUNCTION("IFERROR(INDEX(FILTER('Contenido Curricular'!$C$4:$C$100, 'Contenido Curricular'!$F$4:$F$100=3), 2), """")"),"") | F29: =IFERROR(__xludf.DUMMYFUNCTION("IFERROR(INDEX(FILTER('Contenido Curricular'!$D$4:$D$100, 'Contenido Curricular'!$F$4:$F$100=3), 2), """")"),"")
A30: 3 | B30: =IFERROR(__xludf.DUMMYFUNCTION("IFERROR(INDEX(FILTER('Contenido Curricular'!$B$4:$B$100, 'Contenido Curricular'!$F$4:$F$100=3), 3), """")"),"") | D30: =IFERROR(__xludf.DUMMYFUNCTION("IFERROR(INDEX(FILTER('Contenido Curricular'!$C$4:$C$100, 'Contenido Curricular'!$F$4:$F$100=3), 3), """")"),"") | F30: =IFERROR(__xludf.DUMMYFUNCTION("IFERROR(INDEX(FILTER('Contenido Curricular'!$D$4:$D$100, 'Contenido Curricular'!$F$4:$F$100=3), 3), """")"),"")
A31: 4 | B31: =IFERROR(__xludf.DUMMYFUNCTION("IFERROR(INDEX(FILTER('Contenido Curricular'!$B$4:$B$100, 'Contenido Curricular'!$F$4:$F$100=3), 4), """")"),"") | D31: =IFERROR(__xludf.DUMMYFUNCTION("IFERROR(INDEX(FILTER('Contenido Curricular'!$C$4:$C$100, 'Contenido Curricular'!$F$4:$F$100=3), 4), """")"),"") | F31: =IFERROR(__xludf.DUMMYFUNCTION("IFERROR(INDEX(FILTER('Contenido Curricular'!$D$4:$D$100, 'Contenido Curricular'!$F$4:$F$100=3), 4), """")"),"")
A32: 5 | B32: =IFERROR(__xludf.DUMMYFUNCTION("IFERROR(INDEX(FILTER('Contenido Curricular'!$B$4:$B$100, 'Contenido Curricular'!$F$4:$F$100=3), 5), """")"),"") | D32: =IFERROR(__xludf.DUMMYFUNCTION("IFERROR(INDEX(FILTER('Contenido Curricular'!$C$4:$C$100, 'Contenido Curricular'!$F$4:$F$100=3), 5), """")"),"") | F32: =IFERROR(__xludf.DUMMYFUNCTION("IFERROR(INDEX(FILTER('Contenido Curricular'!$D$4:$D$100, 'Contenido Curricular'!$F$4:$F$100=3), 5), """")"),"")
A33: 6 | B33: =IFERROR(__xludf.DUMMYFUNCTION("IFERROR(INDEX(FILTER('Contenido Curricular'!$B$4:$B$100, 'Contenido Curricular'!$F$4:$F$100=3), 6), """")"),"") | D33: =IFERROR(__xludf.DUMMYFUNCTION("IFERROR(INDEX(FILTER('Contenido Curricular'!$C$4:$C$100, 'Contenido Curricular'!$F$4:$F$100=3), 6), """")"),"") | F33: =IFERROR(__xludf.DUMMYFUNCTION("IFERROR(INDEX(FILTER('Contenido Curricular'!$D$4:$D$100, 'Contenido Curricular'!$F$4:$F$100=3), 6), """")"),"")
A34: 7 | B34: =IFERROR(__xludf.DUMMYFUNCTION("IFERROR(INDEX(FILTER('Contenido Curricular'!$B$4:$B$100, 'Contenido Curricular'!$F$4:$F$100=3), 7), """")"),"") | D34: =IFERROR(__xludf.DUMMYFUNCTION("IFERROR(INDEX(FILTER('Contenido Curricular'!$C$4:$C$100, 'Contenido Curricular'!$F$4:$F$100=3), 7), """")"),"") | F34: =IFERROR(__xludf.DUMMYFUNCTION("IFERROR(INDEX(FILTER('Contenido Curricular'!$D$4:$D$100, 'Contenido Curricular'!$F$4:$F$100=3), 7), """")"),"")
A35: 8 | B35: =IFERROR(__xludf.DUMMYFUNCTION("IFERROR(INDEX(FILTER('Contenido Curricular'!$B$4:$B$100, 'Contenido Curricular'!$F$4:$F$100=3), 8), """")"),"") | D35: =IFERROR(__xludf.DUMMYFUNCTION("IFERROR(INDEX(FILTER('Contenido Curricular'!$C$4:$C$100, 'Contenido Curricular'!$F$4:$F$100=3), 8), """")"),"") | F35: =IFERROR(__xludf.DUMMYFUNCTION("IFERROR(INDEX(FILTER('Contenido Curricular'!$D$4:$D$100, 'Contenido Curricular'!$F$4:$F$100=3), 8), """")"),"")
A36: 9 | B36: =IFERROR(__xludf.DUMMYFUNCTION("IFERROR(INDEX(FILTER('Contenido Curricular'!$B$4:$B$100, 'Contenido Curricular'!$F$4:$F$100=3), 9), """")"),"") | D36: =IFERROR(__xludf.DUMMYFUNCTION("IFERROR(INDEX(FILTER('Contenido Curricular'!$C$4:$C$100, 'Contenido Curricular'!$F$4:$F$100=3), 9), """")"),"") | F36: =IFERROR(__xludf.DUMMYFUNCTION("IFERROR(INDEX(FILTER('Contenido Curricular'!$D$4:$D$100, 'Contenido Curricular'!$F$4:$F$100=3), 9), """")"),"")
A37: 10 | B37: =IFERROR(__xludf.DUMMYFUNCTION("IFERROR(INDEX(FILTER('Contenido Curricular'!$B$4:$B$100, 'Contenido Curricular'!$F$4:$F$100=3), 10), """")"),"") | D37: =IFERROR(__xludf.DUMMYFUNCTION("IFERROR(INDEX(FILTER('Contenido Curricular'!$C$4:$C$100, 'Contenido Curricular'!$F$4:$F$100=3), 10), """")"),"") | F37: =IFERROR(__xludf.DUMMYFUNCTION("IFERROR(INDEX(FILTER('Contenido Curricular'!$D$4:$D$100, 'Contenido Curricular'!$F$4:$F$100=3), 10), """")"),"")
A38: 2.2 Recursos Educativos
A39: Tipo de Recurso a utilizar | C39: Tipo | E39: Rango Aproximando | G39: Tiempo Aproximado
A40: Presentacion | C40: Obligatorio | E40: 15-25 minutos | G40: 15
A41: Video | C41: Obligatorio | E41: 3 a 6 minutos | G41: 4
A42: Lectura | C42: Optativo | E42: 3-5 minutos | G42: 4
A43: Ejercicio Demostrativo | C43: Obligatorio | E43: 20-25 minutos | G43: 20
A45: 3. Área de Habilidades (Saber Hacer) | G45: Tiempo | H45: 50
G46: Tiene que estar en un rango de 30 a 50 minutos
A47: Actividad 1 (Obligatoria)
...

Sheet S. 4
I1: =B51+IF(ISNUMBER(B62),B62,0) -> 20
B2: Diseño de la Sesión de Laboratorio
B4: Curso | C4: 770 - Introducción a la Programación y Computación 1
B5: Semana | C5: 4
B6: Tiempo | C6: =H10+H21+H45+H70 -> 113
B7: Ponderación | C7: =B50+B61 -> 5
B8: Validación de Tiempo | C8: =IF(B51<=0, "❌ ERROR: La Actividad 1 debe tener un tiempo mayor a 0.", IF(H21>60, "❌ ERROR: El 'Área de Conocimiento' no puede exceder los 60 min.", IF((H10+H21+H45)<100, "❌ ERROR: El tiempo total debe ser de al menos 100 min.", "✅ VALIDACIÓN CORRECTA"))) -> ✅ VALIDACIÓN CORRECTA
A10: 1. Área Actitudinal (Saber Ser) | G10: Tiempo | H10: 3
G11: Tiene que estar en un rango de 3 a 5 minutos
A12: Nombre del Valor | B12: Disciplina
A13: Tiempo Aproximado
A14: Descripcion
A15: La sesión aborda los conceptos iniciales de la sintaxis de programación en Java, enfocándose en el uso de operadores y en comprender el funcionamiento de herramientas fundamentales como el JDK (Java Development Kit) y la JVM (Java Virtual Machine) para la futura implementación de sistemas de software seguros.
A17: Como se relaciona con los conocimientos de la sesion y se aplicaria
A18: El valor de la disciplina se relaciona íntimamente con estos temas porque dominar un lenguaje estructurado y estricto como Java exige constancia y gran atención al detalle; en la práctica, esto se aplicaría fomentando el seguimiento riguroso de las reglas de sintaxis, la escritura ordenada del código desde los primeros ejercicios y el hábito de revisar meticulosamente las operaciones para evitar errores de compilación.
A21: 2. Área Conocimiento (Saber) | G21: Tiempo | H21: 50
G22: No puede exceder los 60 minutos
A23: Competencia a desarrollar | B23: Analiza Estructuras de datos y algoritmos Análisis de complejidad temporal Optimizar rendimiento y eficiencia
A24: Competencia a desarrollar | B24: Implementa Sistemas de software Java, archivos y APIs Integridad y seguridad de datos
A26: 2.1 Contenido
A27: No. | B27: Unidad | D27: Tema | F27: Sub Tema
A28: 1 | B28: =IFERROR(__xludf.DUMMYFUNCTION("IFERROR(INDEX(FILTER('Contenido Curricular'!$B$4:$B$100, 'Contenido Curricular'!$F$4:$F$100=4), 1), """")"),"2. Java Básico") -> 2. Java Básico | D28: =IFERROR(__xludf.DUMMYFUNCTION("IFERROR(INDEX(FILTER('Contenido Curricular'!$C$4:$C$100, 'Contenido Curricular'!$F$4:$F$100=4), 1), """")"),"Sintaxis Inicial") -> Sintaxis Inicial | F28: =IFERROR(__xludf.DUMMYFUNCTION("IFERROR(INDEX(FILTER('Contenido Curricular'!$D$4:$D$100, 'Contenido Curricular'!$F$4:$F$100=4), 1), """")"),"JDK, JVM y Operadores") -> JDK, JVM y Operadores
A29: 2 | B29: =IFERROR(__xludf.DUMMYFUNCTION("IFERROR(INDEX(FILTER('Contenido Curricular'!$B$4:$B$100, 'Contenido Curricular'!$F$4:$F$100=4), 2), """")"),"") | D29: =IFERROR(__xludf.DUMMYFUNCTION("IFERROR(INDEX(FILTER('Contenido Curricular'!$C$4:$C$100, 'Contenido Curricular'!$F$4:$F$100=4), 2), """")"),"") | F29: =IFERROR(__xludf.DUMMYFUNCTION("IFERROR(INDEX(FILTER('Contenido Curricular'!$D$4:$D$100, 'Contenido Curricular'!$F$4:$F$100=4), 2), """")"),"")
A30: 3 | B30: =IFERROR(__xludf.DUMMYFUNCTION("IFERROR(INDEX(FILTER('Contenido Curricular'!$B$4:$B$100, 'Contenido Curricular'!$F$4:$F$100=4), 3), """")"),"") | D30: =IFERROR(__xludf.DUMMYFUNCTION("IFERROR(INDEX(FILTER('Contenido Curricular'!$C$4:$C$100, 'Contenido Curricular'!$F$4:$F$100=4), 3), """")"),"") | F30: =IFERROR(__xludf.DUMMYFUNCTION("IFERROR(INDEX(FILTER('Contenido Curricular'!$D$4:$D$100, 'Contenido Curricular'!$F$4:$F$100=4), 3), """")"),"")
A31: 4 | B31: =IFERROR(__xludf.DUMMYFUNCTION("IFERROR(INDEX(FILTER('Contenido Curricular'!$B$4:$B$100, 'Contenido Curricular'!$F$4:$F$100=4), 4), """")"),"") | D31: =IFERROR(__xludf.DUMMYFUNCTION("IFERROR(INDEX(FILTER('Contenido Curricular'!$C$4:$C$100, 'Contenido Curricular'!$F$4:$F$100=4), 4), """")"),"") | F31: =IFERROR(__xludf.DUMMYFUNCTION("IFERROR(INDEX(FILTER('Contenido Curricular'!$D$4:$D$100, 'Contenido Curricular'!$F$4:$F$100=4), 4), """")"),"")
A32: 5 | B32: =IFERROR(__xludf.DUMMYFUNCTION("IFERROR(INDEX(FILTER('Contenido Curricular'!$B$4:$B$100, 'Contenido Curricular'!$F$4:$F$100=4), 5), """")"),"") | D32: =IFERROR(__xludf.DUMMYFUNCTION("IFERROR(INDEX(FILTER('Contenido Curricular'!$C$4:$C$100, 'Contenido Curricular'!$F$4:$F$100=4), 5), """")"),"") | F32: =IFERROR(__xludf.DUMMYFUNCTION("IFERROR(INDEX(FILTER('Contenido Curricular'!$D$4:$D$100, 'Contenido Curricular'!$F$4:$F$100=4), 5), """")"),"")
A33: 6 | B33: =IFERROR(__xludf.DUMMYFUNCTION("IFERROR(INDEX(FILTER('Contenido Curricular'!$B$4:$B$100, 'Contenido Curricular'!$F$4:$F$100=4), 6), """")"),"") | D33: =IFERROR(__xludf.DUMMYFUNCTION("IFERROR(INDEX(FILTER('Contenido Curricular'!$C$4:$C$100, 'Contenido Curricular'!$F$4:$F$100=4), 6), """")"),"") | F33: =IFERROR(__xludf.DUMMYFUNCTION("IFERROR(INDEX(FILTER('Contenido Curricular'!$D$4:$D$100, 'Contenido Curricular'!$F$4:$F$100=4), 6), """")"),"")
A34: 7 | B34: =IFERROR(__xludf.DUMMYFUNCTION("IFERROR(INDEX(FILTER('Contenido Curricular'!$B$4:$B$100, 'Contenido Curricular'!$F$4:$F$100=4), 7), """")"),"") | D34: =IFERROR(__xludf.DUMMYFUNCTION("IFERROR(INDEX(FILTER('Contenido Curricular'!$C$4:$C$100, 'Contenido Curricular'!$F$4:$F$100=4), 7), """")"),"") | F34: =IFERROR(__xludf.DUMMYFUNCTION("IFERROR(INDEX(FILTER('Contenido Curricular'!$D$4:$D$100, 'Contenido Curricular'!$F$4:$F$100=4), 7), """")"),"")
A35: 8 | B35: =IFERROR(__xludf.DUMMYFUNCTION("IFERROR(INDEX(FILTER('Contenido Curricular'!$B$4:$B$100, 'Contenido Curricular'!$F$4:$F$100=4), 8), """")"),"") | D35: =IFERROR(__xludf.DUMMYFUNCTION("IFERROR(INDEX(FILTER('Contenido Curricular'!$C$4:$C$100, 'Contenido Curricular'!$F$4:$F$100=4), 8), """")"),"") | F35: =IFERROR(__xludf.DUMMYFUNCTION("IFERROR(INDEX(FILTER('Contenido Curricular'!$D$4:$D$100, 'Contenido Curricular'!$F$4:$F$100=4), 8), """")"),"")
A36: 9 | B36: =IFERROR(__xludf.DUMMYFUNCTION("IFERROR(INDEX(FILTER('Contenido Curricular'!$B$4:$B$100, 'Contenido Curricular'!$F$4:$F$100=4), 9), """")"),"") | D36: =IFERROR(__xludf.DUMMYFUNCTION("IFERROR(INDEX(FILTER('Contenido Curricular'!$C$4:$C$100, 'Contenido Curricular'!$F$4:$F$100=4), 9), """")"),"") | F36: =IFERROR(__xludf.DUMMYFUNCTION("IFERROR(INDEX(FILTER('Contenido Curricular'!$D$4:$D$100, 'Contenido Curricular'!$F$4:$F$100=4), 9), """")"),"")
A37: 10 | B37: =IFERROR(__xludf.DUMMYFUNCTION("IFERROR(INDEX(FILTER('Contenido Curricular'!$B$4:$B$100, 'Contenido Curricular'!$F$4:$F$100=4), 10), """")"),"") | D37: =IFERROR(__xludf.DUMMYFUNCTION("IFERROR(INDEX(FILTER('Contenido Curricular'!$C$4:$C$100, 'Contenido Curricular'!$F$4:$F$100=4), 10), """")"),"") | F37: =IFERROR(__xludf.DUMMYFUNCTION("IFERROR(INDEX(FILTER('Contenido Curricular'!$D$4:$D$100, 'Contenido Curricular'!$F$4:$F$100=4), 10), """")"),"")
A38: 2.2 Recursos Educativos
A39: Tipo de Recurso a utilizar | C39: Tipo | E39: Rango Aproximando | G39: Tiempo Aproximado
A40: Presentacion | C40: Obligatorio | E40: 15-25 minutos | G40: 15
A41: Video | C41: Obligatorio | E41: 3 a 6 minutos | G41: 4
A42: Lectura | C42: Optativo | E42: 3-5 minutos | G42: 4
A43: Ejercicio Demostrativo | C43: Obligatorio | E43: 20-25 minutos | G43: 20
A45: 3. Área de Habilidades (Saber Hacer) | G45: Tiempo | H45: 50
G46: Tiene que estar en un rango de 30 a 50 minutos
A47: Actividad 1 (Obligatoria)
...

Sheet S. 5
I1: =B51+IF(ISNUMBER(B62),B62,0) -> 20
B2: Diseño de la Sesión de Laboratorio
B4: Curso | C4: 770 - Introducción a la Programación y Computación 1
B5: Semana | C5: 5
B6: Tiempo | C6: =H10+H21+H45+H70 -> 113
B7: Ponderación | C7: =B50+B61 -> 0
B8: Validación de Tiempo | C8: =IF(B51<=0, "❌ ERROR: La Actividad 1 debe tener un tiempo mayor a 0.", IF(H21>60, "❌ ERROR: El 'Área de Conocimiento' no puede exceder los 60 min.", IF((H10+H21+H45)<100, "❌ ERROR: El tiempo total debe ser de al menos 100 min.", "✅ VALIDACIÓN CORRECTA"))) -> ✅ VALIDACIÓN CORRECTA
A10: 1. Área Actitudinal (Saber Ser) | G10: Tiempo | H10: 3
G11: Tiene que estar en un rango de 3 a 5 minutos
A12: Nombre del Valor | B12: Honestidad
A13: Tiempo Aproximado
A14: Descripcion
A15: La sesión aborda el uso de estructuras de almacenamiento fundamentales como los arreglos (arrays) y las estructuras de control repetitivas (ciclos) en Java, los cuales son esenciales para recorrer, procesar y gestionar eficientemente colecciones de datos en el desarrollo de sistemas.
A17: Como se relaciona con los conocimientos de la sesion y se aplicaria
A18: El valor de la honestidad se relaciona directamente con la integridad en el manejo de la información; en la práctica, esto se aplicaría fomentando que el desarrollador no altere, falsifique u oculte datos dentro de un arreglo para forzar que un programa funcione, y que tenga la transparencia de reconocer y corregir errores lógicos (como desbordamientos de memoria o índices incorrectos en un ciclo) en lugar de ignorarlos, garantizando así la seguridad y fiabilidad del software.
A21: 2. Área Conocimiento (Saber) | G21: Tiempo | H21: 50
G22: No puede exceder los 60 minutos
A23: Competencia a desarrollar | B23: Implementa Sistemas de software Java, archivos y APIs Integridad y seguridad de datos
A24: Competencia a desarrollar | B24: Evalúa Arquitecturas de software Patrones de diseño y testing Mantenibilidad y robustez
A26: 2.1 Contenido
A27: No. | B27: Unidad | D27: Tema | F27: Sub Tema
A28: 1 | B28: =IFERROR(__xludf.DUMMYFUNCTION("IFERROR(INDEX(FILTER('Contenido Curricular'!$B$4:$B$100, 'Contenido Curricular'!$F$4:$F$100=5), 1), """")"),"2. Java Básico") -> 2. Java Básico | D28: =IFERROR(__xludf.DUMMYFUNCTION("IFERROR(INDEX(FILTER('Contenido Curricular'!$C$4:$C$100, 'Contenido Curricular'!$F$4:$F$100=5), 1), """")"),"Estructuras") -> Estructuras | F28: =IFERROR(__xludf.DUMMYFUNCTION("IFERROR(INDEX(FILTER('Contenido Curricular'!$D$4:$D$100, 'Contenido Curricular'!$F$4:$F$100=5), 1), """")"),"Ciclos y Arreglos") -> Ciclos y Arreglos
A29: 2 | B29: =IFERROR(__xludf.DUMMYFUNCTION("IFERROR(INDEX(FILTER('Contenido Curricular'!$B$4:$B$100, 'Contenido Curricular'!$F$4:$F$100=5), 2), """")"),"") | D29: =IFERROR(__xludf.DUMMYFUNCTION("IFERROR(INDEX(FILTER('Contenido Curricular'!$C$4:$C$100, 'Contenido Curricular'!$F$4:$F$100=5), 2), """")"),"") | F29: =IFERROR(__xludf.DUMMYFUNCTION("IFERROR(INDEX(FILTER('Contenido Curricular'!$D$4:$D$100, 'Contenido Curricular'!$F$4:$F$100=5), 2), """")"),"")
A30: 3 | B30: =IFERROR(__xludf.DUMMYFUNCTION("IFERROR(INDEX(FILTER('Contenido Curricular'!$B$4:$B$100, 'Contenido Curricular'!$F$4:$F$100=5), 3), """")"),"") | D30: =IFERROR(__xludf.DUMMYFUNCTION("IFERROR(INDEX(FILTER('Contenido Curricular'!$C$4:$C$100, 'Contenido Curricular'!$F$4:$F$100=5), 3), """")"),"") | F30: =IFERROR(__xludf.DUMMYFUNCTION("IFERROR(INDEX(FILTER('Contenido Curricular'!$D$4:$D$100, 'Contenido Curricular'!$F$4:$F$100=5), 3), """")"),"")
A31: 4 | B31: =IFERROR(__xludf.DUMMYFUNCTION("IFERROR(INDEX(FILTER('Contenido Curricular'!$B$4:$B$100, 'Contenido Curricular'!$F$4:$F$100=5), 4), """")"),"") | D31: =IFERROR(__xludf.DUMMYFUNCTION("IFERROR(INDEX(FILTER('Contenido Curricular'!$C$4:$C$100, 'Contenido Curricular'!$F$4:$F$100=5), 4), """")"),"") | F31: =IFERROR(__xludf.DUMMYFUNCTION("IFERROR(INDEX(FILTER('Contenido Curricular'!$D$4:$D$100, 'Contenido Curricular'!$F$4:$F$100=5), 4), """")"),"")
A32: 5 | B32: =IFERROR(__xludf.DUMMYFUNCTION("IFERROR(INDEX(FILTER('Contenido Curricular'!$B$4:$B$100, 'Contenido Curricular'!$F$4:$F$100=5), 5), """")"),"") | D32: =IFERROR(__xludf.DUMMYFUNCTION("IFERROR(INDEX(FILTER('Contenido Curricular'!$C$4:$C$100, 'Contenido Curricular'!$F$4:$F$100=5), 5), """")"),"") | F32: =IFERROR(__xludf.DUMMYFUNCTION("IFERROR(INDEX(FILTER('Contenido Curricular'!$D$4:$D$100, 'Contenido Curricular'!$F$4:$F$100=5), 5), """")"),"")
A33: 6 | B33: =IFERROR(__xludf.DUMMYFUNCTION("IFERROR(INDEX(FILTER('Contenido Curricular'!$B$4:$B$100, 'Contenido Curricular'!$F$4:$F$100=5), 6), """")"),"") | D33: =IFERROR(__xludf.DUMMYFUNCTION("IFERROR(INDEX(FILTER('Contenido Curricular'!$C$4:$C$100, 'Contenido Curricular'!$F$4:$F$100=5), 6), """")"),"") | F33: =IFERROR(__xludf.DUMMYFUNCTION("IFERROR(INDEX(FILTER('Contenido Curricular'!$D$4:$D$100, 'Contenido Curricular'!$F$4:$F$100=5), 6), """")"),"")
A34: 7 | B34: =IFERROR(__xludf.DUMMYFUNCTION("IFERROR(INDEX(FILTER('Contenido Curricular'!$B$4:$B$100, 'Contenido Curricular'!$F$4:$F$100=5), 7), """")"),"") | D34: =IFERROR(__xludf.DUMMYFUNCTION("IFERROR(INDEX(FILTER('Contenido Curricular'!$C$4:$C$100, 'Contenido Curricular'!$F$4:$F$100=5), 7), """")"),"") | F34: =IFERROR(__xludf.DUMMYFUNCTION("IFERROR(INDEX(FILTER('Contenido Curricular'!$D$4:$D$100, 'Contenido Curricular'!$F$4:$F$100=5), 7), """")"),"")
A35: 8 | B35: =IFERROR(__xludf.DUMMYFUNCTION("IFERROR(INDEX(FILTER('Contenido Curricular'!$B$4:$B$100, 'Contenido Curricular'!$F$4:$F$100=5), 8), """")"),"") | D35: =IFERROR(__xludf.DUMMYFUNCTION("IFERROR(INDEX(FILTER('Contenido Curricular'!$C$4:$C$100, 'Contenido Curricular'!$F$4:$F$100=5), 8), """")"),"") | F35: =IFERROR(__xludf.DUMMYFUNCTION("IFERROR(INDEX(FILTER('Contenido Curricular'!$D$4:$D$100, 'Contenido Curricular'!$F$4:$F$100=5), 8), """")"),"")
A36: 9 | B36: =IFERROR(__xludf.DUMMYFUNCTION("IFERROR(INDEX(FILTER('Contenido Curricular'!$B$4:$B$100, 'Contenido Curricular'!$F$4:$F$100=5), 9), """")"),"") | D36: =IFERROR(__xludf.DUMMYFUNCTION("IFERROR(INDEX(FILTER('Contenido Curricular'!$C$4:$C$100, 'Contenido Curricular'!$F$4:$F$100=5), 9), """")"),"") | F36: =IFERROR(__xludf.DUMMYFUNCTION("IFERROR(INDEX(FILTER('Contenido Curricular'!$D$4:$D$100, 'Contenido Curricular'!$F$4:$F$100=5), 9), """")"),"")
A37: 10 | B37: =IFERROR(__xludf.DUMMYFUNCTION("IFERROR(INDEX(FILTER('Contenido Curricular'!$B$4:$B$100, 'Contenido Curricular'!$F$4:$F$100=5), 10), """")"),"") | D37: =IFERROR(__xludf.DUMMYFUNCTION("IFERROR(INDEX(FILTER('Contenido Curricular'!$C$4:$C$100, 'Contenido Curricular'!$F$4:$F$100=5), 10), """")"),"") | F37: =IFERROR(__xludf.DUMMYFUNCTION("IFERROR(INDEX(FILTER('Contenido Curricular'!$D$4:$D$100, 'Contenido Curricular'!$F$4:$F$100=5), 10), """")"),"")
A38: 2.2 Recursos Educativos
A39: Tipo de Recurso a utilizar | C39: Tipo | E39: Rango Aproximando | G39: Tiempo Aproximado
A40: Presentacion | C40: Obligatorio | E40: 15-25 minutos | G40: 15
A41: Video | C41: Obligatorio | E41: 3 a 6 minutos | G41: 4
A42: Lectura | C42: Optativo | E42: 3-5 minutos | G42: 4
A43: Ejercicio Demostrativo | C43: Obligatorio | E43: 20-25 minutos | G43: 20
A45: 3. Área de Habilidades (Saber Hacer) | G45: Tiempo | H45: 50
G46: Tiene que estar en un rango de 30 a 50 minutos
A47: Actividad 1 (Obligatoria)
...

Sheet S. 6
I1: =B51+IF(ISNUMBER(B62),B62,0) -> 20
B2: Diseño de la Sesión de Laboratorio
B4: Curso | C4: 770 - Introducción a la Programación y Computación 1
B5: Semana | C5: 6
B6: Tiempo | C6: =H10+H21+H45+H70 -> 113
B7: Ponderación | C7: =B50+B61 -> 0
B8: Validación de Tiempo | C8: =IF(B51<=0, "❌ ERROR: La Actividad 1 debe tener un tiempo mayor a 0.", IF(H21>60, "❌ ERROR: El 'Área de Conocimiento' no puede exceder los 60 min.", IF((H10+H21+H45)<100, "❌ ERROR: El tiempo total debe ser de al menos 100 min.", "✅ VALIDACIÓN CORRECTA"))) -> ✅ VALIDACIÓN CORRECTA
A10: 1. Área Actitudinal (Saber Ser) | G10: Tiempo | H10: 3
G11: Tiene que estar en un rango de 3 a 5 minutos
A12: Nombre del Valor | B12: Perseverancia
A13: Tiempo Aproximado
A14: Descripcion
A15: La sesión aborda conceptos avanzados de programación como la recursividad, el funcionamiento interno de la pila de ejecución y el manejo de archivos, enfocándose en el análisis de la complejidad algorítmica para optimizar el rendimiento y la eficiencia del software.
A17: Como se relaciona con los conocimientos de la sesion y se aplicaria
A18: El valor de la perseverancia se relaciona estrechamente con estos temas porque dominar la recursividad y depurar el flujo de datos en la pila de ejecución son retos complejos que suelen generar frustración o bloqueos iniciales; en la práctica, esto se aplicaría motivando al estudiante a no rendirse frente a errores comunes como el desbordamiento de memoria (StackOverflow), impulsándolo a rastrear pacientemente cada llamada a la función e iterar sobre su código hasta encontrar el caso base correcto y la solución más eficiente.
A21: 2. Área Conocimiento (Saber) | G21: Tiempo | H21: 50
G22: No puede exceder los 60 minutos
A23: Competencia a desarrollar | B23: Analiza Estructuras de datos y algoritmos Análisis de complejidad temporal Optimizar rendimiento y eficiencia
A24: Competencia a desarrollar | B24: Implementa Sistemas de software Java, archivos y APIs Integridad y seguridad de datos
A26: 2.1 Contenido
A27: No. | B27: Unidad | D27: Tema | F27: Sub Tema
A28: 1 | B28: =IFERROR(__xludf.DUMMYFUNCTION("IFERROR(INDEX(FILTER('Contenido Curricular'!$B$4:$B$100, 'Contenido Curricular'!$F$4:$F$100=6), 1), """")"),"3. Avanzado") -> 3. Avanzado | D28: =IFERROR(__xludf.DUMMYFUNCTION("IFERROR(INDEX(FILTER('Contenido Curricular'!$C$4:$C$100, 'Contenido Curricular'!$F$4:$F$100=6), 1), """")"),"Recursividad") -> Recursividad | F28: =IFERROR(__xludf.DUMMYFUNCTION("IFERROR(INDEX(FILTER('Contenido Curricular'!$D$4:$D$100, 'Contenido Curricular'!$F$4:$F$100=6), 1), """")"),"Pila de ejecución y Archivos") -> Pila de ejecución y Archivos
A29: 2 | B29: =IFERROR(__xludf.DUMMYFUNCTION("IFERROR(INDEX(FILTER('Contenido Curricular'!$B$4:$B$100, 'Contenido Curricular'!$F$4:$F$100=6), 2), """")"),"") | D29: =IFERROR(__xludf.DUMMYFUNCTION("IFERROR(INDEX(FILTER('Contenido Curricular'!$C$4:$C$100, 'Contenido Curricular'!$F$4:$F$100=6), 2), """")"),"") | F29: =IFERROR(__xludf.DUMMYFUNCTION("IFERROR(INDEX(FILTER('Contenido Curricular'!$D$4:$D$100, 'Contenido Curricular'!$F$4:$F$100=6), 2), """")"),"")
A30: 3 | B30: =IFERROR(__xludf.DUMMYFUNCTION("IFERROR(INDEX(FILTER('Contenido Curricular'!$B$4:$B$100, 'Contenido Curricular'!$F$4:$F$100=6), 3), """")"),"") | D30: =IFERROR(__xludf.DUMMYFUNCTION("IFERROR(INDEX(FILTER('Contenido Curricular'!$C$4:$C$100, 'Contenido Curricular'!$F$4:$F$100=6), 3), """")"),"") | F30: =IFERROR(__xludf.DUMMYFUNCTION("IFERROR(INDEX(FILTER('Contenido Curricular'!$D$4:$D$100, 'Contenido Curricular'!$F$4:$F$100=6), 3), """")"),"")
A31: 4 | B31: =IFERROR(__xludf.DUMMYFUNCTION("IFERROR(INDEX(FILTER('Contenido Curricular'!$B$4:$B$100, 'Contenido Curricular'!$F$4:$F$100=6), 4), """")"),"") | D31: =IFERROR(__xludf.DUMMYFUNCTION("IFERROR(INDEX(FILTER('Contenido Curricular'!$C$4:$C$100, 'Contenido Curricular'!$F$4:$F$100=6), 4), """")"),"") | F31: =IFERROR(__xludf.DUMMYFUNCTION("IFERROR(INDEX(FILTER('Contenido Curricular'!$D$4:$D$100, 'Contenido Curricular'!$F$4:$F$100=6), 4), """")"),"")
A32: 5 | B32: =IFERROR(__xludf.DUMMYFUNCTION("IFERROR(INDEX(FILTER('Contenido Curricular'!$B$4:$B$100, 'Contenido Curricular'!$F$4:$F$100=6), 5), """")"),"") | D32: =IFERROR(__xludf.DUMMYFUNCTION("IFERROR(INDEX(FILTER('Contenido Curricular'!$C$4:$C$100, 'Contenido Curricular'!$F$4:$F$100=6), 5), """")"),"") | F32: =IFERROR(__xludf.DUMMYFUNCTION("IFERROR(INDEX(FILTER('Contenido Curricular'!$D$4:$D$100, 'Contenido Curricular'!$F$4:$F$100=6), 5), """")"),"")
A33: 6 | B33: =IFERROR(__xludf.DUMMYFUNCTION("IFERROR(INDEX(FILTER('Contenido Curricular'!$B$4:$B$100, 'Contenido Curricular'!$F$4:$F$100=6), 6), """")"),"") | D33: =IFERROR(__xludf.DUMMYFUNCTION("IFERROR(INDEX(FILTER('Contenido Curricular'!$C$4:$C$100, 'Contenido Curricular'!$F$4:$F$100=6), 6), """")"),"") | F33: =IFERROR(__xludf.DUMMYFUNCTION("IFERROR(INDEX(FILTER('Contenido Curricular'!$D$4:$D$100, 'Contenido Curricular'!$F$4:$F$100=6), 6), """")"),"")
A34: 7 | B34: =IFERROR(__xludf.DUMMYFUNCTION("IFERROR(INDEX(FILTER('Contenido Curricular'!$B$4:$B$100, 'Contenido Curricular'!$F$4:$F$100=6), 7), """")"),"") | D34: =IFERROR(__xludf.DUMMYFUNCTION("IFERROR(INDEX(FILTER('Contenido Curricular'!$C$4:$C$100, 'Contenido Curricular'!$F$4:$F$100=6), 7), """")"),"") | F34: =IFERROR(__xludf.DUMMYFUNCTION("IFERROR(INDEX(FILTER('Contenido Curricular'!$D$4:$D$100, 'Contenido Curricular'!$F$4:$F$100=6), 7), """")"),"")
A35: 8 | B35: =IFERROR(__xludf.DUMMYFUNCTION("IFERROR(INDEX(FILTER('Contenido Curricular'!$B$4:$B$100, 'Contenido Curricular'!$F$4:$F$100=6), 8), """")"),"") | D35: =IFERROR(__xludf.DUMMYFUNCTION("IFERROR(INDEX(FILTER('Contenido Curricular'!$C$4:$C$100, 'Contenido Curricular'!$F$4:$F$100=6), 8), """")"),"") | F35: =IFERROR(__xludf.DUMMYFUNCTION("IFERROR(INDEX(FILTER('Contenido Curricular'!$D$4:$D$100, 'Contenido Curricular'!$F$4:$F$100=6), 8), """")"),"")
A36: 9 | B36: =IFERROR(__xludf.DUMMYFUNCTION("IFERROR(INDEX(FILTER('Contenido Curricular'!$B$4:$B$100, 'Contenido Curricular'!$F$4:$F$100=6), 9), """")"),"") | D36: =IFERROR(__xludf.DUMMYFUNCTION("IFERROR(INDEX(FILTER('Contenido Curricular'!$C$4:$C$100, 'Contenido Curricular'!$F$4:$F$100=6), 9), """")"),"") | F36: =IFERROR(__xludf.DUMMYFUNCTION("IFERROR(INDEX(FILTER('Contenido Curricular'!$D$4:$D$100, 'Contenido Curricular'!$F$4:$F$100=6), 9), """")"),"")
A37: 10 | B37: =IFERROR(__xludf.DUMMYFUNCTION("IFERROR(INDEX(FILTER('Contenido Curricular'!$B$4:$B$100, 'Contenido Curricular'!$F$4:$F$100=6), 10), """")"),"") | D37: =IFERROR(__xludf.DUMMYFUNCTION("IFERROR(INDEX(FILTER('Contenido Curricular'!$C$4:$C$100, 'Contenido Curricular'!$F$4:$F$100=6), 10), """")"),"") | F37: =IFERROR(__xludf.DUMMYFUNCTION("IFERROR(INDEX(FILTER('Contenido Curricular'!$D$4:$D$100, 'Contenido Curricular'!$F$4:$F$100=6), 10), """")"),"")
A38: 2.2 Recursos Educativos
A39: Tipo de Recurso a utilizar | C39: Tipo | E39: Rango Aproximando | G39: Tiempo Aproximado
A40: Presentacion | C40: Obligatorio | E40: 15-25 minutos | G40: 15
A41: Video | C41: Obligatorio | E41: 3 a 6 minutos | G41: 4
A42: Lectura | C42: Optativo | E42: 3-5 minutos | G42: 4
A43: Ejercicio Demostrativo | C43: Obligatorio | E43: 20-25 minutos | G43: 20
A45: 3. Área de Habilidades (Saber Hacer) | G45: Tiempo | H45: 50
G46: Tiene que estar en un rango de 30 a 50 minutos
A47: Actividad 1 (Obligatoria)
...

Sheet S. 7
I1: =B51+IF(ISNUMBER(B62),B62,0) -> 20
B2: Diseño de la Sesión de Laboratorio
B4: Curso | C4: 770 - Introducción a la Programación y Computación 1
B5: Semana | C5: 7
B6: Tiempo | C6: =H10+H21+H45+H70 -> 113
B7: Ponderación | C7: =B50+B61 -> 0
B8: Validación de Tiempo | C8: =IF(B51<=0, "❌ ERROR: La Actividad 1 debe tener un tiempo mayor a 0.", IF(H21>60, "❌ ERROR: El 'Área de Conocimiento' no puede exceder los 60 min.", IF((H10+H21+H45)<100, "❌ ERROR: El tiempo total debe ser de al menos 100 min.", "✅ VALIDACIÓN CORRECTA"))) -> ✅ VALIDACIÓN CORRECTA
A10: 1. Área Actitudinal (Saber Ser) | G10: Tiempo | H10: 3
G11: Tiene que estar en un rango de 3 a 5 minutos
A12: Nombre del Valor | B12: Integridad
A13: Tiempo Aproximado
A14: Descripcion
A15: La sesión aborda los conceptos fundamentales de la Programación Orientada a Objetos (POO), analizando la creación de clases y objetos, así como la implementación de sus pilares principales (encapsulamiento, abstracción, herencia y polimorfismo), con el objetivo de establecer bases sólidas para el diseño de arquitecturas de software robustas y mantenibles.
A17: Como se relaciona con los conocimientos de la sesion y se aplicaria
A18: El valor de la integridad se relaciona de manera directa con el pilar del encapsulamiento, cuyo propósito técnico es proteger el estado interno de los datos. En la práctica, esto se aplicaría diseñando clases que restrinjan el acceso no autorizado a sus atributos, obligando a que cualquier modificación se realice a través de métodos controlados y validados; esto refleja el compromiso del desarrollador por construir sistemas seguros donde la información se mantenga coherente, inalterada y fiel a la realidad.
A21: 2. Área Conocimiento (Saber) | G21: Tiempo | H21: 50
G22: No puede exceder los 60 minutos
A23: Competencia a desarrollar | B23: Evalúa Arquitecturas de software Patrones de diseño y testing Mantenibilidad y robustez
A24: Competencia a desarrollar | B24: Analiza Estructuras de datos y algoritmos Análisis de complejidad temporal Optimizar rendimiento y eficiencia
A26: 2.1 Contenido
A27: No. | B27: Unidad | D27: Tema | F27: Sub Tema
A28: 1 | B28: =IFERROR(__xludf.DUMMYFUNCTION("IFERROR(INDEX(FILTER('Contenido Curricular'!$B$4:$B$100, 'Contenido Curricular'!$F$4:$F$100=7), 1), """")"),"4. POO") -> 4. POO | D28: =IFERROR(__xludf.DUMMYFUNCTION("IFERROR(INDEX(FILTER('Contenido Curricular'!$C$4:$C$100, 'Contenido Curricular'!$F$4:$F$100=7), 1), """")"),"Fundamentos") -> Fundamentos | F28: =IFERROR(__xludf.DUMMYFUNCTION("IFERROR(INDEX(FILTER('Contenido Curricular'!$D$4:$D$100, 'Contenido Curricular'!$F$4:$F$100=7), 1), """")"),"Clases, Objetos y Pilares") -> Clases, Objetos y Pilares
A29: 2 | B29: =IFERROR(__xludf.DUMMYFUNCTION("IFERROR(INDEX(FILTER('Contenido Curricular'!$B$4:$B$100, 'Contenido Curricular'!$F$4:$F$100=7), 2), """")"),"") | D29: =IFERROR(__xludf.DUMMYFUNCTION("IFERROR(INDEX(FILTER('Contenido Curricular'!$C$4:$C$100, 'Contenido Curricular'!$F$4:$F$100=7), 2), """")"),"") | F29: =IFERROR(__xludf.DUMMYFUNCTION("IFERROR(INDEX(FILTER('Contenido Curricular'!$D$4:$D$100, 'Contenido Curricular'!$F$4:$F$100=7), 2), """")"),"")
A30: 3 | B30: =IFERROR(__xludf.DUMMYFUNCTION("IFERROR(INDEX(FILTER('Contenido Curricular'!$B$4:$B$100, 'Contenido Curricular'!$F$4:$F$100=7), 3), """")"),"") | D30: =IFERROR(__xludf.DUMMYFUNCTION("IFERROR(INDEX(FILTER('Contenido Curricular'!$C$4:$C$100, 'Contenido Curricular'!$F$4:$F$100=7), 3), """")"),"") | F30: =IFERROR(__xludf.DUMMYFUNCTION("IFERROR(INDEX(FILTER('Contenido Curricular'!$D$4:$D$100, 'Contenido Curricular'!$F$4:$F$100=7), 3), """")"),"")
A31: 4 | B31: =IFERROR(__xludf.DUMMYFUNCTION("IFERROR(INDEX(FILTER('Contenido Curricular'!$B$4:$B$100, 'Contenido Curricular'!$F$4:$F$100=7), 4), """")"),"") | D31: =IFERROR(__xludf.DUMMYFUNCTION("IFERROR(INDEX(FILTER('Contenido Curricular'!$C$4:$C$100, 'Contenido Curricular'!$F$4:$F$100=7), 4), """")"),"") | F31: =IFERROR(__xludf.DUMMYFUNCTION("IFERROR(INDEX(FILTER('Contenido Curricular'!$D$4:$D$100, 'Contenido Curricular'!$F$4:$F$100=7), 4), """")"),"")
A32: 5 | B32: =IFERROR(__xludf.DUMMYFUNCTION("IFERROR(INDEX(FILTER('Contenido Curricular'!$B$4:$B$100, 'Contenido Curricular'!$F$4:$F$100=7), 5), """")"),"") | D32: =IFERROR(__xludf.DUMMYFUNCTION("IFERROR(INDEX(FILTER('Contenido Curricular'!$C$4:$C$100, 'Contenido Curricular'!$F$4:$F$100=7), 5), """")"),"") | F32: =IFERROR(__xludf.DUMMYFUNCTION("IFERROR(INDEX(FILTER('Contenido Curricular'!$D$4:$D$100, 'Contenido Curricular'!$F$4:$F$100=7), 5), """")"),"")
A33: 6 | B33: =IFERROR(__xludf.DUMMYFUNCTION("IFERROR(INDEX(FILTER('Contenido Curricular'!$B$4:$B$100, 'Contenido Curricular'!$F$4:$F$100=7), 6), """")"),"") | D33: =IFERROR(__xludf.DUMMYFUNCTION("IFERROR(INDEX(FILTER('Contenido Curricular'!$C$4:$C$100, 'Contenido Curricular'!$F$4:$F$100=7), 6), """")"),"") | F33: =IFERROR(__xludf.DUMMYFUNCTION("IFERROR(INDEX(FILTER('Contenido Curricular'!$D$4:$D$100, 'Contenido Curricular'!$F$4:$F$100=7), 6), """")"),"")
